Workbook

Sheet BCC
C1: Jan | D1: Feb | E1: Mar | F1: Apr | G1: May | H1: Jun | I1: Jul | J1: Aug | K1: Sept | L1: Oct | M1: Nov | N1: Dec
A2: Group | B2: ID
A3: Big F09 | B3: ELI-581 | C3: 0 | D3: 0 | E3: 0 | F3: 0 | G3: 0 | H3: 0 | I3: 0 | J3: 0 | K3: 0 | L3: 0 | M3: 0 | N3: 0
A4: Big Pride 2013 Cub 1 | B4: ELI-583 | C4: 0 | D4: 0 | E4: 0 | F4: 0 | G4: 0 | H4: 0 | I4: 1 | J4: 1 | K4: 1 | L4: 1 | M4: 1 | N4: 1
A5: Big Pride 2013 Cub 2 | B5: ELI-584 | C5: 0 | D5: 0 | E5: 0 | F5: 0 | G5: 0 | H5: 0 | I5: 1 | J5: 1 | K5: 1 | L5: 1 | M5: 1 | N5: 1
A6: Big Pride 2013 Cub 3 | B6: ELI-585 | C6: 0 | D6: 0 | E6: 0 | F6: 0 | G6: 0 | H6: 0 | I6: 1 | J6: 1 | K6: 1 | L6: 1 | M6: 1 | N6: 1
A7: Big Pride 2013 Cub 4 | B7: ELI-586 | C7: 0 | D7: 0 | E7: 0 | F7: 0 | G7: 0 | H7: 0 | I7: 1 | J7: 1 | K7: 1 | L7: 1 | M7: 1 | N7: 1
A8: Big Pride 2013 Cub 5 | B8: ELI-587 | C8: 0 | E8: 0 | F8: 0 | G8: 0 | H8: 0 | I8: 1 | J8: 1 | K8: 1 | L8: 1 | M8: 1 | N8: 1
A9: Big Pride 2013 Cub 6 | B9: ELI-590 | C9: 0 | D9: 0 | E9: 0 | F9: 1 | G9: 0 | H9: 0 | I9: 1 | J9: 1 | K9: 1 | L9: 1 | M9: 1 | N9: 1
A10: Big Pride 2013 Cub 7 | B10: ELI-591 | C10: 0 | D10: 0 | E10: 0 | F10: 1 | G10: 0 | H10: 0 | I10: 1 | J10: 1 | K10: 1 | L10: 1 | M10: 1 | N10: 1
A11: Big Pride 2013 Cub 8 | B11: ELI-592 | C11: 0 | D11: 0 | E11: 0 | F11: 1 | G11: 0 | H11: 0 | I11: 1 | J11: 1 | K11: 1 | L11: 1 | M11: 1 | N11: 1
A12: Big Pride 2013 Cub 9 | B12: ELI-593 | C12: 0 | D12: 0 | E12: 0 | F12: 0 | G12: 0 | H12: 0 | I12: 0 | J12: 1 | K12: 1 | L12: 1 | M12: 1 | N12: 1
A13: Big Pride 2013 Cub 10 | B13: ELI-594 | C13: 0 | D13: 0 | E13: 0 | F13: 0 | G13: 0 | H13: 0 | I13: 1 | J13: 1 | K13: 1 | L13: 1 | M13: 0 | N13: 1
A14: Big Pride 2013 Cub 11 | B14: ELI-595 | C14: 0 | D14: 0 | E14: 0 | F14: 0 | G14: 0 | H14: 0 | I14: 0 | J14: 0 | K14: 0 | L14: 1 | M14: 0 | N14: 1
A15: Big Pride F01 | B15: ELI-243 | C15: 0 | D15: 0 | E15: 0 | F15: 1 | G15: 0 | H15: 1 | I15: 1 | J15: 1 | K15: 1 | L15: 1 | M15: 1 | N15: 1
A16: Big Pride F02 | B16: ELI-242 | C16: 0 | D16: 0 | E16: 0 | F16: 0 | G16: 0 | H16: 1 | I16: 1 | J16: 1 | K16: 1 | L16: 1 | M16: 1 | N16: 1
A17: Big Pride | B17: ELI-226 | C17: 0 | D17: 0 | E17: 0 | F17: 0 | G17: 0 | H17: 0 | I17: 1 | J17: 0 | K17: 0 | L17: 0 | M17: 0 | N17: 0
A18: Big Pride F03 | B18: ELI-225 | C18: 0 | D18: 0 | E18: 0 | F18: 0 | G18: 0 | H18: 0 | I18: 0 | J18: 0 | K18: 0 | L18: 0 | M18: 0 | N18: 0
A19: Big Pride F04 | B19: ELI-224 | C19: 0 | D19: 0 | E19: 0 | F19: 0 | G19: 0 | H19: 1 | I19: 0 | J19: 1 | K19: 1 | M19: 1 | N19: 0
A20: Big Pride F05 | B20: ELI-245 | C20: 0 | D20: 0 | E20: 0 | F20: 0 | G20: 0 | H20: 1 | I20: 1 | J20: 1 | K20: 1 | L20: 1 | M20: 1 | N20: 1
A21: Big Pride F06 | B21: ELI-223 | C21: 0 | D21: 0 | E21: 0 | F21: 0 | G21: 0 | H21: 1 | I21: 1 | J21: 1 | K21: 1 | L21: 1 | M21: 1 | N21: 1
A22: Big Pride F07 | B22: ELI-220 | C22: 0 | D22: 0 | E22: 0 | F22: 0 | G22: 0 | H22: 1 | I22: 0 | J22: 1 | K22: 1 | L22: 1 | M22: 1 | N22: 1
A23: Big Pride F08 | B23: ELI-218 | C23: 0 | D23: 0 | E23: 0 | F23: 0 | G23: 0 | H23: 1 | I23: 1 | J23: 1 | K23: 1 | L23: 1 | M23: 1 | N23: 1
A24: Big Pride F09 | B24: ELI-143 | C24: 0 | D24: 0 | E24: 0 | F24: 0 | G24: 0 | H24: 1 | I24: 0 | J24: 0 | K24: 0 | L24: 0 | M24: 0 | N24: 0
A25: Big Pride F10 | B25: ELI-219 | C25: 0 | D25: 0 | E25: 0 | F25: 0 | G25: 0 | H25: 1 | I25: 1 | J25: 1 | K25: 1 | L25: 1 | M25: 1 | N25: 1
A26: Big Pride F12 | B26: ELI-496 | C26: 0 | D26: 0 | E26: 0 | F26: 0 | G26: 0 | H26: 0 | I26: 0 | J26: 0 | K26: 0 | L26: 0 | M26: 0 | N26: 0
A27: Big Pride M01 | B27: ELI-227 | C27: 0 | D27: 0 | E27: 0 | F27: 0 | G27: 0 | H27: 0 | I27: 0 | J27: 0 | K27: 0 | L27: 0 | M27: 0 | N27: 0
A28: Big Pride M02 | B28: ELI-221 | C28: 0 | D28: 0 | E28: 0 | F28: 0 | G28: 0 | H28: 0 | I28: 0 | J28: 0 | K28: 0 | L28: 0 | M28: 0 | N28: 0
A29: Big Pride M03 | B29: ELI-222 | C29: 0 | D29: 0 | E29: 0 | F29: 0 | G29: 0 | H29: 0 | I29: 0 | J29: 0 | K29: 0 | L29: 0 | M29: 0 | N29: 0
C31: Jan | D31: Feb | E31: Mar | F31: Apr | G31: May | H31: Jun | I31: Jul | J31: Aug | K31: Sept | L31: Oct | M31: Nov | N31: Dec
A32: Group | B32: ID
A33: Chowo F01 | B33: ELI-414 | C33: 0 | D33: 0 | E33: 0 | F33: 0 | G33: 1 | H33: 1 | I33: 0 | J33: 0 | K33: 1 | L33: 0 | M33: 0 | N33: 0
A34: Chowo F02 | B34: ELI-415 | C34: 0 | D34: 0 | E34: 0 | F34: 0 | G34: 0 | H34: 0 | I34: 0 | J34: 0 | K34: 0 | L34: 0 | M34: 0 | N34: 0
A35: Chowo F03 | B35: ELI-436 | C35: 0 | D35: 0 | E35: 0 | F35: 0 | G35: 0 | H35: 0 | I35: 0 | J35: 0 | K35: 0 | L35: 0 | M35: 0 | N35: 0
A36: Chowo F04 | B36: ELI-413 | C36: 0 | D36: 0 | E36: 0 | F36: 0 | G36: 0 | H36: 0 | I36: 0 | J36: 0 | K36: 0 | L36: 0 | M36: 0 | N36: 0
A37: Chowo F05 | B37: ELI-493 | C37: 0 | D37: 0 | E37: 0 | F37: 0 | G37: 1 | H37: 1 | I37: 0 | J37: 0 | K37: 1 | L37: 0 | M37: 0 | N37: 0
A38: Chowo F06 | B38: ELI-494 | C38: 0 | D38: 0 | E38: 0 | F38: 0 | G38: 0 | H38: 1 | I38: 0 | J38: 0 | K38: 1 | L38: 0 | M38: 0 | N38: 0
A39: Chowo | B39: ELI-495 | C39: 0 | D39: 0 | E39: 0 | F39: 0 | G39: 1 | H39: 0 | I39: 0 | J39: 0 | K39: 0 | L39: 0 | M39: 0 | N39: 0
A40: Chowo | B40: ELI-598 | C40: 0 | D40: 0 | E40: 0 | F40: 0 | G40: 0 | H40: 1 | I40: 0 | J40: 0 | K40: 1 | L40: 0 | M40: 0 | N40: 0
A41: Chowo | B41: ELI-599 | C41: 0 | D41: 0 | E41: 0 | F41: 0 | G41: 0 | H41: 1 | I41: 0 | J41: 0 | K41: 1 | L41: 1 | M41: 0 | N41: 0
...

Sheet NHK
C1: Jan | D1: Feb | E1: Mar | F1: Apr | G1: May | H1: Jun | I1: Jul | J1: Aug | K1: Sept | L1: Oct | M1: Nov | N1: Dec
A2: Group | B2: ID
A3: Nsefu F01 | B3: ELI-173 | C3: 0 | D3: 0 | E3: 0 | F3: 0 | G3: 1 | H3: 1 | I3: 0 | J3: 0 | K3: 1 | L3: 1 | M3: 0 | N3: 0
A4: Nsefu F02 | B4: ELI-174 | C4: 0 | D4: 0 | E4: 0 | F4: 0 | G4: 1 | H4: 1 | I4: 1 | J4: 0 | K4: 1 | L4: 0 | M4: 1 | N4: 0
A5: Nsefu F03 | B5: ELI-247 | C5: 0 | D5: 0 | E5: 0 | F5: 0 | G5: 1 | H5: 1 | I5: 0 | J5: 0 | K5: 1 | L5: 1 | M5: 1 | N5: 0
A6: Nsefu F04 | B6: ELI-248 | C6: 0 | D6: 0 | E6: 0 | F6: 0 | G6: 1 | H6: 1 | I6: 1 | J6: 1 | K6: 1 | L6: 1 | M6: 1 | N6: 0
A7: Nsefu F05 | B7: ELI-249 | C7: 0 | D7: 0 | E7: 0 | F7: 0 | G7: 0 | H7: 1 | I7: 0 | J7: 0 | K7: 0 | L7: 0 | M7: 0 | N7: 0
A8: Nsefu F06 | B8: ELI-250 | C8: 0 | D8: 0 | E8: 0 | F8: 0 | G8: 1 | H8: 1 | I8: 0 | J8: 1 | K8: 1 | L8: 1 | M8: 1 | N8: 0
A9: Nsefu F07 | B9: ELI-462 | C9: 0 | D9: 0 | E9: 0 | F9: 0 | G9: 1 | H9: 0 | I9: 0 | J9: 1 | K9: 0 | L9: 1 | M9: 1 | N9: 0
A10: Nsefu F11 | B10: ELI-378 | C10: 0 | D10: 0 | E10: 0 | F10: 0 | G10: 0 | H10: 1 | I10: 1 | J10: 1 | K10: 1 | L10: 0 | M10: 0 | N10: 0
A11: Nsefu F12 | B11: ELI-463 | C11: 0 | D11: 0 | E11: 0 | F11: 0 | G11: 0 | H11: 1 | I11: 0 | J11: 1 | K11: 1 | L11: 1 | M11: 1 | N11: 0
A12: Nsefu F13 | B12: ELI-515 | C12: 0 | D12: 0 | E12: 0 | F12: 0 | G12: 1 | H12: 0 | I12: 0 | J12: 0 | K12: 0 | L12: 0 | M12: 0 | N12: 0
A13: Nsefu M02 | B13: ELI-373 | C13: 0 | D13: 0 | E13: 0 | F13: 0 | G13: 0 | H13: 1 | I13: 0 | J13: 0 | K13: 1 | L13: 1 | M13: 1 | N13: 0
A14: Nsefu M03 | B14: ELI-375 | C14: 0 | D14: 0 | E14: 0 | F14: 0 | G14: 0 | H14: 1 | I14: 0 | J14: 0 | K14: 1 | L14: 1 | M14: 0 | N14: 0
... A24: Nsefu | B24: ELI-601 | C24: 0 | D24: 0 | E24: 0 | F24: 0 | G24: 0 | H24: 0 | I24: 0 | J24: 0 | K24: 0 | L24: 1 | M24: 1 | N24: 0
C27: Jan | D27: Feb | E27: Mar | F27: Apr | G27: May | H27: Jun | I27: Jul | J27: Aug | K27: Sept | L27: Oct | M27: Nov | N27: Dec
A28: Group | B28: ID
A29: Hot Springs F01 | B29: ELI-258 | C29: 0 | D29: 0 | E29: 0 | F29: 0 | G29: 0 | H29: 0 | I29: 1 | J29: 0 | K29: 1 | L29: 0 | M29: 0 | N29: 0
A30: Hot Springs Cub 1 | B30: ELI-608 | E30: 0 | F30: 0 | G30: 0 | H30: 0 | I30: 0 | J30: 0 | K30: 1 | L30: 0 | M30: 0 | N30: 0
A31: Hot Springs Cub 2 | B31: ELI-609 | E31: 0 | F31: 0 | G31: 0 | H31: 0 | I31: 0 | J31: 0 | K31: 1 | L31: 0 | M31: 0 | N31: 0
A32: Hot Springs Cub 3 | B32: ELI-611 | E32: 0 | F32: 0 | G32: 0 | H32: 0 | I32: 0 | J32: 0 | K32: 1 | L32: 0 | M32: 0 | N32: 0
A33: Hot Springs F02 | B33: ELI-256 | C33: 0 | D33: 0 | E33: 0 | F33: 0 | G33: 0 | H33: 0 | I33: 0 | J33: 0 | K33: 0 | L33: 0 | M33: 0 | N33: 0
A34: Hot Springs F03 | B34: ELI-466 | C34: 0 | D34: 0 | E34: 0 | F34: 0 | G34: 0 | H34: 0 | I34: 0 | J34: 0 | K34: 0 | L34: 0 | M34: 0 | N34: 0
A35: Hot Springs M01 | B35: ELI-379 | C35: 0 | D35: 0 | E35: 0 | F35: 0 | G35: 0 | H35: 0 | I35: 1 | J35: 0 | K35: 1 | L35: 0 | M35: 0 | N35: 0
C37: Jan | D37: Feb | E37: Mar | F37: Apr | G37: May | H37: Jun | I37: Jul | J37: Aug | K37: Sept | L37: Oct | M37: Nov | N37: Dec
A38: Group | B38: ID
A39: Kapamba F01 | B39: ELI-203 | C39: 0 | D39: 0 | E39: 0 | F39: 0 | G39: 0 | H39: 0 | I39: 0 | J39: 0 | K39: 0 | L39: 0 | M39: 0 | N39: 0
A40: Kapamba F02 | B40: ELI-204 | C40: 0 | D40: 0 | E40: 0 | F40: 0 | G40: 0 | H40: 0 | I40: 0 | J40: 0 | K40: 0 | L40: 0 | M40: 0 | N40: 0
A41: Kapamba F09 | B41: ELI-532 | C41: 0 | D41: 0 | E41: 0 | F41: 0 | G41: 0 | H41: 0 | I41: 0 | J41: 0 | K41: 0 | L41: 0 | M41: 0 | N41: 0
A42: Kapamba M03 | B42: ELI-534 | C42: 0 | D42: 0 | E42: 0 | F42: 0 | G42: 0 | H42: 0 | I42: 0 | J42: 0 | K42: 0 | L42: 0 | M42: 0 | N42: 0
A43: Kapamba M04 | B43: ELI-533 | C43: 0 | D43: 0 | E43: 0 | F43: 0 | G43: 0 | H43: 0 | I43: 0 | J43: 0 | K43: 0 | L43: 0 | M43: 0 | N43: 0
A44: Kapamba M05 | B44: ELI-535 | C44: 0 | D44: 0 | E44: 0 | F44: 0 | G44: 0 | H44: 0 | I44: 0 | J44: 0 | K44: 0 | L44: 0 | M44: 0 | N44: 0
A45: Kapamba M06 | B45: ELI-536 | C45: 0 | D45: 0 | E45: 0 | F45: 0 | G45: 0 | H45: 0 | I45: 0 | J45: 0 | K45: 0 | L45: 0 | M45: 0 | N45: 0
A46: New Kapamba F03 | B46: ELI-480 | C46: 0 | D46: 0 | E46: 0 | F46: 0 | G46: 0 | H46: 0 | I46: 0 | J46: 0 | K46: 0 | L46: 0 | M46: 0 | N46: 0

Sheet CH
C1: Jan | D1: Feb | E1: Mar | F1: Apr | G1: May | H1: Jun | I1: Jul | J1: Aug | K1: Sept | L1: Oct | M1: Nov | N1: Dec
A2: Group | B2: ID
A3: 2011 Cub U01 | B3: ELI-438 | C3: 0 | D3: 0 | E3: 0 | F3: 0 | G3: 0 | I3: 1 | J3: 0 | K3: 0 | L3: 0 | M3: 0 | N3: 0
A4: 2011 Cub U02 | B4: ELI-441 | C4: 0 | D4: 0 | E4: 0 | F4: 0 | G4: 0 | H4: 0 | I4: 0 | J4: 0 | K4: 0 | L4: 0 | M4: 0 | N4: 0
A5: 2011 Cub U03 | B5: ELI-442 | C5: 0 | D5: 0 | E5: 0 | F5: 0 | G5: 0 | H5: 0 | I5: 0 | J5: 0 | K5: 0 | L5: 0 | M5: 0 | N5: 0
A6: 2011 Cub U04 | B6: ELI-443 | C6: 0 | D6: 0 | E6: 0 | F6: 0 | G6: 0 | H6: 0 | I6: 0 | J6: 0 | K6: 0 | L6: 0 | M6: 0 | N6: 0
A7: Chamilandu F01 | B7: ELI-192 | C7: 0 | D7: 0 | E7: 0 | F7: 0 | G7: 0 | H7: 0 | I7: 0 | J7: 0 | K7: 0 | L7: 0 | M7: 0 | N7: 0
A8: Chamilandu F02 | B8: ELI-193 | C8: 0 | D8: 0 | E8: 0 | F8: 0 | G8: 0 | H8: 0 | I8: 0 | J8: 0 | K8: 0 | L8: 0 | M8: 0 | N8: 0
A9: Chamilandu F03 | B9: ELI-194 | C9: 0 | D9: 0 | E9: 0 | F9: 0 | G9: 0 | H9: 0 | I9: 0 | J9: 0 | K9: 0 | L9: 0 | M9: 0 | N9: 0
A10: Chamilandu F05 | B10: ELI-228 | C10: 0 | D10: 0 | E10: 0 | F10: 0 | G10: 0 | H10: 0 | I10: 0 | J10: 0 | K10: 0 | L10: 0 | M10: 0 | N10: 0
A11: Chamilandu F06 | B11: ELI-398 | C11: 0 | D11: 0 | E11: 0 | F11: 0 | G11: 0 | H11: 0 | I11: 1 | J11: 0 | K11: 0 | L11: 0 | M11: 0 | N11: 0
A12: Chamilandu F07 | B12: ELI-405 | O12: duplicate of 444
A13: Chamilandu F08 | B13: ELI-444 | C13: 0 | D13: 0 | E13: 0 | F13: 0 | G13: 0 | H13: 0 | I13: 1 | J13: 0 | K13: 0 | L13: 0 | M13: 0 | N13: 0
A14: Chamilandu F09 | B14: ELI-439 | C14: 0 | D14: 0 | E14: 0 | F14: 0 | G14: 0 | H14: 0 | I14: 0 | J14: 0 | K14: 0 | L14: 0 | M14: 0 | N14: 0
A15: Chamilandu F10 | B15: ELI-440 | C15: 0 | D15: 0 | E15: 0 | F15: 0 | G15: 0 | H15: 0 | I15: 1 | J15: 0 | K15: 0 | L15: 0 | M15: 0 | N15: 0
A16: Chamilandu F11 | B16: ELI-437 | C16: 0 | D16: 0 | E16: 0 | F16: 0 | G16: 0 | H16: 0 | I16: 0 | J16: 0 | K16: 0 | L16: 0 | M16: 0 | N16: 0
A17: Chamilandu M03 | B17: ELI-404 | C17: 0 | D17: 0 | E17: 0 | F17: 0 | G17: 0 | H17: 0 | I17: 0 | J17: 0 | K17: 0 | L17: 0 | M17: 0 | N17: 0
A18: Chamilandu Male Cub 01 | B18: ELI-196 | C18: 0 | D18: 0 | E18: 0 | F18: 0 | G18: 0 | H18: 0 | I18: 0 | J18: 0 | K18: 0 | L18: 0 | M18: 0 | N18: 0
C19: 0 | D19: 0 | E19: 0 | F19: 0 | G19: 0 | H19: 0 | I19: 0 | J19: 0 | K19: 0 | L19: 0 | M19: 0 | N19: 0
C22: Jan | D22: Feb | E22: Mar | F22: April | G22: May | H22: Jun | I22: Jul | J22: Aug | K22: Sept | L22: Oct | M22: Nov | N22: Dec
A23: Group | B23: ID
A24: Hollywood M01 | B24: ELI-233 | C24: 0 | D24: 0 | E24: 0 | F24: 0 | G24: 1 | H24: 0 | I24: 0 | J24: 0 | K24: 0 | L24: 0 | M24: 0 | N24: 0
A25: Hollywood Cub 01 '10 | B25: ELI-400 | C25: 0 | D25: 0 | E25: 0 | F25: 0 | G25: 0 | H25: 0 | I25: 0 | J25: 0 | K25: 0 | L25: 0 | M25: 0 | N25: 0
A26: Hollywood Cub 02 '10 | B26: ELI-401 | C26: 0 | D26: 0 | E26: 0 | F26: 0 | G26: 0 | H26: 0 | I26: 0 | J26: 0 | K26: 0 | L26: 0 | M26: 0 | N26: 0
A27: Hollywood F01 | B27: ELI-197 | C27: 0 | D27: 0 | E27: 0 | F27: 0 | G27: 1 | H27: 0 | I27: 0 | J27: 0 | K27: 1 | L27: 1 | M27: 0 | N27: 0
A28: Hollywood F02 | B28: ELI-198 | C28: 0 | D28: 0 | E28: 0 | F28: 0 | G28: 0 | H28: 0 | I28: 0 | J28: 0 | K28: 1 | L28: 1 | M28: 0 | N28: 0
A29: Hollywood F03 | B29: ELI-230 | C29: 0 | D29: 0 | E29: 0 | F29: 0 | G29: 0 | H29: 0 | I29: 0 | J29: 0 | K29: 1 | L29: 1 | M29: 0 | N29: 0
A30: Hollywood F04 | B30: ELI-231 | C30: 0 | D30: 0 | E30: 0 | F30: 0 | G30: 0 | H30: 0 | I30: 0 | J30: 0 | K30: 1 | L30: 1 | M30: 0 | N30: 0
A31: Hollywood F05 | B31: ELI-232 | C31: 0 | D31: 0 | E31: 0 | F31: 0 | G31: 1 | H31: 0 | I31: 0 | J31: 0 | K31: 0 | L31: 0 | M31: 0 | N31: 0
A32: Hollywood F06 | B32: ELI-424 | C32: 0 | D32: 0 | E32: 0 | F32: 0 | G32: 1 | H32: 0 | I32: 0 | J32: 0 | K32: 0 | L32: 1 | M32: 0 | N32: 0
A33: Hollywood F07 | B33: ELI-425 | C33: 0 | D33: 0 | E33: 0 | F33: 0 | G33: 0 | H33: 0 | I33: 0 | J33: 0 | K33: 1 | L33: 1 | M33: 0 | N33: 0
A34: Hollywood 2013Cub1 | B34: ELI-612 | C34: 0 | D34: 0 | E34: 0 | F34: 0 | G34: 0 | H34: 0 | I34: 0 | J34: 0 | K34: 1 | L34: 1 | M34: 0 | N34: 0
A35: Hollywood 2013Cub2 | B35: ELI-613 | C35: 0 | D35: 0 | E35: 0 | F35: 0 | G35: 0 | H35: 0 | I35: 0 | J35: 0 | K35: 1 | L35: 1 | M35: 0 | N35: 0
... A39: Hollywood 2013Cub6 | B39: ELI-618 | C39: 0 | D39: 0 | E39: 0 | F39: 0 | G39: 0 | H39: 0 | I39: 0 | J39: 0 | K39: 1 | L39: 1 | M39: 0 | N39: 0

Sheet LM
C1: Jan | D1: Feb | E1: Mar | F1: Apr | G1: May | H1: Jun | I1: Jul | J1: Aug | K1: Sept | L1: Oct | M1: Nov | N1: Dec
A2: Group | B2: ID
A3: Luwi F01 | B3: ELI-152 | C3: 0 | D3: 0 | E3: 0 | F3: 0 | G3: 0 | H3: 0 | I3: 0 | J3: 0 | K3: 0 | L3: 0 | M3: 0 | N3: 0
A4: Luwi F03 | B4: ELI-154 | C4: 0 | D4: 0 | E4: 0 | F4: 0 | G4: 1 | H4: 0 | I4: 0 | J4: 0 | K4: 0 | L4: 0 | M4: 1 | N4: 0
A5: Luwi F04 | B5: ELI-155 | C5: 0 | D5: 0 | E5: 0 | F5: 0 | G5: 1 | H5: 0 | I5: 0 | J5: 1 | K5: 0 | L5: 1 | M5: 1 | N5: 0
A6: Luwi F08 | B6: ELI-160 | C6: 0 | D6: 0 | E6: 0 | F6: 0 | G6: 0 | H6: 0 | I6: 0 | J6: 0 | K6: 0 | L6: 0 | M6: 0 | N6: 0
A7: Luwi F09 | B7: ELI-241 | C7: 0 | D7: 0 | E7: 0 | F7: 0 | G7: 0 | H7: 0 | I7: 0 | J7: 0 | K7: 0 | L7: 0 | M7: 0 | N7: 0
A8: Luwi F10 | B8: ELI-369 | C8: 0 | D8: 0 | E8: 0 | F8: 0 | G8: 1 | H8: 0 | I8: 0 | J8: 0 | K8: 0 | L8: 1 | M8: 1 | N8: 0
A9: Luwi M05 | B9: ELI-370 | C9: 0 | D9: 0 | E9: 0 | F9: 0 | G9: 1 | H9: 0 | I9: 0 | J9: 0 | K9: 0 | L9: 1 | M9: 1 | N9: 0
A10: Manky Ear | B10: ELI-159 | C10: 0 | D10: 0 | E10: 0 | F10: 0 | G10: 1 | H10: 0 | I10: 0 | J10: 0 | K10: 0 | L10: 1 | M10: 1 | N10: 0
A11: Luwi M01 | B11: ELI-158 | C11: 0 | D11: 0 | E11: 0 | F11: 0 | G11: 0 | H11: 0 | I11: 0 | J11: 0 | K11: 0 | L11: 0 | M11: 0 | N11: 0
A12: Luwi M02 | B12: ELI-161 | C12: 0 | D12: 0 | E12: 0 | F12: 0 | G12: 0 | H12: 0 | I12: 0 | J12: 0 | K12: 0 | L12: 0 | M12: 0 | N12: 0
A13: Ginger | B13: ELI-162 | C13: 0 | D13: 0 | E13: 0 | F13: 0 | G13: 0 | H13: 0 | I13: 0 | J13: 0 | K13: 0 | L13: 0 | M13: 0 | N13: 0
A14: Luwi M04 | B14: ELI-163 | C14: 0 | D14: 0 | E14: 0 | F14: 0 | G14: 0 | H14: 0 | I14: 0 | J14: 0 | K14: 0 | L14: 0 | M14: 0 | N14: 0
C17: Jan | D17: Feb | E17: Mar | F17: Apr | G17: May | H17: Jun | I17: Jul | J17: Aug | K17: Sept | L17: Oct | M17: Nov | N17: Dec
A18: Group | B18: ID
A19: Mwamba I F01 | B19: ELI-124 | C19: 0 | D19: 0 | E19: 0 | F19: 0 | G19: 0 | H19: 0 | I19: 0 | J19: 1 | K19: 0 | L19: 0 | M19: 1 | N19: 1
A20: Mwamba I F02 | B20: ELI-125 | C20: 0 | D20: 0 | E20: 0 | F20: 0 | G20: 0 | H20: 0 | I20: 0 | J20: 1 | K20: 0 | L20: 0 | M20: 1 | N20: 1
A21: Mwamba I F03 | B21: ELI-246 | C21: 0 | D21: 0 | E21: 0 | F21: 0 | G21: 0 | H21: 0 | I21: 0 | J21: 0 | K21: 0 | L21: 0 | M21: 0 | N21: 0
A22: Mwamba I F04 | B22: ELI-126 | C22: 0 | D22: 0 | E22: 0 | F22: 0 | G22: 0 | H22: 0 | I22: 0 | J22: 1 | K22: 0 | L22: 0 | M22: 1 | N22: 1
A23: Mwamba I F05 | B23: ELI-127 | C23: 0 | D23: 0 | E23: 0 | F23: 0 | G23: 0 | H23: 0 | I23: 0 | J23: 1 | K23: 0 | L23: 0 | M23: 1 | N23: 1
A24: Mwamba I M03 | B24: ELI-130 | C24: 0 | D24: 0 | E24: 0 | F24: 0 | G24: 1 | H24: 0 | I24: 0 | J24: 0 | K24: 0 | L24: 0 | M24: 0 | N24: 0
A25: Mwamba I | B25: ELI-469 | C25: 0 | D25: 0 | E25: 0 | F25: 0 | G25: 0 | H25: 0 | I25: 0 | J25: 1 | K25: 0 | L25: 0 | M25: 1 | N25: 1
A26: Mwamba I | B26: ELI-657 | C26: 0 | D26: 0 | E26: 0 | F26: 0 | G26: 0 | H26: 0 | I26: 0 | J26: 1 | K26: 1 | L26: 0 | M26: 1 | N26: 1
A27: Mwamba I | B27: ELI-658 | C27: 0 | D27: 0 | E27: 0 | F27: 0 | G27: 0 | H27: 0 | I27: 0 | J27: 0 | K27: 0 | L27: 0 | M27: 1 | N27: 1
A28: Mwamba I | B28: ELI-659 | C28: 0 | D28: 0 | E28: 0 | F28: 0 | G28: 0 | H28: 0 | I28: 0 | J28: 1 | K28: 0 | L28: 0 | M28: 1 | N28: 1
A29: Mwamba I | B29: ELI-660 | C29: 0 | D29: 0 | E29: 0 | F29: 0 | G29: 0 | H29: 0 | I29: 0 | J29: 1 | K29: 0 | L29: 0 | M29: 1 | N29: 1
A30: Mwamba I | B30: ELI-661 | C30: 0 | D30: 0 | E30: 0 | F30: 0 | G30: 0 | H30: 0 | I30: 0 | J30: 1 | K30: 0 | L30: 0 | M30: 1 | N30: 1
... A37: Mwamba II F05 | B37: ELI-138 | C37: 0 | D37: 0 | E37: 0 | F37: 0 | G37: 0 | H37: 0 | I37: 0 | J37: 1 | K37: 1 | L37: 0 | M37: 1 | N37: 1
C41: Jan | D41: Feb | E41: Mar | F41: Apr | G41: May | H41: Jun | I41: Jul | J41: Aug | K41: Sept | L41: Oct | M41: Nov | N41: Dec
A42: Group
A43: Mwamba II F01 | B43: ELI-134 | C43: 0 | D43: 0 | E43: 0 | F43: 0 | G43: 0 | H43: 0 | I43: 0 | J43: 0 | K43: 1 | L43: 0 | M43: 0 | N43: 0
A44: Mwamba II F02 | B44: ELI-135 | C44: 0 | D44: 0 | E44: 0 | F44: 0 | G44: 0 | H44: 0 | I44: 0 | J44: 0 | K44: 1 | L44: 0 | M44: 0 | N44: 0
A45: Mwamba II F03 | B45: ELI-136 | C45: 0 | D45: 0 | E45: 0 | F45: 0 | G45: 0 | H45: 0 | I45: 0 | J45: 0 | K45: 1 | L45: 0 | M45: 0 | N45: 0
A46: Mwamba II F06 | B46: ELI-139 | C46: 0 | D46: 0 | E46: 0 | F46: 0 | G46: 0 | H46: 0 | I46: 0 | J46: 0 | K46: 1 | L46: 0 | M46: 0 | N46: 0
A47: New Mwamba M01 | B47: ELI-430 | C47: 0 | D47: 0 | E47: 0 | F47: 0 | G47: 0 | H47: 0 | I47: 0 | J47: 0 | K47: 0 | L47: 0 | M47: 0 | N47: 0
A48: Mwamba II Cub 01 | B48: ELI-XX1 | C48: 0 | D48: 0 | E48: 0 | F48: 0 | G48: 0 | H48: 0 | I48: 0 | J48: 1 | K48: 1 | L48: 0 | M48: 0 | N48: 0
A49: Mwamba II Cub 02 | B49: ELI-XX2 | C49: 0 | D49: 0 | E49: 0 | F49: 0 | G49: 0 | H49: 0 | I49: 0 | J49: 1 | K49: 0 | L49: 0 | M49: 0 | N49: 0
A50: Mwamba II Cub 03 | B50: ELI-XX3 | C50: 0 | D50: 0 | E50: 0 | F50: 0 | G50: 0 | H50: 0 | I50: 0 | J50: 1 | K50: 0 | L50: 0 | M50: 0 | N50: 0
A51: Mwamba II Cub 04 | B51: ELI-XX4 | C51: 0 | D51: 0 | E51: 0 | F51: 0 | G51: 0 | H51: 0 | I51: 0 | J51: 1 | K51: 0 | L51: 0 | M51: 0 | N51: 0
...

Sheet NS
C1: Jan | D1: Feb | E1: Mar | F1: Apr | G1: May | H1: Jun | I1: Jul | J1: Aug | K1: Sept | L1: Oct | M1: Nov | N1: Dec
A2: Group | B2: ID
A3: Nsolo F06 | B3: ELI-215 | C3: 0 | D3: 0 | E3: 0 | F3: 1 | G3: 1 | H3: 0 | I3: 1 | J3: 0 | K3: 0 | L3: 0 | M3: 0 | N3: 0
A4: Nsolo F07 | B4: ELI-454 | C4: 0 | D4: 0 | E4: 0 | F4: 0 | G4: 0 | H4: 0 | I4: 0 | J4: 0 | K4: 0 | L4: 0 | M4: 0 | N4: 0
A5: Nsolo F08 | B5: ELI-455 | C5: 0 | D5: 0 | E5: 0 | F5: 0 | G5: 0 | H5: 0 | I5: 0 | J5: 0 | K5: 0 | L5: 0 | M5: 0 | N5: 0
A6: Nsolo F09 | B6: ELI-458 | C6: 0 | D6: 0 | E6: 0 | F6: 0 | G6: 0 | H6: 0 | I6: 0 | J6: 0 | K6: 0 | L6: 0 | M6: 0 | N6: 0
A7: Nsolo F10 | B7: ELI-459 | C7: 0 | D7: 0 | E7: 0 | F7: 0 | G7: 0 | H7: 0 | I7: 0 | J7: 0 | K7: 0 | L7: 0 | M7: 0 | N7: 0
A8: Nsolo M04 | B8: ELI-461 | C8: 0 | D8: 0 | E8: 0 | F8: 0 | G8: 0 | H8: 0 | I8: 0 | J8: 0 | K8: 0 | L8: 0 | M8: 0 | N8: 0
A9: Nsolo M05 | B9: ELI-456 | C9: 0 | D9: 0 | E9: 0 | F9: 0 | G9: 0 | H9: 0 | I9: 0 | J9: 0 | K9: 0 | L9: 0 | M9: 0 | N9: 0
A10: Nsolo M06 | B10: ELI-457 | C10: 0 | D10: 0 | E10: 0 | F10: 0 | G10: 0 | H10: 0 | I10: 0 | J10: 0 | K10: 0 | L10: 0 | M10: 0 | N10: 0
A11: Nsolo M07 | B11: ELI-460 | C11: 0 | D11: 0 | E11: 0 | F11: 0 | G11: 0 | H11: 0 | I11: 0 | J11: 0 | K11: 0 | L11: 0 | M11: 0 | N11: 0
A12: Nsolo Pride F02 | B12: ELI-209 | C12: 0 | D12: 0 | E12: 0 | F12: 0 | G12: 1 | H12: 0 | I12: 0 | J12: 0 | K12: 0 | L12: 0 | M12: 0 | N12: 0
A13: Nsolo Pride F03 | B13: ELI-210 | C13: 0 | D13: 0 | E13: 0 | F13: 1 | G13: 1 | H13: 0 | I13: 1 | J13: 0 | K13: 0 | L13: 0 | M13: 0 | N13: 0
A14: Nsolo Pride F05 | B14: ELI-212 | C14: 0 | D14: 0 | E14: 0 | F14: 0 | G14: 0 | H14: 0 | I14: 0 | J14: 0 | K14: 0 | L14: 0 | M14: 0 | N14: 0
A18: Group
A19: Nsolo 2 | B19: ELI-700 | C19: 0 | D19: 0 | E19: 0 | F19: 1 | G19: 0 | H19: 0 | I19: 0 | J19: 1 | K19: 0 | L19: 0 | M19: 1 | N19: 0
A20: Nsolo 2 | B20: ELI-701 | C20: 0 | D20: 0 | E20: 0 | F20: 1 | G20: 0 | H20: 0 | I20: 0 | J20: 1 | K20: 0 | L20: 0 | M20: 1 | N20: 1
A21: Nsolo 2 | B21: ELI-702 | C21: 0 | D21: 0 | E21: 0 | F21: 1 | G21: 0 | H21: 0 | I21: 0 | J21: 1 | K21: 0 | L21: 0 | M21: 1 | N21: 0
C24: Jan | D24: Feb | E24: Mar | F24: Apr | G24: May | H24: Jun | I24: Jul | J24: Aug | K24: Sept | L24: Oct | M24: Nov | N24: Dec
A25: Group | B25: ID
A26: Saltpan 2011 Cub U01 | B26: ELI-468 | D26: 0 | E26: 0 | F26: 0 | G26: 0 | H26: 0 | I26: 0 | J26: 0 | K26: 0 | L26: 0 | M26: 0 | N26: 0
A27: Saltpan F01 | B27: ELI-182 | D27: 0 | E27: 0 | F27: 0 | G27: 0 | H27: 0 | I27: 0 | J27: 0 | K27: 0 | L27: 0 | M27: 0 | N27: 0
A28: Saltpan F03 | B28: ELI-261 | D28: 0 | E28: 0 | F28: 0 | G28: 0 | H28: 0 | I28: 0 | J28: 0 | K28: 0 | L28: 0 | M28: 0 | N28: 0
A29: Saltpan F04 | B29: ELI-185 | D29: 0 | E29: 0 | F29: 0 | G29: 0 | H29: 0 | I29: 0 | J29: 0 | K29: 0 | L29: 0 | M29: 0 | N29: 0
A30: Saltpan F06 | B30: ELI-257 | D30: 0 | E30: 0 | F30: 0 | G30: 0 | H30: 0 | I30: 0 | J30: 0 | K30: 0 | L30: 0 | M30: 0 | N30: 0
A31: Saltpan F07 | B31: ELI-183 | D31: 0 | E31: 0 | F31: 0 | G31: 0 | H31: 0 | I31: 0 | J31: 0 | K31: 0 | L31: 0 | M31: 0 | N31: 0
A32: Saltpan F08 | B32: ELI-189 | D32: 0 | E32: 0 | F32: 0 | G32: 0 | H32: 0 | I32: 0 | J32: 0 | K32: 0 | L32: 0 | M32: 0 | N32: 0
A33: Saltpan F09 | B33: ELI-465 | D33: 0 | E33: 0 | F33: 0 | G33: 0 | H33: 0 | I33: 0 | J33: 0 | K33: 0 | L33: 0 | M33: 0 | N33: 0
A34: Saltpan F10 | B34: ELI-467 | D34: 0 | E34: 0 | F34: 0 | G34: 0 | H34: 0 | I34: 0 | J34: 0 | K34: 0 | L34: 0 | M34: 0 | N34: 0
A35: Saltpan M02 | B35: ELI-259 | D35: 0 | E35: 0 | F35: 0 | G35: 0 | H35: 0 | I35: 0 | J35: 0 | K35: 0 | L35: 0 | M35: 0 | N35: 0
A36: Saltpan M04 | B36: ELI-187 | D36: 0 | E36: 0 | F36: 0 | G36: 0 | H36: 0 | I36: 0 | J36: 0 | K36: 0 | L36: 0 | M36: 0 | N36: 0

Sheet Coa
D1: Jan | E1: Feb | F1: Mar | G1: Apr | H1: May | I1: Jun | J1: Jul | K1: Aug | L1: Sept | M1: Oct | N1: Nov | O1: Dec
B2: Group | C2: ID
A3: Saltpan COA | B3: Saltpan Coa M02 | C3: ELI-179 | D3: 0 | E3: 0 | F3: 0 | G3: 0 | H3: 0 | I3: 0 | J3: 0 | K3: 0 | L3: 0 | M3: 0 | N3: 0 | O3: 0
A4: Big Pride COA | B4: Big Pride M04 | C4: ELI-167 | D4: 0 | E4: 0 | F4: 0 | G4: 0 | H4: 0 | I4: 0 | J4: 0 | K4: 0 | L4: 0 | M4: 0 | N4: 0 | O4: 0
A5: Big Pride COA | B5: Big Pride M05 | C5: ELI-168 | D5: 0 | E5: 0 | F5: 0 | G5: 0 | H5: 0 | I5: 0 | J5: 0 | K5: 0 | L5: 0 | M5: 0 | N5: 0 | O5: 0
A6: Big Pride COA | B6: Big Pride M06 | C6: ELI-169 | D6: 0 | E6: 0 | F6: 0 | G6: 0 | H6: 0 | I6: 0 | J6: 0 | K6: 0 | L6: 0 | M6: 0 | N6: 0 | O6: 0
A7: Mwamba COA | B7: Mwamba Coa M02 | C7: ELI-421 | D7: 0 | E7: 0 | F7: 0 | G7: 0 | H7: 0 | I7: 0 | J7: 0 | K7: 1 | L7: 0 | M7: 0 | N7: 1 | O7: 0
A8: Mwamba COA | B8: Mwamba Coa M03 | C8: ELI-422 | D8: 0 | E8: 0 | F8: 0 | G8: 0 | H8: 0 | I8: 0 | J8: 0 | K8: 0 | L8: 0 | M8: 0 | N8: 0 | O8: 0
A9: Mwamba COA | B9: Mwamba Coa M01 | C9: ELI-420 | D9: 0 | E9: 0 | F9: 0 | G9: 0 | H9: 0 | I9: 0 | J9: 0 | K9: 1 | L9: 0 | M9: 0 | N9: 0 | O9: 0
A10: Tafika COA | B10: Tafika F01 | C10: ELI-475 | D10: 0 | E10: 0 | F10: 0 | G10: 0 | H10: 0 | I10: 0 | J10: 0 | K10: 0 | L10: 0 | M10: 0 | N10: 0 | O10: 0
A11: Tafika COA | B11: Tafika M01 | C11: ELI-476 | D11: 0 | E11: 0 | F11: 0 | G11: 0 | H11: 0 | I11: 0 | J11: 0 | K11: 0 | L11: 0 | M11: 0 | N11: 0 | O11: 0
A12: Tafika COA | B12: Tafika M02 | C12: ELI-477 | D12: 0 | E12: 0 | F12: 0 | G12: 0 | H12: 0 | I12: 0 | J12: 0 | K12: 0 | L12: 0 | M12: 0 | N12: 0 | O12: 0
A13: Tafika COA | B13: Tafika M03 | C13: ELI-478 | D13: 0 | E13: 0 | F13: 0 | G13: 0 | H13: 0 | I13: 0 | J13: 0 | K13: 0 | L13: 0 | M13: 0 | N13: 0 | O13: 0
A14: Tsetse COA | B14: Tsetse Coa M01 | C14: ELI-564 | D14: 0 | E14: 0 | F14: 0 | G14: 0 | H14: 1 | I14: 0 | J14: 0 | K14: 0 | L14: 0 | M14: 0 | N14: 1 | O14: 0
... A34: New Luwi COA | B34: New Luwi | C34: ELI-779 | D34: 0 | E34: 0 | F34: 0 | G34: 0 | H34: 1 | I34: 0 | J34: 0 | K34: 1 | L34: 0 | M34: 1 | N34: 1 | O34: 0

Sheet pride covariates
A1: pride | B1: collared
A2: Big Pride | B2: 1
A3: Chichele | B3: 1
A4: Chowo | B4: 1
A5: Nsefu | B5: 1
A6: Hot Springs | B6: 1
A7: Kapamba | B7: 0
A8: Hollywood | B8: 0
A9: Mwamba I | B9: 1
A10: Mwamba II | B10: 0
A11: Chamilandu | B11: 0
A12: Luwi | B12: 1
A13: Nsolo | B13: 1
... A37: Chinzombo | B37: 1

Sheet allpride
A1: pride | B1: altname | C1: lionid | D1: jan | E1: feb | F1: mar | G1: apr | H1: may | I1: jun | J1: jul | K1: aug | L1: sep | M1: oct | N1: nov | O1: dec | P1: sexknown | Q1: sexmale | R1: knowndead | S1: dobknown | T1: yearatfirst | U1: monthatfirst | V1: ageatfirst | W1: collaredgroup | X1: sexmale(altenrate m and f if not known)
A2: Big Pride | B2: Big Pride 2013 Cub 1 | C2: ELI-583 | D2: 0 | E2: 0 | F2: 0 | G2: 0 | H2: 0 | I2: 0 | J2: 1 | K2: 1 | L2: 1 | M2: 1 | N2: 1 | O2: 1 | P2: 1 | Q2: 1 | R2: 0 | S2: 1 | T2: 2013 | U2: 7 | V2: 0 | W2: =VLOOKUP(A2,'pride covariates'!A$2:B$33,2,FALSE) -> 1 | X2: 1 | Y2: =CONCATENATE("/* ",C2," */ ",G2,H2,I2,J2,K2,L2,M2,N2," 1"," ",P2," ",S2," ",R2," ",X2," ",V2," ",W2,";") -> /* ELI-583 */ 00011111 1 1 1 0 1 0 1; | Z2: =CONCATENATE(G2,H2,I2,J2,K2,L2,M2,N2) -> 00011111 | AA2: =CONCATENATE("/*",C2,"*/ ",G2,H2,I2,J2,K2,L2,M2,N2," 1",";") -> /*ELI-583*/ 00011111 1;
A3: Big Pride | B3: Big Pride 2013 Cub 2 | C3: ELI-584 | D3: 0 | E3: 0 | F3: 0 | G3: 0 | H3: 0 | I3: 0 | J3: 1 | K3: 1 | L3: 1 | M3: 1 | N3: 1 | O3: 1 | P3: 1 | Q3: 0 | R3: 0 | S3: 1 | T3: 2013 | U3: 7 | V3: 0 | W3: =VLOOKUP(A3,'pride covariates'!A$2:B$33,2,FALSE) -> 1 | X3: 0 | Y3: =CONCATENATE("/* ",C3," */ ",G3,H3,I3,J3,K3,L3,M3,N3," 1"," ",P3," ",S3," ",R3," ",X3," ",V3," ",W3,";") -> /* ELI-584 */ 00011111 1 1 1 0 0 0 1; | Z3: =CONCATENATE(G3,H3,I3,J3,K3,L3,M3,N3) -> 00011111 | AA3: =CONCATENATE("/*",C3,"*/ ",G3,H3,I3,J3,K3,L3,M3,N3," 1",";") -> /*ELI-584*/ 00011111 1;
A4: Big Pride | B4: Big Pride 2013 Cub 3 | C4: ELI-585 | D4: 0 | E4: 0 | F4: 0 | G4: 0 | H4: 0 | I4: 0 | J4: 1 | K4: 1 | L4: 1 | M4: 1 | N4: 1 | O4: 1 | P4: 1 | Q4: 0 | R4: 0 | S4: 1 | T4: 2013 | U4: 7 | V4: 0 | W4: =VLOOKUP(A4,'pride covariates'!A$2:B$33,2,FALSE) -> 1 | X4: 0 | Y4: =CONCATENATE("/* ",C4," */ ",G4,H4,I4,J4,K4,L4,M4,N4," 1"," ",P4," ",S4," ",R4," ",X4," ",V4," ",W4,";") -> /* ELI-585 */ 00011111 1 1 1 0 0 0 1; | Z4: =CONCATENATE(G4,H4,I4,J4,K4,L4,M4,N4) -> 00011111 | AA4: =CONCATENATE("/*",C4,"*/ ",G4,H4,I4,J4,K4,L4,M4,N4," 1",";") -> /*ELI-585*/ 00011111 1;
A5: Big Pride | B5: Big Pride 2013 Cub 4 | C5: ELI-586 | D5: 0 | E5: 0 | F5: 0 | G5: 0 | H5: 0 | I5: 0 | J5: 1 | K5: 1 | L5: 1 | M5: 1 | N5: 1 | O5: 1 | P5: 1 | Q5: 1 | R5: 0 | S5: 1 | T5: 2013 | U5: 7 | V5: 0 | W5: =VLOOKUP(A5,'pride covariates'!A$2:B$33,2,FALSE) -> 1 | X5: 1 | Y5: =CONCATENATE("/* ",C5," */ ",G5,H5,I5,J5,K5,L5,M5,N5," 1"," ",P5," ",S5," ",R5," ",X5," ",V5," ",W5,";") -> /* ELI-586 */ 00011111 1 1 1 0 1 0 1; | Z5: =CONCATENATE(G5,H5,I5,J5,K5,L5,M5,N5) -> 00011111 | AA5: =CONCATENATE("/*",C5,"*/ ",G5,H5,I5,J5,K5,L5,M5,N5," 1",";") -> /*ELI-586*/ 00011111 1;
A6: Big Pride | B6: Big Pride 2013 Cub 5 | C6: ELI-587 | D6: 0 | E6: 0 | F6: 0 | G6: 0 | H6: 0 | I6: 0 | J6: 1 | K6: 1 | L6: 1 | M6: 1 | N6: 1 | O6: 1 | P6: 1 | Q6: 0 | R6: 0 | S6: 1 | T6: 2013 | U6: 7 | V6: 0 | W6: =VLOOKUP(A6,'pride covariates'!A$2:B$33,2,FALSE) -> 1 | X6: 0 | Y6: =CONCATENATE("/* ",C6," */ ",G6,H6,I6,J6,K6,L6,M6,N6," 1"," ",P6," ",S6," ",R6," ",X6," ",V6," ",W6,";") -> /* ELI-587 */ 00011111 1 1 1 0 0 0 1; | Z6: =CONCATENATE(G6,H6,I6,J6,K6,L6,M6,N6) -> 00011111 | AA6: =CONCATENATE("/*",C6,"*/ ",G6,H6,I6,J6,K6,L6,M6,N6," 1",";") -> /*ELI-587*/ 00011111 1;
A7: Big Pride | B7: Big Pride 2013 Cub 6 | C7: ELI-590 | D7: 0 | E7: 0 | F7: 0 | G7: 1 | H7: 0 | I7: 0 | J7: 1 | K7: 1 | L7: 1 | M7: 1 | N7: 1 | O7: 1 | P7: 1 | Q7: 0 | R7: 0 | S7: 1 | T7: 2013 | U7: 4 | V7: 0 | W7: =VLOOKUP(A7,'pride covariates'!A$2:B$33,2,FALSE) -> 1 | X7: 0 | Y7: =CONCATENATE("/* ",C7," */ ",G7,H7,I7,J7,K7,L7,M7,N7," 1"," ",P7," ",S7," ",R7," ",X7," ",V7," ",W7,";") -> /* ELI-590 */ 10011111 1 1 1 0 0 0 1; | Z7: =CONCATENATE(G7,H7,I7,J7,K7,L7,M7,N7) -> 10011111 | AA7: =CONCATENATE("/*",C7,"*/ ",G7,H7,I7,J7,K7,L7,M7,N7," 1",";") -> /*ELI-590*/ 10011111 1;
A8: Big Pride | B8: Big Pride 2013 Cub 7 | C8: ELI-591 | D8: 0 | E8: 0 | F8: 0 | G8: 1 | H8: 0 | I8: 0 | J8: 1 | K8: 0 | L8: 0 | M8: 0 | N8: 0 | O8: 0 | P8: 0 | Q8: NA | R8: 1 | S8: 1 | T8: 2013 | U8: 4 | V8: 0 | W8: =VLOOKUP(A8,'pride covariates'!A$2:B$33,2,FALSE) -> 1 | X8: 0 | Y8: =CONCATENATE("/* ",C8," */ ",G8,H8,I8,J8,K8,L8,M8,N8," 1"," ",P8," ",S8," ",R8," ",X8," ",V8," ",W8,";") -> /* ELI-591 */ 10010000 1 0 1 1 0 0 1; | Z8: =CONCATENATE(G8,H8,I8,J8,K8,L8,M8,N8) -> 10010000 | AA8: =CONCATENATE("/*",C8,"*/ ",G8,H8,I8,J8,K8,L8,M8,N8," 1",";") -> /*ELI-591*/ 10010000 1;
A9: Big Pride | B9: Big Pride 2013 Cub 8 | C9: ELI-592 | D9: 0 | E9: 0 | F9: 0 | G9: 1 | H9: 0 | I9: 0 | J9: 1 | K9: 1 | L9: 1 | M9: 1 | N9: 1 | O9: 1 | P9: 1 | Q9: 0 | R9: 0 | S9: 1 | T9: 2013 | U9: 4 | V9: 0 | W9: =VLOOKUP(A9,'pride covariates'!A$2:B$33,2,FALSE) -> 1 | X9: 0 | Y9: =CONCATENATE("/* ",C9," */ ",G9,H9,I9,J9,K9,L9,M9,N9," 1"," ",P9," ",S9," ",R9," ",X9," ",V9," ",W9,";") -> /* ELI-592 */ 10011111 1 1 1 0 0 0 1; | Z9: =CONCATENATE(G9,H9,I9,J9,K9,L9,M9,N9) -> 10011111 | AA9: =CONCATENATE("/*",C9,"*/ ",G9,H9,I9,J9,K9,L9,M9,N9," 1",";") -> /*ELI-592*/ 10011111 1;
A10: Big Pride | B10: Big Pride 2013 Cub 9 | C10: ELI-593 | D10: 0 | E10: 0 | F10: 0 | G10: 0 | H10: 0 | I10: 0 | J10: 1 | K10: 1 | L10: 1 | M10: 1 | N10: 1 | O10: 1 | P10: 1 | Q10: 1 | R10: 0 | S10: 1 | T10: 2013 | U10: 7 | V10: 0 | W10: =VLOOKUP(A10,'pride covariates'!A$2:B$33,2,FALSE) -> 1 | X10: 1 | Y10: =CONCATENATE("/* ",C10," */ ",G10,H10,I10,J10,K10,L10,M10,N10," 1"," ",P10," ",S10," ",R10," ",X10," ",V10," ",W10,";") -> /* ELI-593 */ 00011111 1 1 1 0 1 0 1; | Z10: =CONCATENATE(G10,H10,I10,J10,K10,L10,M10,N10) -> 00011111 | AA10: =CONCATENATE("/*",C10,"*/ ",G10,H10,I10,J10,K10,L10,M10,N10," 1",";") -> /*ELI-593*/ 00011111 1;
A11: Big Pride | B11: Big Pride 2013 Cub 10 | C11: ELI-594 | D11: 0 | E11: 0 | F11: 0 | G11: 0 | H11: 0 | I11: 0 | J11: 1 | K11: 1 | L11: 1 | M11: 1 | N11: 0 | O11: 1 | P11: 1 | Q11: 0 | R11: 0 | S11: 1 | T11: 2013 | U11: 7 | V11: 0 | W11: =VLOOKUP(A11,'pride covariates'!A$2:B$33,2,FALSE) -> 1 | X11: 0 | Y11: =CONCATENATE("/* ",C11," */ ",G11,H11,I11,J11,K11,L11,M11,N11," 1"," ",P11," ",S11," ",R11," ",X11," ",V11," ",W11,";") -> /* ELI-594 */ 00011110 1 1 1 0 0 0 1; | Z11: =CONCATENATE(G11,H11,I11,J11,K11,L11,M11,N11) -> 00011110 | AA11: =CONCATENATE("/*",C11,"*/ ",G11,H11,I11,J11,K11,L11,M11,N11," 1",";") -> /*ELI-594*/ 00011110 1;
A12: Big Pride | B12: Big Pride 2013 Cub 11 | C12: ELI-595 | D12: 0 | E12: 0 | F12: 0 | G12: 0 | H12: 0 | I12: 0 | J12: 1 | K12: 0 | L12: 0 | M12: 1 | N12: 0 | O12: 1 | P12: 1 | Q12: 1 | R12: 0 | S12: 1 | T12: 2013 | U12: 7 | V12: 0 | W12: =VLOOKUP(A12,'pride covariates'!A$2:B$33,2,FALSE) -> 1 | X12: 1 | Y12: =CONCATENATE("/* ",C12," */ ",G12,H12,I12,J12,K12,L12,M12,N12," 1"," ",P12," ",S12," ",R12," ",X12," ",V12," ",W12,";") -> /* ELI-595 */ 00010010 1 1 1 0 1 0 1; | Z12: =CONCATENATE(G12,H12,I12,J12,K12,L12,M12,N12) -> 00010010 | AA12: =CONCATENATE("/*",C12,"*/ ",G12,H12,I12,J12,K12,L12,M12,N12," 1",";") -> /*ELI-595*/ 00010010 1;
A13: Big Pride | B13: Big Pride 2013 Cub 12 | C13: ELI-596 | D13: 0 | E13: 0 | F13: 0 | G13: 0 | H13: 0 | I13: 0 | J13: 1 | K13: 0 | L13: 0 | M13: 0 | N13: 0 | O13: 0 | P13: 0 | Q13: NA | R13: 1 | S13: 1 | T13: 2013 | U13: 7 | V13: 0 | W13: =VLOOKUP(A13,'pride covariates'!A$2:B$33,2,FALSE) -> 1 | X13: 1 | Y13: =CONCATENATE("/* ",C13," */ ",G13,H13,I13,J13,K13,L13,M13,N13," 1"," ",P13," ",S13," ",R13," ",X13," ",V13," ",W13,";") -> /* ELI-596 */ 00010000 1 0 1 1 1 0 1; | Z13: =CONCATENATE(G13,H13,I13,J13,K13,L13,M13,N13) -> 00010000 | AA13: =CONCATENATE("/*",C13,"*/ ",G13,H13,I13,J13,K13,L13,M13,N13," 1",";") -> /*ELI-596*/ 00010000 1;
A14: Big Pride | B14: Big Pride F01 | C14: ELI-243 | D14: 0 | E14: 1 | F14: 1 | G14: 1 | H14: 0 | I14: 1 | J14: 1 | K14: 1 | L14: 1 | M14: 1 | N14: 1 | O14: 1 | P14: 1 | Q14: 0 | R14: 0 | S14: 1 | T14: 2008 | U14: 10 | V14: 3 | W14: =VLOOKUP(A14,'pride covariates'!A$2:B$33,2,FALSE) -> 1 | X14: 0 | Y14: =CONCATENATE("/* ",C14," */ ",G14,H14,I14,J14,K14,L14,M14,N14," 1"," ",P14," ",S14," ",R14," ",X14," ",V14," ",W14,";") -> /* ELI-243 */ 10111111 1 1 1 0 0 3 1; | Z14: =CONCATENATE(G14,H14,I14,J14,K14,L14,M14,N14) -> 10111111 | AA14: =CONCATENATE("/*",C14,"*/ ",G14,H14,I14,J14,K14,L14,M14,N14," 1",";") -> /*ELI-243*/ 10111111 1;
A15: Big Pride | B15: Big Pride F02 | C15: ELI-242 | D15: 0 | E15: 0 | F15: 0 | G15: 0 | H15: 0 | I15: 1 | J15: 1 | K15: 1 | L15: 1 | M15: 1 | N15: 1 | O15: 1 | P15: 1 | Q15: 0 | R15: 0 | S15: 1 | T15: 2008 | U15: 10 | V15: 6 | W15: =VLOOKUP(A15,'pride covariates'!A$2:B$33,2,FALSE) -> 1 | X15: 0 | Y15: =CONCATENATE("/* ",C15," */ ",G15,H15,I15,J15,K15,L15,M15,N15," 1"," ",P15," ",S15," ",R15," ",X15," ",V15," ",W15,";") -> /* ELI-242 */ 00111111 1 1 1 0 0 6 1; | Z15: =CONCATENATE(G15,H15,I15,J15,K15,L15,M15,N15) -> 00111111 | AA15: =CONCATENATE("/*",C15,"*/ ",G15,H15,I15,J15,K15,L15,M15,N15," 1",";") -> /*ELI-242*/ 00111111 1;
A16: Big Pride | B16: Big Pride F04 | C16: ELI-224 | D16: 0 | E16: 0 | F16: 0 | G16: 0 | H16: 0 | I16: 1 | J16: 0 | K16: 1 | L16: 1 | M16: 0 | N16: 1 | O16: 0 | P16: 1 | Q16: 0 | R16: 0 | S16: 1 | T16: 2009 | U16: 4 | V16: 4 | W16: =VLOOKUP(A16,'pride covariates'!A$2:B$33,2,FALSE) -> 1 | X16: 0 | Y16: =CONCATENATE("/* ",C16," */ ",G16,H16,I16,J16,K16,L16,M16,N16," 1"," ",P16," ",S16," ",R16," ",X16," ",V16," ",W16,";") -> /* ELI-224 */ 00101101 1 1 1 0 0 4 1; | Z16: =CONCATENATE(G16,H16,I16,J16,K16,L16,M16,N16) -> 00101101 | AA16: =CONCATENATE("/*",C16,"*/ ",G16,H16,I16,J16,K16,L16,M16,N16," 1",";") -> /*ELI-224*/ 00101101 1;
A17: Big Pride | B17: Big Pride F05 | C17: ELI-245 | D17: 0 | E17: 0 | F17: 0 | G17: 0 | H17: 0 | I17: 1 | J17: 1 | K17: 1 | L17: 1 | M17: 1 | N17: 1 | O17: 1 | P17: 1 | Q17: 0 | R17: 0 | S17: 1 | T17: 2008 | U17: 10 | V17: 1 | W17: =VLOOKUP(A17,'pride covariates'!A$2:B$33,2,FALSE) -> 1 | X17: 0 | Y17: =CONCATENATE("/* ",C17," */ ",G17,H17,I17,J17,K17,L17,M17,N17," 1"," ",P17," ",S17," ",R17," ",X17," ",V17," ",W17,";") -> /* ELI-245 */ 00111111 1 1 1 0 0 1 1; | Z17: =CONCATENATE(G17,H17,I17,J17,K17,L17,M17,N17) -> 00111111 | AA17: =CONCATENATE("/*",C17,"*/ ",G17,H17,I17,J17,K17,L17,M17,N17," 1",";") -> /*ELI-245*/ 00111111 1;
A18: Big Pride | B18: Big Pride F06 | C18: ELI-223 | D18: 0 | E18: 0 | F18: 0 | G18: 0 | H18: 0 | I18: 1 | J18: 1 | K18: 1 | L18: 1 | M18: 1 | N18: 1 | O18: 1 | P18: 1 | Q18: 0 | R18: 0 | S18: 1 | T18: 2008 | U18: 10 | V18: 1 | W18: =VLOOKUP(A18,'pride covariates'!A$2:B$33,2,FALSE) -> 1 | X18: 0 | Y18: =CONCATENATE("/* ",C18," */ ",G18,H18,I18,J18,K18,L18,M18,N18," 1"," ",P18," ",S18," ",R18," ",X18," ",V18," ",W18,";") -> /* ELI-223 */ 00111111 1 1 1 0 0 1 1; | Z18: =CONCATENATE(G18,H18,I18,J18,K18,L18,M18,N18) -> 00111111 | AA18: =CONCATENATE("/*",C18,"*/ ",G18,H18,I18,J18,K18,L18,M18,N18," 1",";") -> /*ELI-223*/ 00111111 1;
A19: Big Pride | B19: Big Pride F07 | C19: ELI-220 | D19: 0 | E19: 0 | F19: 0 | G19: 0 | H19: 0 | I19: 1 | J19: 1 | K19: 1 | L19: 1 | M19: 1 | N19: 1 | O19: 1 | P19: 1 | Q19: 0 | R19: 0 | S19: 1 | T19: 2008 | U19: 10 | V19: 0 | W19: =VLOOKUP(A19,'pride covariates'!A$2:B$33,2,FALSE) -> 1 | X19: 0 | Y19: =CONCATENATE("/* ",C19," */ ",G19,H19,I19,J19,K19,L19,M19,N19," 1"," ",P19," ",S19," ",R19," ",X19," ",V19," ",W19,";") -> /* ELI-220 */ 00111111 1 1 1 0 0 0 1; | Z19: =CONCATENATE(G19,H19,I19,J19,K19,L19,M19,N19) -> 00111111 | AA19: =CONCATENATE("/*",C19,"*/ ",G19,H19,I19,J19,K19,L19,M19,N19," 1",";") -> /*ELI-220*/ 00111111 1;
A20: Big Pride | B20: Big Pride F08 | C20: ELI-218 | D20: 0 | E20: 0 | F20: 0 | G20: 0 | H20: 0 | I20: 1 | J20: 1 | K20: 1 | L20: 1 | M20: 1 | N20: 1 | O20: 1 | P20: 1 | Q20: 0 | R20: 0 | S20: 1 | T20: 2009 | U20: 4 | V20: 1 | W20: =VLOOKUP(A20,'pride covariates'!A$2:B$33,2,FALSE) -> 1 | X20: 0 | Y20: =CONCATENATE("/* ",C20," */ ",G20,H20,I20,J20,K20,L20,M20,N20," 1"," ",P20," ",S20," ",R20," ",X20," ",V20," ",W20,";") -> /* ELI-218 */ 00111111 1 1 1 0 0 1 1; | Z20: =CONCATENATE(G20,H20,I20,J20,K20,L20,M20,N20) -> 00111111 | AA20: =CONCATENATE("/*",C20,"*/ ",G20,H20,I20,J20,K20,L20,M20,N20," 1",";") -> /*ELI-218*/ 00111111 1;
A21: Big Pride | B21: Big Pride F09 | C21: ELI-143 | D21: 0 | E21: 0 | F21: 0 | G21: 0 | H21: 0 | I21: 1 | J21: 0 | K21: 0 | L21: 0 | M21: 0 | N21: 0 | O21: 0 | P21: 1 | Q21: 0 | R21: 0 | S21: 1 | T21: 2009 | U21: 7 | V21: 1 | W21: =VLOOKUP(A21,'pride covariates'!A$2:B$33,2,FALSE) -> 1 | X21: 0 | Y21: =CONCATENATE("/* ",C21," */ ",G21,H21,I21,J21,K21,L21,M21,N21," 1"," ",P21," ",S21," ",R21," ",X21," ",V21," ",W21,";") -> /* ELI-143 */ 00100000 1 1 1 0 0 1 1; | Z21: =CONCATENATE(G21,H21,I21,J21,K21,L21,M21,N21) -> 00100000 | AA21: =CONCATENATE("/*",C21,"*/ ",G21,H21,I21,J21,K21,L21,M21,N21," 1",";") -> /*ELI-143*/ 00100000 1;
A22: Big Pride | B22: Big Pride F10 | C22: ELI-219 | D22: 0 | E22: 0 | F22: 0 | G22: 0 | H22: 0 | I22: 1 | J22: 1 | K22: 1 | L22: 1 | M22: 1 | N22: 1 | O22: 1 | P22: 1 | Q22: 0 | R22: 0 | S22: 1 | T22: 2008 | U22: 10 | V22: 0 | W22: =VLOOKUP(A22,'pride covariates'!A$2:B$33,2,FALSE) -> 1 | X22: 0 | Y22: =CONCATENATE("/* ",C22," */ ",G22,H22,I22,J22,K22,L22,M22,N22," 1"," ",P22," ",S22," ",R22," ",X22," ",V22," ",W22,";") -> /* ELI-219 */ 00111111 1 1 1 0 0 0 1; | Z22: =CONCATENATE(G22,H22,I22,J22,K22,L22,M22,N22) -> 00111111 | AA22: =CONCATENATE("/*",C22,"*/ ",G22,H22,I22,J22,K22,L22,M22,N22," 1",";") -> /*ELI-219*/ 00111111 1;
A23: Chowo | B23: Chowo F01 | C23: ELI-414 | D23: 1 | E23: 1 | F23: 1 | G23: 1 | H23: 1 | I23: 1 | J23: 1 | K23: 0 | L23: 1 | M23: 1 | N23: 1 | O23: 1 | P23: 1 | Q23: 0 | R23: 0 | S23: 1 | T23: 2011 | U23: 7 | V23: 3 | W23: =VLOOKUP(A23,'pride covariates'!A$2:B$33,2,FALSE) -> 1 | X23: 0 | Y23: =CONCATENATE("/* ",C23," */ ",G23,H23,I23,#REF!,K23,L23,M23,N23," 1"," ",P23," ",S23," ",R23," ",X23," ",V23," ",W23,";") -> #REF! | Z23: =CONCATENATE(G23,H23,I23,#REF!,K23,L23,M23,N23) -> #REF! | AA23: =CONCATENATE("/*",C23,"*/ ",G23,H23,I23,#REF!,K23,L23,M23,N23," 1",";") -> #REF!
A24: Chowo | B24: Chowo F05 | C24: ELI-493 | D24: 0 | E24: 1 | F24: 0 | G24: 1 | H24: 1 | I24: 1 | J24: 0 | K24: 0 | L24: 1 | M24: 1 | N24: 1 | O24: 0 | P24: 1 | Q24: 0 | R24: 0 | S24: 1 | T24: 2012 | U24: 6 | V24: 4 | W24: =VLOOKUP(A24,'pride covariates'!A$2:B$33,2,FALSE) -> 1 | X24: 0 | Y24: =CONCATENATE("/* ",C24," */ ",G24,H24,I24,J23,K24,L24,M24,N24," 1"," ",P24," ",S24," ",R24," ",X24," ",V24," ",W24,";") -> /* ELI-493 */ 11110111 1 1 1 0 0 4 1; | Z24: =CONCATENATE(G24,H24,I24,J23,K24,L24,M24,N24) -> 11110111 | AA24: =CONCATENATE("/*",C24,"*/ ",G24,H24,I24,J23,K24,L24,M24,N24," 1",";") -> /*ELI-493*/ 11110111 1;
A25: Chowo | B25: Chowo F06 | C25: ELI-494 | D25: 0 | E25: 1 | F25: 0 | G25: 1 | H25: 1 | I25: 1 | J25: 0 | K25: 0 | L25: 1 | M25: 1 | N25: 1 | O25: 0 | P25: 1 | Q25: 0 | R25: 0 | S25: 1 | T25: 2012 | U25: 6 | V25: 1 | W25: =VLOOKUP(A25,'pride covariates'!A$2:B$33,2,FALSE) -> 1 | X25: 0 | Y25: =CONCATENATE("/* ",C25," */ ",G25,H25,I25,J25,K25,L25,M25,N25," 1"," ",P25," ",S25," ",R25," ",X25," ",V25," ",W25,";") -> /* ELI-494 */ 11100111 1 1 1 0 0 1 1; | Z25: =CONCATENATE(G25,H25,I25,J25,K25,L25,M25,N25) -> 11100111 | AA25: =CONCATENATE("/*",C25,"*/ ",G25,H25,I25,J25,K25,L25,M25,N25," 1",";") -> /*ELI-494*/ 11100111 1;
A26: Chowo | B26: Chowo | C26: ELI-598 | D26: 0 | E26: 0 | F26: 0 | G26: 1 | H26: 0 | I26: 1 | J26: 0 | K26: 0 | L26: 1 | M26: 1 | N26: 1 | O26: 0 | P26: 1 | Q26: 0 | R26: 0 | S26: 1 | T26: 2013 | U26: 4 | V26: 0 | W26: =VLOOKUP(A26,'pride covariates'!A$2:B$33,2,FALSE) -> 1 | X26: 0 | Y26: =CONCATENATE("/* ",C26," */ ",G26,H26,I26,J26,K26,L26,M26,N26," 1"," ",P26," ",S26," ",R26," ",X26," ",V26," ",W26,";") -> /* ELI-598 */ 10100111 1 1 1 0 0 0 1; | Z26: =CONCATENATE(G26,H26,I26,J26,K26,L26,M26,N26) -> 10100111 | AA26: =CONCATENATE("/*",C26,"*/ ",G26,H26,I26,J26,K26,L26,M26,N26," 1",";") -> /*ELI-598*/ 10100111 1;
A27: Chowo | B27: Chowo | C27: ELI-599 | D27: 0 | E27: 0 | F27: 0 | G27: 1 | H27: 0 | I27: 1 | J27: 0 | K27: 0 | L27: 1 | M27: 1 | N27: 1 | O27: 0 | P27: 1 | Q27: 0 | R27: 0 | S27: 1 | T27: 2013 | U27: 4 | V27: 0 | W27: =VLOOKUP(A27,'pride covariates'!A$2:B$33,2,FALSE) -> 1 | X27: 0 | Y27: =CONCATENATE("/* ",C27," */ ",G27,H27,I27,J27,K27,L27,M27,N27," 1"," ",P27," ",S27," ",R27," ",X27," ",V27," ",W27,";") -> /* ELI-599 */ 10100111 1 1 1 0 0 0 1; | Z27: =CONCATENATE(G27,H27,I27,J27,K27,L27,M27,N27) -> 10100111 | AA27: =CONCATENATE("/*",C27,"*/ ",G27,H27,I27,J27,K27,L27,M27,N27," 1",";") -> /*ELI-599*/ 10100111 1;
A28: Chowo | B28: Chowo | C28: ELI-597 | D28: 0 | E28: 0 | F28: 0 | G28: 1 | H28: 0 | I28: 0 | J28: 0 | K28: 0 | L28: 0 | M28: 0 | N28: 0 | O28: 0 | P28: 0 | Q28: NA | R28: 1 | S28: 1 | T28: 2013 | U28: 4 | V28: 0 | W28: =VLOOKUP(A28,'pride covariates'!A$2:B$33,2,FALSE) -> 1 | X28: 0 | Y28: =CONCATENATE("/* ",C28," */ ",G28,H28,I28,J28,K28,L28,M28,N28," 1"," ",P28," ",S28," ",R28," ",X28," ",V28," ",W28,";") -> /* ELI-597 */ 10000000 1 0 1 1 0 0 1; | Z28: =CONCATENATE(G28,H28,I28,J28,K28,L28,M28,N28) -> 10000000 | AA28: =CONCATENATE("/*",C28,"*/ ",G28,H28,I28,J28,K28,L28,M28,N28," 1",";") -> /*ELI-597*/ 10000000 1;
A29: Chowo | B29: Chowo U01 | C29: ELI-523 | D29: 0 | E29: 1 | F29: 0 | G29: 1 | H29: 0 | I29: 1 | J29: 0 | K29: 0 | L29: 1 | M29: 0 | N29: 0 | O29: 0 | P29: 0 | Q29: NA | R29: 1 | S29: 1 | T29: 2012 | U29: 10 | V29: 0 | W29: =VLOOKUP(A29,'pride covariates'!A$2:B$33,2,FALSE) -> 1 | X29: 1 | Y29: =CONCATENATE("/* ",C29," */ ",G29,H29,I29,J29,K29,L29,M29,N29," 1"," ",P29," ",S29," ",R29," ",X29," ",V29," ",W29,";") -> /* ELI-523 */ 10100100 1 0 1 1 1 0 1; | Z29: =CONCATENATE(G29,H29,I29,J29,K29,L29,M29,N29) -> 10100100 | AA29: =CONCATENATE("/*",C29,"*/ ",G29,H29,I29,J29,K29,L29,M29,N29," 1",";") -> /*ELI-523*/ 10100100 1;
A30: Chowo | B30: Chowo U02 | C30: ELI-524 | D30: 0 | E30: 1 | F30: 0 | G30: 1 | H30: 0 | I30: 1 | J30: 0 | K30: 0 | L30: 1 | M30: 1 | N30: 1 | O30: 0 | P30: 1 | Q30: 0 | R30: 0 | S30: 1 | T30: 2012 | U30: 10 | V30: 0 | W30: =VLOOKUP(A30,'pride covariates'!A$2:B$33,2,FALSE) -> 1 | X30: 0 | Y30: =CONCATENATE("/* ",C30," */ ",G30,H30,I30,J30,K30,L30,M30,N30," 1"," ",P30," ",S30," ",R30," ",X30," ",V30," ",W30,";") -> /* ELI-524 */ 10100111 1 1 1 0 0 0 1; | Z30: =CONCATENATE(G30,H30,I30,J30,K30,L30,M30,N30) -> 10100111 | AA30: =CONCATENATE("/*",C30,"*/ ",G30,H30,I30,J30,K30,L30,M30,N30," 1",";") -> /*ELI-524*/ 10100111 1;
A31: Chowo | B31: Chowo U03 | C31: ELI-525 | D31: 0 | E31: 1 | F31: 0 | G31: 1 | H31: 0 | I31: 0 | J31: 0 | K31: 0 | L31: 0 | M31: 0 | N31: 0 | O31: 0 | P31: 0 | Q31: NA | R31: 1 | S31: 1 | T31: 2012 | U31: 10 | V31: 0 | W31: =VLOOKUP(A31,'pride covariates'!A$2:B$33,2,FALSE) -> 1 | X31: 0 | Y31: =CONCATENATE("/* ",C31," */ ",G31,H31,I31,J31,K31,L31,M31,N31," 1"," ",P31," ",S31," ",R31," ",X31," ",V31," ",W31,";") -> /* ELI-525 */ 10000000 1 0 1 1 0 0 1; | Z31: =CONCATENATE(G31,H31,I31,J31,K31,L31,M31,N31) -> 10000000 | AA31: =CONCATENATE("/*",C31,"*/ ",G31,H31,I31,J31,K31,L31,M31,N31," 1",";") -> /*ELI-525*/ 10000000 1;
A32: Chichele | B32: Chichele F02 | C32: ELI-236 | D32: 0 | E32: 0 | F32: 1 | G32: 1 | H32: 1 | I32: 1 | J32: 1 | K32: 0 | L32: 1 | M32: 0 | N32: 0 | O32: 1 | P32: 1 | Q32: 0 | R32: 0 | S32: 1 | T32: 2008 | U32: 9 | V32: 5 | W32: =VLOOKUP(A32,'pride covariates'!A$2:B$33,2,FALSE) -> 1 | X32: 0 | Y32: =CONCATENATE("/* ",C32," */ ",G32,H32,I32,J32,K32,L32,M32,N32," 1"," ",P32," ",S32," ",R32," ",X32," ",V32," ",W32,";") -> /* ELI-236 */ 11110100 1 1 1 0 0 5 1; | Z32: =CONCATENATE(G32,H32,I32,J32,K32,L32,M32,N32) -> 11110100 | AA32: =CONCATENATE("/*",C32,"*/ ",G32,H32,I32,J32,K32,L32,M32,N32," 1",";") -> /*ELI-236*/ 11110100 1;
A33: Chichele | B33: Chichele F03 | C33: ELI-235 | D33: 0 | E33: 1 | F33: 1 | G33: 1 | H33: 1 | I33: 1 | J33: 1 | K33: 0 | L33: 1 | M33: 1 | N33: 0 | O33: 1 | P33: 1 | Q33: 0 | R33: 0 | S33: 1 | T33: 2008 | U33: 9 | V33: 2 | W33: =VLOOKUP(A33,'pride covariates'!A$2:B$33,2,FALSE) -> 1 | X33: 0 | Y33: =CONCATENATE("/* ",C33," */ ",G33,H33,I33,J33,K33,L33,M33,N33," 1"," ",P33," ",S33," ",R33," ",X33," ",V33," ",W33,";") -> /* ELI-235 */ 11110110 1 1 1 0 0 2 1; | Z33: =CONCATENATE(G33,H33,I33,J33,K33,L33,M33,N33) -> 11110110 | AA33: =CONCATENATE("/*",C33,"*/ ",G33,H33,I33,J33,K33,L33,M33,N33," 1",";") -> /*ELI-235*/ 11110110 1;
A34: Chichele | B34: Chichele F04 | C34: ELI-554 | D34: 0 | E34: 0 | F34: 1 | G34: 1 | H34: 1 | I34: 1 | J34: 1 | K34: 0 | L34: 0 | M34: 0 | N34: 0 | O34: 0 | P34: 1 | Q34: 0 | R34: 0 | S34: 1 | T34: 2012 | U34: 11 | V34: 0 | W34: =VLOOKUP(A34,'pride covariates'!A$2:B$33,2,FALSE) -> 1 | X34: 0 | Y34: =CONCATENATE("/* ",C34," */ ",G34,H34,I34,J34,K34,L34,M34,N34," 1"," ",P34," ",S34," ",R34," ",X34," ",V34," ",W34,";") -> /* ELI-554 */ 11110000 1 1 1 0 0 0 1; | Z34: =CONCATENATE(G34,H34,I34,J34,K34,L34,M34,N34) -> 11110000 | AA34: =CONCATENATE("/*",C34,"*/ ",G34,H34,I34,J34,K34,L34,M34,N34," 1",";") -> /*ELI-554*/ 11110000 1;
A35: Chichele | B35: Chichele F05 | C35: ELI-555 | D35: 0 | E35: 0 | F35: 1 | G35: 1 | H35: 1 | I35: 1 | J35: 1 | K35: 0 | L35: 0 | M35: 0 | N35: 0 | O35: 0 | P35: 1 | Q35: 0 | R35: 0 | S35: 1 | T35: 2012 | U35: 11 | V35: 0 | W35: =VLOOKUP(A35,'pride covariates'!A$2:B$33,2,FALSE) -> 1 | X35: 0 | Y35: =CONCATENATE("/* ",C35," */ ",G35,H35,I35,J35,K35,L35,M35,N35," 1"," ",P35," ",S35," ",R35," ",X35," ",V35," ",W35,";") -> /* ELI-555 */ 11110000 1 1 1 0 0 0 1; | Z35: =CONCATENATE(G35,H35,I35,J35,K35,L35,M35,N35) -> 11110000 | AA35: =CONCATENATE("/*",C35,"*/ ",G35,H35,I35,J35,K35,L35,M35,N35," 1",";") -> /*ELI-555*/ 11110000 1;
A36: Chichele | B36: Chichele M03 | C36: ELI-556 | D36: 0 | E36: 0 | F36: 1 | G36: 1 | H36: 1 | I36: 1 | J36: 1 | K36: 0 | L36: 0 | M36: 0 | N36: 0 | O36: 0 | P36: 1 | Q36: 1 | R36: 0 | S36: 1 | T36: 2012 | U36: 11 | V36: 0 | W36: =VLOOKUP(A36,'pride covariates'!A$2:B$33,2,FALSE) -> 1 | X36: 1 | Y36: =CONCATENATE("/* ",C36," */ ",G36,H36,I36,J36,K36,L36,M36,N36," 1"," ",P36," ",S36," ",R36," ",X36," ",V36," ",W36,";") -> /* ELI-556 */ 11110000 1 1 1 0 1 0 1; | Z36: =CONCATENATE(G36,H36,I36,J36,K36,L36,M36,N36) -> 11110000 | AA36: =CONCATENATE("/*",C36,"*/ ",G36,H36,I36,J36,K36,L36,M36,N36," 1",";") -> /*ELI-556*/ 11110000 1;
A37: Nsefu | B37: Nsefu F01 | C37: ELI-173 | D37: 0 | E37: 0 | F37: 0 | G37: 0 | H37: 1 | I37: 1 | J37: 0 | K37: 0 | L37: 1 | M37: 1 | N37: 1 | O37: 0 | P37: 1 | Q37: 0 | R37: 0 | S37: 1 | T37: 2008 | U37: 8 | V37: 2 | W37: =VLOOKUP(A37,'pride covariates'!A$2:B$33,2,FALSE) -> 1 | X37: 0 | Y37: =CONCATENATE("/* ",C37," */ ",G37,H37,I37,J37,K37,L37,M37,N37," 1"," ",P37," ",S37," ",R37," ",X37," ",V37," ",W37,";") -> /* ELI-173 */ 01100111 1 1 1 0 0 2 1; | Z37: =CONCATENATE(G37,H37,I37,J37,K37,L37,M37,N37) -> 01100111 | AA37: =CONCATENATE("/*",C37,"*/ ",G37,H37,I37,J37,K37,L37,M37,N37," 1",";") -> /*ELI-173*/ 01100111 1;
A38: Nsefu | B38: Nsefu F02 | C38: ELI-174 | D38: 0 | E38: 0 | F38: 0 | G38: 0 | H38: 1 | I38: 1 | J38: 1 | K38: 0 | L38: 1 | M38: 0 | N38: 1 | O38: 0 | P38: 1 | Q38: 0 | R38: 0 | S38: 1 | T38: 2008 | U38: 8 | V38: 6 | W38: =VLOOKUP(A38,'pride covariates'!A$2:B$33,2,FALSE) -> 1 | X38: 0 | Y38: =CONCATENATE("/* ",C38," */ ",G38,H38,I38,J38,K38,L38,M38,N38," 1"," ",P38," ",S38," ",R38," ",X38," ",V38," ",W38,";") -> /* ELI-174 */ 01110101 1 1 1 0 0 6 1; | Z38: =CONCATENATE(G38,H38,I38,J38,K38,L38,M38,N38) -> 01110101 | AA38: =CONCATENATE("/*",C38,"*/ ",G38,H38,I38,J38,K38,L38,M38,N38," 1",";") -> /*ELI-174*/ 01110101 1;
A39: Nsefu | B39: Nsefu F03 | C39: ELI-247 | D39: 0 | E39: 0 | F39: 0 | G39: 0 | H39: 1 | I39: 1 | J39: 0 | K39: 0 | L39: 1 | M39: 1 | N39: 1 | O39: 0 | P39: 1 | Q39: 0 | R39: 0 | S39: 1 | T39: 2009 | U39: 8 | V39: 3 | W39: =VLOOKUP(A39,'pride covariates'!A$2:B$33,2,FALSE) -> 1 | X39: 0 | Y39: =CONCATENATE("/* ",C39," */ ",G39,H39,I39,J39,K39,L39,M39,N39," 1"," ",P39," ",S39," ",R39," ",X39," ",V39," ",W39,";") -> /* ELI-247 */ 01100111 1 1 1 0 0 3 1; | Z39: =CONCATENATE(G39,H39,I39,J39,K39,L39,M39,N39) -> 01100111 | AA39: =CONCATENATE("/*",C39,"*/ ",G39,H39,I39,J39,K39,L39,M39,N39," 1",";") -> /*ELI-247*/ 01100111 1;
A40: Nsefu | B40: Nsefu F04 | C40: ELI-248 | D40: 0 | E40: 0 | F40: 0 | G40: 0 | H40: 1 | I40: 1 | J40: 1 | K40: 1 | L40: 1 | M40: 1 | N40: 1 | O40: 1 | P40: 1 | Q40: 0 | R40: 0 | S40: 1 | T40: 2009 | U40: 11 | V40: 3 | W40: =VLOOKUP(A40,'pride covariates'!A$2:B$33,2,FALSE) -> 1 | X40: 0 | Y40: =CONCATENATE("/* ",C40," */ ",G40,H40,I40,J40,K40,L40,M40,N40," 1"," ",P40," ",S40," ",R40," ",X40," ",V40," ",W40,";") -> /* ELI-248 */ 01111111 1 1 1 0 0 3 1; | Z40: =CONCATENATE(G40,H40,I40,J40,K40,L40,M40,N40) -> 01111111 | AA40: =CONCATENATE("/*",C40,"*/ ",G40,H40,I40,J40,K40,L40,M40,N40," 1",";") -> /*ELI-248*/ 01111111 1;
...

Sheet input_format
A1: =CONCATENATE("/*",LEFT(allpride!C2,7),"*/ ",allpride!G2,allpride!H2,allpride!I2,allpride!J2,allpride!K2,allpride!L2,allpride!M2,allpride!N2," 1;") -> /*ELI-583*/ 00011111 1;
A2: =CONCATENATE("/*",LEFT(allpride!C3,7),"*/ ",allpride!G3,allpride!H3,allpride!I3,allpride!J3,allpride!K3,allpride!L3,allpride!M3,allpride!N3," 1;") -> /*ELI-584*/ 00011111 1;
A3: =CONCATENATE("/*",LEFT(allpride!C4,7),"*/ ",allpride!G4,allpride!H4,allpride!I4,allpride!J4,allpride!K4,allpride!L4,allpride!M4,allpride!N4," 1;") -> /*ELI-585*/ 00011111 1;
A4: =CONCATENATE("/*",LEFT(allpride!C5,7),"*/ ",allpride!G5,allpride!H5,allpride!I5,allpride!J5,allpride!K5,allpride!L5,allpride!M5,allpride!N5," 1;") -> /*ELI-586*/ 00011111 1;
A5: =CONCATENATE("/*",LEFT(allpride!C6,7),"*/ ",allpride!G6,allpride!H6,allpride!I6,allpride!J6,allpride!K6,allpride!L6,allpride!M6,allpride!N6," 1;") -> /*ELI-587*/ 00011111 1;
A6: =CONCATENATE("/*",LEFT(allpride!C7,7),"*/ ",allpride!G7,allpride!H7,allpride!I7,allpride!J7,allpride!K7,allpride!L7,allpride!M7,allpride!N7," 1;") -> /*ELI-590*/ 10011111 1;
A7: =CONCATENATE("/*",LEFT(allpride!C8,7),"*/ ",allpride!G8,allpride!H8,allpride!I8,allpride!J8,allpride!K8,allpride!L8,allpride!M8,allpride!N8," 1;") -> /*ELI-591*/ 10010000 1;
A8: =CONCATENATE("/*",LEFT(allpride!C9,7),"*/ ",allpride!G9,allpride!H9,allpride!I9,allpride!J9,allpride!K9,allpride!L9,allpride!M9,allpride!N9," 1;") -> /*ELI-592*/ 10011111 1;
A9: =CONCATENATE("/*",LEFT(allpride!C10,7),"*/ ",allpride!G10,allpride!H10,allpride!I10,allpride!J10,allpride!K10,allpride!L10,allpride!M10,allpride!N10," 1;") -> /*ELI-593*/ 00011111 1;
A10: =CONCATENATE("/*",LEFT(allpride!C11,7),"*/ ",allpride!G11,allpride!H11,allpride!I11,allpride!J11,allpride!K11,allpride!L11,allpride!M11,allpride!N11," 1;") -> /*ELI-594*/ 00011110 1;
A11: =CONCATENATE("/*",LEFT(allpride!C12,7),"*/ ",allpride!G12,allpride!H12,allpride!I12,allpride!J12,allpride!K12,allpride!L12,allpride!M12,allpride!N12," 1;") -> /*ELI-595*/ 00010010 1;
A12: =CONCATENATE("/*",LEFT(allpride!C13,7),"*/ ",allpride!G13,allpride!H13,allpride!I13,allpride!J13,allpride!K13,allpride!L13,allpride!M13,allpride!N13," 1;") -> /*ELI-596*/ 00010000 1;
... A148: =CONCATENATE("/*",LEFT(allpride!C149,7),"*/ ",allpride!G149,allpride!H149,allpride!I149,allpride!J149,allpride!K149,allpride!L149,allpride!M149,allpride!N149," 1;") -> /*ELI-972*/ 00000110 1;

Sheet 2013_slnp_lion_ch
A1: /*ELI-583*/ 00011111 1;
A2: /*ELI-584*/ 00011111 1;
A3: /*ELI-585*/ 00011111 1;
A4: /*ELI-586*/ 00011111 1;
A5: /*ELI-587*/ 00011111 1;
A6: /*ELI-590*/ 10011111 1;
A7: /*ELI-591*/ 10010000 1;
A8: /*ELI-592*/ 10011111 1;
A9: /*ELI-593*/ 00011111 1;
A10: /*ELI-594*/ 00011110 1;
A11: /*ELI-595*/ 00010010 1;
A12: /*ELI-596*/ 00010000 1;
... A148: /*ELI-972*/ 00000110 1;

Sheet 2013_slnp_lion_3monRD
A1: =CONCATENATE("/*",allpride!C2,"*/ ",allpride!F2,allpride!G2,allpride!H2,allpride!L2,allpride!M2,allpride!N2," 1;") -> /*ELI-583*/ 000111 1;
A2: =CONCATENATE("/*",allpride!C3,"*/ ",allpride!F3,allpride!G3,allpride!H3,allpride!L3,allpride!M3,allpride!N3," 1;") -> /*ELI-584*/ 000111 1;
A3: =CONCATENATE("/*",allpride!C4,"*/ ",allpride!F4,allpride!G4,allpride!H4,allpride!L4,allpride!M4,allpride!N4," 1;") -> /*ELI-585*/ 000111 1;
A4: =CONCATENATE("/*",allpride!C5,"*/ ",allpride!F5,allpride!G5,allpride!H5,allpride!L5,allpride!M5,allpride!N5," 1;") -> /*ELI-586*/ 000111 1;
A5: =CONCATENATE("/*",allpride!C6,"*/ ",allpride!F6,allpride!G6,allpride!H6,allpride!L6,allpride!M6,allpride!N6," 1;") -> /*ELI-587*/ 000111 1;
A6: =CONCATENATE("/*",allpride!C7,"*/ ",allpride!F7,allpride!G7,allpride!H7,allpride!L7,allpride!M7,allpride!N7," 1;") -> /*ELI-590*/ 010111 1;
A7: =CONCATENATE("/*",allpride!C8,"*/ ",allpride!F8,allpride!G8,allpride!H8,allpride!L8,allpride!M8,allpride!N8," 1;") -> /*ELI-591*/ 010000 1;
A8: =CONCATENATE("/*",allpride!C9,"*/ ",allpride!F9,allpride!G9,allpride!H9,allpride!L9,allpride!M9,allpride!N9," 1;") -> /*ELI-592*/ 010111 1;
A9: =CONCATENATE("/*",allpride!C10,"*/ ",allpride!F10,allpride!G10,allpride!H10,allpride!L10,allpride!M10,allpride!N10," 1;") -> /*ELI-593*/ 000111 1;
A10: =CONCATENATE("/*",allpride!C11,"*/ ",allpride!F11,allpride!G11,allpride!H11,allpride!L11,allpride!M11,allpride!N11," 1;") -> /*ELI-594*/ 000110 1;
A11: =CONCATENATE("/*",allpride!C12,"*/ ",allpride!F12,allpride!G12,allpride!H12,allpride!L12,allpride!M12,allpride!N12," 1;") -> /*ELI-595*/ 000010 1;
A12: =CONCATENATE("/*",allpride!C13,"*/ ",allpride!F13,allpride!G13,allpride!H13,allpride!L13,allpride!M13,allpride!N13," 1;") -> /*ELI-596*/ 000000 1;
... A148: =CONCATENATE("/*",allpride!C149,"*/ ",allpride!F149,allpride!G149,allpride!H149,allpride!L149,allpride!M149,allpride!N149," 1;") -> /*ELI-972*/ 000110 1;
