Workbook

Sheet BCC
C1: Jan | D1: Feb | E1: Mar | F1: Apr | G1: May | H1: Jun | I1: Jul | J1: Aug | K1: Sept | L1: Oct | M1: Nov | N1: Dec
A2: Group | B2: ID
A3: Big F09 | B3: ELI-581 | C3: 0 | D3: 0 | E3: 0 | F3: 0 | G3: 0 | H3: 0 | I3: 0 | J3: 0 | K3: 0 | L3: 0 | M3: 0 | N3: 0
A4: Big Pride 2013 Cub 1 | B4: ELI-583 | C4: 0 | D4: 0 | E4: 0 | F4: 1 | G4: 0 | H4: 1 | I4: 0 | J4: 1 | K4: 0 | L4: 0 | M4: 0 | N4: 0
A5: Big Pride 2013 Cub 2 | B5: ELI-584 | C5: 0 | D5: 0 | E5: 0 | F5: 1 | G5: 1 | H5: 1 | I5: 1 | J5: 1 | K5: 1 | L5: 1 | M5: 1 | N5: 0
A6: Big Pride 2013 Cub 3 | B6: ELI-585 | C6: 0 | D6: 0 | E6: 0 | F6: 1 | G6: 1 | H6: 1 | I6: 1 | J6: 1 | K6: 1 | L6: 1 | M6: 1 | N6: 0
A7: Big Pride 2013 Cub 4 | B7: ELI-586 | C7: 0 | D7: 0 | E7: 0 | F7: 1 | G7: 1 | H7: 1 | I7: 1 | J7: 1 | K7: 1 | L7: 1 | M7: 1 | N7: 0
A8: Big Pride 2013 Cub 5 | B8: ELI-587 | C8: 0 | D8: 0 | E8: 0 | F8: 1 | G8: 1 | H8: 1 | I8: 1 | J8: 1 | K8: 1 | L8: 1 | M8: 1 | N8: 0
A9: Big Pride 2013 Cub 6 | B9: ELI-590 | C9: 0 | D9: 0 | E9: 0 | F9: 1 | G9: 1 | H9: 1 | I9: 1 | J9: 1 | K9: 1 | L9: 1 | M9: 1 | N9: 0
A10: Big Pride 2013 Cub 7 | B10: ELI-591 | C10: 0 | D10: 0 | E10: 0 | F10: 0 | G10: 0 | H10: 0 | I10: 0 | J10: 0 | K10: 0 | L10: 0 | M10: 0 | N10: 0
A11: Big Pride 2013 Cub 8 | B11: ELI-592 | C11: 0 | D11: 0 | E11: 0 | F11: 1 | G11: 1 | H11: 1 | I11: 1 | J11: 1 | K11: 1 | L11: 1 | M11: 1 | N11: 0
A12: Big Pride 2013 Cub 9 | B12: ELI-593 | C12: 0 | D12: 0 | E12: 0 | F12: 1 | G12: 1 | H12: 1 | I12: 1 | J12: 1 | K12: 1 | L12: 1 | M12: 1 | N12: 0
A13: Big Pride 2013 Cub 10 | B13: ELI-594 | C13: 0 | D13: 0 | E13: 0 | F13: 1 | G13: 1 | H13: 1 | I13: 1 | J13: 1 | K13: 1 | L13: 1 | M13: 1 | N13: 0
A14: Big Pride 2013 Cub 11 | B14: ELI-595 | C14: 0 | D14: 0 | E14: 0 | F14: 1 | G14: 1 | H14: 1 | I14: 1 | J14: 1 | K14: 1 | L14: 1 | M14: 1 | N14: 0
... A31: 2014 Cub 5 | B31: ELI-769 | C31: 0 | D31: 0 | E31: 0 | F31: 1 | G31: 0 | H31: 0 | I31: 0 | J31: 0 | K31: 1 | L31: 1 | M31: 1 | N31: 0
C34: Jan | D34: Feb | E34: Mar | F34: Apr | G34: May | H34: Jun | I34: Jul | J34: Aug | K34: Sept | L34: Oct | M34: Nov | N34: Dec
A35: Group | B35: ID
A36: Chowo F01 | B36: ELI-414 | C36: 0 | D36: 0 | E36: 1 | F36: 0 | G36: 1 | H36: 0 | I36: 1 | J36: 1 | K36: 1 | L36: 1 | M36: 1 | N36: 0
A37: Chowo F02 | B37: ELI-415 | C37: 0 | D37: 0 | E37: 0 | F37: 0 | G37: 0 | H37: 0 | I37: 0 | J37: 0 | K37: 0 | L37: 0 | M37: 0 | N37: 0
A38: Chowo F03 | B38: ELI-436 | C38: 0 | D38: 0 | E38: 0 | F38: 0 | G38: 0 | H38: 0 | I38: 0 | J38: 0 | K38: 0 | L38: 0 | M38: 0 | N38: 0
A39: Chowo F04 | B39: ELI-413 | C39: 0 | D39: 0 | E39: 0 | F39: 0 | G39: 0 | H39: 0 | I39: 0 | J39: 0 | K39: 0 | L39: 0 | M39: 0 | N39: 0
A40: Chowo F05 | B40: ELI-493 | C40: 0 | D40: 0 | E40: 1 | F40: 0 | G40: 0 | H40: 0 | I40: 1 | J40: 1 | K40: 1 | L40: 1 | M40: 1 | N40: 0
A41: Chowo F06 | B41: ELI-494 | C41: 0 | D41: 0 | E41: 1 | F41: 0 | G41: 1 | H41: 0 | I41: 0 | J41: 1 | K41: 1 | L41: 1 | M41: 1 | N41: 0
A42: Chowo U01 | B42: ELI-523 | C42: 0 | D42: 0 | E42: 0 | F42: 0 | G42: 0 | H42: 0 | I42: 0 | J42: 0 | K42: 0 | L42: 0 | M42: 0 | N42: 0
A43: Chowo U02 | B43: ELI-524 | C43: 0 | D43: 0 | E43: 1 | F43: 0 | G43: 1 | H43: 0 | I43: 1 | J43: 1 | K43: 1 | L43: 1 | M43: 1 | N43: 0
A44: Chowo U03 | B44: ELI-525 | C44: 0 | D44: 0 | E44: 0 | F44: 0 | G44: 0 | H44: 0 | I44: 0 | J44: 0 | K44: 0 | L44: 0 | M44: 0 | N44: 0
B45: ELI-598 | C45: 0 | D45: 0 | E45: 1 | F45: 0 | G45: 1 | H45: 0 | I45: 1 | J45: 1 | K45: 1 | L45: 1 | M45: 1 | N45: 0
B46: ELI-599 | C46: 0 | D46: 0 | E46: 1 | F46: 0 | G46: 1 | H46: 0 | I46: 1 | J46: 1 | K46: 1 | L46: 1 | M46: 1 | N46: 0
C49: Jan | D49: Feb | E49: Mar | F49: Apr | G49: May | H49: Jun | I49: Jul | J49: Aug | K49: Sept | L49: Oct | M49: Nov | N49: Dec
A50: Group | B50: ID
A51: Chichele F02 | B51: ELI-236 | C51: 0 | D51: 0 | E51: 1 | F51: 1 | G51: 1 | H51: 1 | I51: 1 | J51: 1 | K51: 1 | L51: 0 | M51: 1 | N51: 0
A52: Chichele F03 | B52: ELI-235 | C52: 0 | D52: 0 | E52: 1 | F52: 1 | G52: 1 | H52: 1 | I52: 1 | J52: 1 | K52: 1 | L52: 0 | M52: 1 | N52: 0
A53: Chichele F04 | B53: ELI-554 | C53: 0 | D53: 0 | E53: 0 | F53: 0 | G53: 0 | H53: 0 | I53: 0 | J53: 0 | K53: 0 | L53: 0 | M53: 0 | N53: 0
A54: Chichele F05 | B54: ELI-555 | C54: 0 | D54: 0 | E54: 0 | F54: 0 | G54: 0 | H54: 0 | I54: 0 | J54: 0 | K54: 0 | L54: 0 | M54: 0 | N54: 0
A55: Chichele M02 | B55: ELI-238 | C55: 0 | D55: 0 | E55: 0 | F55: 0 | G55: 0 | H55: 0 | I55: 0 | J55: 0 | K55: 0 | L55: 0 | M55: 0 | N55: 0
A56: Chichele M03 | B56: ELI-556 | C56: 0 | D56: 0 | E56: 0 | F56: 0 | G56: 0 | H56: 0 | I56: 0 | J56: 0 | K56: 0 | L56: 0 | M56: 0 | N56: 0
B57: ELI-604 | C57: 0 | D57: 0 | E57: 1 | F57: 1 | G57: 1 | H57: 1 | I57: 1 | J57: 1 | K57: 1 | L57: 0 | M57: 1 | N57: 0
B58: ELI-606 | C58: 0 | D58: 0 | E58: 1 | F58: 1 | G58: 1 | H58: 1 | I58: 1 | J58: 1 | K58: 1 | L58: 0 | M58: 1 | N58: 0
B59: ELI-607 | C59: 0 | D59: 0 | E59: 1 | F59: 1 | G59: 1 | H59: 1 | I59: 1 | J59: 1 | K59: 1 | L59: 0 | M59: 1 | N59: 0
C63: Jan | D63: Feb | E63: Mar | F63: Apr | G63: May | H63: Jun | I63: Jul | J63: Aug | K63: Sept | L63: Oct | M63: Nov | N63: Dec
...

Sheet NHK
C1: Jan | D1: Feb | E1: Mar | F1: Apr | G1: May | H1: Jun | I1: Jul | J1: Aug | K1: Sept | L1: Oct | M1: Nov | N1: Dec
A2: Group | B2: ID
A3: Nsefu F01 | B3: ELI-173 | C3: 0 | D3: 0 | E3: 0 | F3: 0 | G3: 0 | H3: 0 | I3: 1 | J3: 0 | K3: 1 | L3: 0 | M3: 1 | N3: 0
A4: Nsefu F02 | B4: ELI-174 | C4: 0 | D4: 0 | E4: 0 | F4: 0 | G4: 1 | H4: 0 | I4: 0 | J4: 0 | K4: 1 | L4: 0 | M4: 1 | N4: 0
A5: Nsefu F03 | B5: ELI-247 | C5: 0 | D5: 0 | E5: 0 | F5: 0 | G5: 1 | H5: 1 | I5: 1 | J5: 0 | K5: 1 | L5: 0 | M5: 1 | N5: 0
A6: Nsefu F04 | B6: ELI-248 | C6: 0 | D6: 0 | E6: 0 | F6: 0 | G6: 1 | H6: 1 | I6: 1 | J6: 1 | K6: 1 | L6: 1 | M6: 1 | N6: 0
A7: Nsefu F05 | B7: ELI-249 | C7: 0 | D7: 0 | E7: 0 | F7: 0 | G7: 0 | H7: 0 | I7: 0 | J7: 0 | K7: 0 | L7: 0 | M7: 0 | N7: 0
A8: Nsefu F06 | B8: ELI-250 | C8: 0 | D8: 0 | E8: 0 | F8: 0 | G8: 1 | H8: 0 | I8: 0 | J8: 1 | K8: 1 | L8: 0 | M8: 1 | N8: 0
A9: Nsefu F07 | B9: ELI-462 | C9: 0 | D9: 0 | E9: 0 | F9: 0 | G9: 1 | H9: 0 | I9: 1 | J9: 0 | K9: 0 | L9: 0 | M9: 1 | N9: 0
A10: Nsefu F11 | B10: ELI-378 | C10: 0 | D10: 0 | E10: 0 | F10: 0 | G10: 1 | H10: 1 | I10: 1 | J10: 1 | K10: 1 | L10: 1 | M10: 0 | N10: 0
A11: Nsefu F12 | B11: ELI-463 | C11: 0 | D11: 0 | E11: 0 | F11: 0 | G11: 0 | H11: 0 | I11: 1 | J11: 0 | K11: 0 | L11: 1 | M11: 1 | N11: 0
A12: Nsefu F13 | B12: ELI-515 | C12: 0 | D12: 0 | E12: 0 | F12: 0 | G12: 0 | H12: 0 | I12: 0 | J12: 0 | K12: 0 | L12: 0 | M12: 0 | N12: 0
A13: Nsefu M02 | B13: ELI-373 | C13: 0 | D13: 0 | E13: 0 | F13: 0 | G13: 0 | H13: 0 | I13: 0 | J13: 0 | K13: 1 | L13: 0 | M13: 0 | N13: 0
A14: Nsefu M03 | B14: ELI-375 | C14: 0 | D14: 0 | E14: 0 | F14: 0 | G14: 0 | H14: 0 | I14: 0 | J14: 0 | K14: 1 | L14: 0 | M14: 0 | N14: 0
... A16: Nsefu M05 | B16: ELI-376 | C16: 0 | D16: 0 | E16: 0 | F16: 0 | G16: 0 | H16: 0 | I16: 1 | J16: 0 | K16: 1 | L16: 0 | M16: 0 | N16: 0
B17: ELI-389 | C17: 0 | D17: 0 | E17: 0 | F17: 0 | G17: 0 | H17: 0 | I17: 0 | J17: 0 | K17: 0 | L17: 0 | M17: 1 | N17: 0
B18: ELI-462 | C18: 0 | D18: 0 | E18: 0 | F18: 0 | G18: 0 | H18: 0 | I18: 0 | J18: 0 | K18: 0 | L18: 0 | M18: 1 | N18: 0
A19: Nsefu M06 | B19: ELI-464 | C19: 0 | D19: 0 | E19: 0 | F19: 1 | G19: 0 | H19: 1 | I19: 1 | J19: 1 | K19: 1 | L19: 0 | M19: 1 | N19: 1
A20: Nsefu M07 | B20: ELI-553 | C20: 0 | D20: 0 | E20: 0 | F20: 0 | G20: 0 | H20: 1 | I20: 1 | J20: 0 | K20: 1 | L20: 0 | M20: 1 | N20: 0
A21: Nsefu F09 | B21: ELI-254 | C21: 0 | D21: 0 | E21: 0 | F21: 0 | G21: 0 | H21: 0 | I21: 0 | J21: 0 | K21: 0 | L21: 0 | M21: 0 | N21: 0
B22: ELI-589 | C22: 0 | D22: 0 | E22: 0 | F22: 1 | G22: 0 | H22: 1 | I22: 1 | J22: 0 | K22: 1 | L22: 0 | M22: 1 | N22: 0
B23: ELI-628 | C23: 0 | D23: 0 | E23: 0 | F23: 0 | G23: 0 | H23: 0 | I23: 1 | J23: 1 | K23: 1 | L23: 0 | M23: 0 | N23: 0
B24: ELI-629 | C24: 0 | D24: 0 | E24: 0 | F24: 0 | G24: 0 | H24: 0 | I24: 1 | J24: 1 | K24: 1 | L24: 0 | M24: 0 | N24: 0
B25: ELI-713 | C25: 0 | D25: 0 | E25: 0 | F25: 0 | G25: 0 | H25: 0 | I25: 1 | J25: 1 | K25: 1 | L25: 0 | M25: 1 | N25: 0
B26: ELI-714 | C26: 0 | D26: 0 | E26: 0 | F26: 0 | G26: 0 | H26: 0 | I26: 1 | J26: 1 | K26: 1 | L26: 0 | M26: 1 | N26: 0
B27: ELI-715 | C27: 0 | D27: 0 | E27: 0 | F27: 0 | G27: 0 | H27: 0 | I27: 1 | J27: 0 | K27: 1 | L27: 0 | M27: 1 | N27: 0
B28: ELI-716 | C28: 0 | D28: 0 | E28: 0 | F28: 0 | G28: 0 | H28: 0 | I28: 1 | J28: 1 | K28: 1 | L28: 0 | M28: 1 | N28: 0
B29: ELI-717 | C29: 0 | D29: 0 | E29: 0 | F29: 0 | G29: 0 | H29: 0 | I29: 1 | J29: 0 | K29: 1 | L29: 0 | M29: 1 | N29: 0
B30: ELI-718 | C30: 0 | D30: 0 | E30: 0 | F30: 0 | G30: 0 | H30: 0 | I30: 1 | J30: 0 | K30: 1 | L30: 0 | M30: 1 | N30: 0
B31: ELI-719 | C31: 0 | D31: 0 | E31: 0 | F31: 0 | G31: 0 | H31: 0 | I31: 1 | J31: 0 | K31: 1 | L31: 0 | M31: 1 | N31: 0
C36: Jan | D36: Feb | E36: Mar | F36: Apr | G36: May | H36: Jun | I36: Jul | J36: Aug | K36: Sept | L36: Oct | M36: Nov | N36: Dec
A37: Group | B37: ID
A38: Hot Springs F01 | B38: ELI-258 | C38: 0 | D38: 0 | E38: 0 | F38: 0 | G38: 0 | H38: 0 | I38: 0 | J38: 0 | K38: 0 | L38: 1 | M38: 1 | N38: 0
A39: Hot Springs F02 | B39: ELI-256 | C39: 0 | D39: 0 | E39: 0 | F39: 0 | G39: 0 | H39: 0 | I39: 0 | J39: 0 | K39: 0 | L39: 1 | M39: 1 | N39: 0
A40: Hot Springs F03 | B40: ELI-466 | C40: 0 | D40: 0 | E40: 0 | F40: 0 | G40: 0 | H40: 0 | I40: 0 | J40: 0 | K40: 0 | L40: 0 | M40: 0 | N40: 0
A41: Hot Springs M01 | B41: ELI-379 | C41: 0 | D41: 0 | E41: 0 | F41: 0 | G41: 0 | H41: 0 | I41: 0 | J41: 0 | K41: 0 | L41: 0 | M41: 0 | N41: 0
A42: Hot Springs | B42: ELI-510 | C42: 0 | D42: 0 | E42: 0 | F42: 1 | G42: 1 | H42: 1 | I42: 0 | J42: 1 | K42: 1 | L42: 1 | M42: 1 | N42: 0
B43: ELI-511 | C43: 0 | D43: 0 | E43: 0 | F43: 1 | G43: 1 | H43: 1 | I43: 0 | J43: 1 | K43: 1 | L43: 1 | M43: 1 | N43: 0
B44: ELI-394 | C44: 0 | D44: 0 | E44: 0 | F44: 1 | G44: 0 | H44: 1 | I44: 1 | J44: 0 | K44: 1 | L44: 1 | M44: 1 | N44: 1
B45: ELI-514 | C45: 0 | D45: 0 | E45: 0 | F45: 1 | G45: 1 | H45: 1 | I45: 1 | J45: 1 | K45: 1 | L45: 1 | M45: 1 | N45: 0
...

Sheet CH
C1: Jan | D1: Feb | E1: Mar | F1: Apr | G1: May | H1: Jun | I1: Jul | J1: Aug | K1: Sept | L1: Oct | M1: Nov | N1: Dec
A2: Group | B2: ID
A3: 2011 Cub U01 | B3: ELI-438
A4: 2011 Cub U02 | B4: ELI-441
A5: 2011 Cub U03 | B5: ELI-442
A6: 2011 Cub U04 | B6: ELI-443
A7: Chamilandu F01 | B7: ELI-192
A8: Chamilandu F02 | B8: ELI-193
A9: Chamilandu F03 | B9: ELI-194
A10: Chamilandu F05 | B10: ELI-228
A11: Chamilandu F06 | B11: ELI-398
A12: Chamilandu F07 | B12: ELI-405
A13: Chamilandu F08 | B13: ELI-444
... A18: Chamilandu Male Cub 01 | B18: ELI-196
C22: Jan | D22: Feb | E22: Mar | F22: April | G22: May | H22: Jun | I22: Jul | J22: Aug | K22: Sept | L22: Oct | M22: Nov | N22: Dec
A23: Group | B23: ID
A24: Hollywood M01 | B24: ELI-233
A25: Hollywood Cub 01 '10 | B25: ELI-400
A26: Hollywood Cub 02 '10 | B26: ELI-401
A27: Hollywood F01 | B27: ELI-197 | J27: 1
A28: Hollywood F02 | B28: ELI-198 | J28: 1
A29: Hollywood F03 | B29: ELI-230 | J29: 1
A30: Hollywood F04 | B30: ELI-231 | J30: 1
A31: Hollywood F05 | B31: ELI-232 | J31: 0
A32: Hollywood F06 | B32: ELI-424 | J32: 1
B33: ELI-425 | J33: 1
B34: ELI-612 | J34: 1
B35: ELI-613 | J35: 1
B36: ELI-615 | J36: 1
B37: ELI-616 | J37: 1
B38: ELI-617 | J38: 1
B39: ELI-618 | J39: 1
B40: ELI-735 | J40: 1
B41: ELI-736 | J41: 1
B42: ELI-737 | J42: 1
B43: ELI-738
B44: ELI-739

Sheet LM
C1: Jan | D1: Feb | E1: Mar | F1: Apr | G1: May | H1: Jun | I1: Jul | J1: Aug | K1: Sept | L1: Oct | M1: Nov | N1: Dec
A2: Group | B2: ID
A3: Luwi F01 | B3: ELI-152
A4: Luwi F03 | B4: ELI-154 | G4: 1 | H4: 1 | I4: 1 | J4: 1 | L4: 1
A5: Luwi F04 | B5: ELI-155 | F5: 1 | G5: 1 | H5: 1 | I5: 1 | J5: 1 | K5: 1 | L5: 1
A6: Luwi F08 | B6: ELI-160
A7: Luwi F09 | B7: ELI-241
A8: Luwi F10 | B8: ELI-369 | G8: 0 | H8: 1 | I8: 1 | J8: 1 | K8: 1
A9: Luwi M05 | B9: ELI-370
A10: Manky Ear | B10: ELI-159 | G10: 1 | H10: 1 | I10: 1 | J10: 1 | K10: 1 | L10: 1 | M10: 1
A11: Luwi M01 | B11: ELI-158
A12: Luwi M02 | B12: ELI-161
A13: Ginger | B13: ELI-162
A14: Luwi M04 | B14: ELI-163
B15: ELI-720 | G15: 1 | H15: 1 | I15: 1 | J15: 0
C19: Jan | D19: Feb | E19: Mar | F19: Apr | G19: May | H19: Jun | I19: Jul | J19: Aug | K19: Sept | L19: Oct | M19: Nov | N19: Dec
A20: Group | B20: ID
A21: Mwamba I F01 | B21: ELI-124 | G21: 1 | H21: 1 | I21: 1 | J21: 1
A22: Mwamba I F02 | B22: ELI-125 | G22: 1 | H22: 1 | I22: 1 | J22: 1 | L22: 1
A23: Mwamba I F03 | B23: ELI-246 | I23: 0
A24: Mwamba I F04 | B24: ELI-126 | G24: 1 | H24: 1 | I24: 1 | J24: 1 | L24: 1 | M24: 1 | N24: 1
A25: Mwamba I F05 | B25: ELI-127 | I25: 1 | J25: 1 | L25: 1 | M25: 1 | N25: 1
A26: Mwamba I M03 | B26: ELI-130 | H26: 1
A27: Mwamba II F01 | B27: ELI-134
A28: Mwamba II F02 | B28: ELI-135
A29: Mwamba II F03 | B29: ELI-136
A30: Mwamba II F05 | B30: ELI-138 | I30: 1 | J30: 1 | L30: 1 | N30: 1
A31: Mwamba II F06 | B31: ELI-139
A32: New Mwamba M01 | B32: ELI-430
B33: ELI-469 | I33: 1 | J33: 1 | L33: 1 | N33: 1
B34: ELI-697 | J34: 1 | L34: 1
B35: ELI-657 | G35: 1 | I35: 1 | J35: 1 | L35: 1 | M35: 1 | N35: 1
B36: ELI-658 | G36: 1 | J36: 1 | L36: 1 | M36: 1 | N36: 1
B37: ELI-659 | G37: 1 | I37: 1 | J37: 1 | L37: 1 | M37: 1 | N37: 1
B38: ELI-660 | G38: 1 | H38: 1 | I38: 1 | J38: 1 | L38: 1 | M38: 1 | N38: 1
B39: ELI-661 | I39: 1 | J39: 1 | L39: 1 | M39: 1 | N39: 1
B40: ELI-662 | H40: 1 | I40: 1 | J40: 1 | L40: 1 | M40: 1 | N40: 1
B41: ELI-663 | G41: 1 | H41: 1 | I41: 1 | J41: 1 | L41: 1 | M41: 1
B42: ELI-664 | G42: 1 | H42: 1 | I42: 1 | J42: 1 | L42: 1 | M42: 1
B43: ELI-665 | G43: 1 | H43: 1 | I43: 1 | J43: 1 | L43: 1 | M43: 1
...

Sheet NS
C1: Jan | D1: Feb | E1: Mar | F1: Apr | G1: May | H1: Jun | I1: Jul | J1: Aug | K1: Sept | L1: Oct | M1: Nov | N1: Dec
A2: Group | B2: ID
A3: Nsolo F06 | B3: ELI-215
A4: Nsolo F07 | B4: ELI-454
A5: Nsolo F08 | B5: ELI-455
A6: Nsolo F09 | B6: ELI-458
A7: Nsolo F10 | B7: ELI-459
A8: Nsolo M04 | B8: ELI-461
A9: Nsolo M05 | B9: ELI-456
A10: Nsolo M06 | B10: ELI-457
A11: Nsolo M07 | B11: ELI-460
A12: Nsolo Pride F02 | B12: ELI-209
A13: Nsolo Pride F03 | B13: ELI-210
A14: Nsolo Pride F05 | B14: ELI-212
B15: ELI-61 | K15: 1 | L15: 1 | M15: 1
B16: ELI-667 | L16: 1 | M16: 1
B17: ELI-668 | K17: 1 | L17: 1 | M17: 1
B18: ELI-669 | K18: 1 | L18: 1 | M18: 1
B19: ELI-670 | K19: 1 | L19: 1 | M19: 1
B20: ELI-700 | H20: 1
B21: ELI-701 | H21: 1
B22: ELI-784 | K22: 1 | L22: 1 | M22: 1
B23: ELI-785 | K23: 1 | L23: 1 | M23: 1
B24: ELI-779 | H24: 1
C27: Jan | D27: Feb | E27: Mar | F27: Apr | G27: May | H27: Jun | I27: Jul | J27: Aug | K27: Sept | L27: Oct | M27: Nov | N27: Dec
A28: Group | B28: ID
A29: Saltpan 2011 Cub U01 | B29: ELI-468 | K29: 1 | L29: 1
A30: Saltpan F01 | B30: ELI-182
A31: Saltpan F03 | B31: ELI-261 | L31: 1
A32: Saltpan F04 | B32: ELI-185
A33: Saltpan F06 | B33: ELI-257 | K33: 1 | L33: 1
A34: Saltpan F07 | B34: ELI-183 | K34: 1 | L34: 1
A35: Saltpan F08 | B35: ELI-189 | K35: 1
A36: Saltpan F09 | B36: ELI-465 | L36: 1
A37: Saltpan F10 | B37: ELI-467 | K37: 1 | L37: 1
A38: Saltpan M02 | B38: ELI-259
A39: Saltpan M04 | B39: ELI-187
B40: ELI-770 | L40: 1
B41: ELI-771 | L41: 1
B42: ELI-772 | L42: 1
...

Sheet Coa
C1: Jan | D1: Feb | E1: Mar | F1: Apr | G1: May | H1: Jun | I1: Jul | J1: Aug | K1: Sept | L1: Oct | M1: Nov | N1: Dec
A2: Group | B2: ID
A3: Saltpan Coa M02 | B3: ELI-179
A4: Big Pride M04 | B4: ELI-167
A5: Big Pride M05 | B5: ELI-168 | L5: 1
A6: Big Pride M06 | B6: ELI-169
A7: Tafika F01 | B7: ELI-475
A8: Tafika M01 | B8: ELI-476
A9: Tafika M02 | B9: ELI-477
A10: Tafika M03 | B10: ELI-478
A11: Tsetse Coa M01 | B11: ELI-564 | H11: 1 | M11: 1
A12: Tsetse Coa M02 | B12: ELI-565 | H12: 1 | K12: 1 | L12: 1 | M12: 1
A13: Nsolo I Coa M02 | B13: ELI-207
A14: Nsolo II Coa M01 | B14: ELI-213 | E14: 1 | F14: 1 | G14: 1 | H14: 1 | J14: 1 | L14: 1
A15: Nsolo II Coa M02 | B15: ELI-214 | E15: 1 | F15: 0 | G15: 1 | H15: 1 | J15: 1 | L15: 1 | M15: 1
A16: Nsolo II Coa M03 | B16: ELI-216 | E16: 1 | F16: 1 | G16: 1 | H16: 1 | J16: 1 | K16: 1 | L16: 1
A17: Puku Ridge M01 | B17: ELI-445
A18: Puku Ridge M02 | B18: ELI-267
A19: Malama Coa M01 | B19: ELI-563
A20: Mwamba Coa M01 | B20: ELI-420 | H20: 1 | J20: 1
A21: Mwamba Coa M02 | B21: ELI-421 | H21: 1 | L21: 1
A22: Mwamba Coa M03 | B22: ELI-422 | H22: 1 | J22: 1 | K22: 1
A23: Scarface | B23: ELI-202
A24: Kakonje M02 | B24: ELI-407
A25: Lion Plain M01 | B25: ELI-175 | I25: 1
A26: Luamfwa F01 | B26: ELI-562
A27: Luamfwa M01 | B27: ELI-402
A28: Limpy | B28: ELI-474 | E28: 1
A29: Shaka | B29: ELI-234
A30: Mwamba II F05 | B30: ELI-138
A31: Mwamba II F06 | B31: ELI-139
A32: Zikomo M1 | B32: ELI-130 | H32: 1
A33: Zikomo M2 | B33: ELI-699 | H33: 1
A34: Tafika 2 M1 | B34: ELI-628 | I34: 1 | J34: 1 | K34: 1 | L34: 1 | M34: 1
A35: Tafika 2 M2 | B35: ELI-629 | I35: 1 | J35: 1 | K35: 1 | L35: 1 | M35: 1
A36: New Luwi COA | B36: New Luwi | C36: ELI-779

Sheet allprides
A1: lionid | B1: pride | C1: altname | D1: jan | E1: feb | F1: mar | G1: apr | H1: may | I1: jun | J1: jul | K1: aug | L1: sep | M1: oct | N1: nov | O1: dec | P1: sexknown | Q1: sexmale | R1: knowndead | S1: dobknown | T1: yearatfirst | U1: monthatfirst | V1: ageatfirst | W1: collaredgroup | X1: collaredgroup(0 if unknown) | Y1: sexmale(altenrate m and f if not known)
A2: ELI-583 | B2: Big Pride | C2: Big Pride 2013 Cub 1 | D2: 0 | E2: 0 | F2: 0 | G2: 1 | H2: 1 | I2: 1 | J2: 0 | K2: 0 | L2: 0 | M2: 0 | N2: 0 | O2: 0 | P2: =VLOOKUP(A2,[1]allpride!$C$2:$V$215,14,FALSE) -> 1 | Q2: =VLOOKUP(A2,[1]allpride!$C$2:$V$215,15,FALSE) -> 1 | R2: 1 | S2: =VLOOKUP(A2,[1]allpride!$C$2:$V$215,17,FALSE) -> 1 | T2: =VLOOKUP(A2,[1]allpride!$C$2:$V$215,18,FALSE) -> 2013 | U2: =VLOOKUP(A2,[1]allpride!$C$2:$V$215,19,FALSE) -> 7 | V2: =VLOOKUP(A2,[1]allpride!$C$2:$V$215,20,FALSE) -> 0 | W2: =VLOOKUP(B2,'[2]pride covariates'!$A$2:$B$33,2,FALSE) -> 1 | X2: 1 | Y2: 1 | Z2: =CONCATENATE("/* ",A2," */ ",G2,H2,I2,J2,K2,L2,M2,N2," 1"," ",P2," ",S2," ",R2," ",Y2," ",V2," ",X2,";") -> /* ELI-583 */ 11100000 1 1 1 1 1 0 1; | AA2: =CONCATENATE(G2,H2,I2,J2,K2,L2,M2,N2) -> 11100000 | AB2: =CONCATENATE("/*",A2,"*/ ",G2,H2,I2,J2,K2,L2,M2,N2," 1;") -> /*ELI-583*/ 11100000 1;
A3: ELI-584 | B3: Big Pride | C3: Big Pride 2013 Cub 2 | D3: 0 | E3: 0 | F3: 0 | G3: 1 | H3: 1 | I3: 1 | J3: 1 | K3: 1 | L3: 1 | M3: 1 | N3: 1 | O3: 0 | P3: =VLOOKUP(A3,[1]allpride!$C$2:$V$215,14,FALSE) -> 1 | Q3: =VLOOKUP(A3,[1]allpride!$C$2:$V$215,15,FALSE) -> 0 | R3: =VLOOKUP(A3,[1]allpride!$C$2:$V$215,16,FALSE) -> 0 | S3: =VLOOKUP(A3,[1]allpride!$C$2:$V$215,17,FALSE) -> 1 | T3: =VLOOKUP(A3,[1]allpride!$C$2:$V$215,18,FALSE) -> 2013 | U3: =VLOOKUP(A3,[1]allpride!$C$2:$V$215,19,FALSE) -> 7 | V3: =VLOOKUP(A3,[1]allpride!$C$2:$V$215,20,FALSE) -> 0 | W3: =VLOOKUP(B3,'[2]pride covariates'!$A$2:$B$33,2,FALSE) -> 1 | X3: 1 | Y3: 0 | Z3: =CONCATENATE("/* ",A3," */ ",G3,H3,I3,J3,K3,L3,M3,N3," 1"," ",P3," ",S3," ",R3," ",Y3," ",V3," ",X3,";") -> /* ELI-584 */ 11111111 1 1 1 0 0 0 1; | AA3: =CONCATENATE(G3,H3,I3,J3,K3,L3,M3,N3) -> 11111111 | AB3: =CONCATENATE("/*",A3,"*/ ",G3,H3,I3,J3,K3,L3,M3,N3," 1;") -> /*ELI-584*/ 11111111 1;
A4: ELI-585 | B4: Big Pride | C4: Big Pride 2013 Cub 3 | D4: 0 | E4: 0 | F4: 0 | G4: 1 | H4: 1 | I4: 1 | J4: 1 | K4: 1 | L4: 1 | M4: 1 | N4: 1 | O4: 0 | P4: =VLOOKUP(A4,[1]allpride!$C$2:$V$215,14,FALSE) -> 1 | Q4: =VLOOKUP(A4,[1]allpride!$C$2:$V$215,15,FALSE) -> 0 | R4: =VLOOKUP(A4,[1]allpride!$C$2:$V$215,16,FALSE) -> 0 | S4: =VLOOKUP(A4,[1]allpride!$C$2:$V$215,17,FALSE) -> 1 | T4: =VLOOKUP(A4,[1]allpride!$C$2:$V$215,18,FALSE) -> 2013 | U4: =VLOOKUP(A4,[1]allpride!$C$2:$V$215,19,FALSE) -> 7 | V4: =VLOOKUP(A4,[1]allpride!$C$2:$V$215,20,FALSE) -> 0 | W4: =VLOOKUP(B4,'[2]pride covariates'!$A$2:$B$33,2,FALSE) -> 1 | X4: 1 | Y4: 0 | Z4: =CONCATENATE("/* ",A4," */ ",G4,H4,I4,J4,K4,L4,M4,N4," 1"," ",P4," ",S4," ",R4," ",Y4," ",V4," ",X4,";") -> /* ELI-585 */ 11111111 1 1 1 0 0 0 1; | AA4: =CONCATENATE(G4,H4,I4,J4,K4,L4,M4,N4) -> 11111111 | AB4: =CONCATENATE("/*",A4,"*/ ",G4,H4,I4,J4,K4,L4,M4,N4," 1;") -> /*ELI-585*/ 11111111 1;
A5: ELI-586 | B5: Big Pride | C5: Big Pride 2013 Cub 4 | D5: 0 | E5: 0 | F5: 0 | G5: 1 | H5: 1 | I5: 1 | J5: 1 | K5: 1 | L5: 1 | M5: 1 | N5: 1 | O5: 0 | P5: =VLOOKUP(A5,[1]allpride!$C$2:$V$215,14,FALSE) -> 1 | Q5: =VLOOKUP(A5,[1]allpride!$C$2:$V$215,15,FALSE) -> 1 | R5: =VLOOKUP(A5,[1]allpride!$C$2:$V$215,16,FALSE) -> 0 | S5: =VLOOKUP(A5,[1]allpride!$C$2:$V$215,17,FALSE) -> 1 | T5: =VLOOKUP(A5,[1]allpride!$C$2:$V$215,18,FALSE) -> 2013 | U5: =VLOOKUP(A5,[1]allpride!$C$2:$V$215,19,FALSE) -> 7 | V5: =VLOOKUP(A5,[1]allpride!$C$2:$V$215,20,FALSE) -> 0 | W5: =VLOOKUP(B5,'[2]pride covariates'!$A$2:$B$33,2,FALSE) -> 1 | X5: 1 | Y5: 1 | Z5: =CONCATENATE("/* ",A5," */ ",G5,H5,I5,J5,K5,L5,M5,N5," 1"," ",P5," ",S5," ",R5," ",Y5," ",V5," ",X5,";") -> /* ELI-586 */ 11111111 1 1 1 0 1 0 1; | AA5: =CONCATENATE(G5,H5,I5,J5,K5,L5,M5,N5) -> 11111111 | AB5: =CONCATENATE("/*",A5,"*/ ",G5,H5,I5,J5,K5,L5,M5,N5," 1;") -> /*ELI-586*/ 11111111 1;
A6: ELI-587 | B6: Big Pride | C6: Big Pride 2013 Cub 5 | D6: 0 | E6: 0 | F6: 0 | G6: 1 | H6: 1 | I6: 1 | J6: 1 | K6: 1 | L6: 1 | M6: 1 | N6: 1 | O6: 0 | P6: =VLOOKUP(A6,[1]allpride!$C$2:$V$215,14,FALSE) -> 1 | Q6: =VLOOKUP(A6,[1]allpride!$C$2:$V$215,15,FALSE) -> 0 | R6: =VLOOKUP(A6,[1]allpride!$C$2:$V$215,16,FALSE) -> 0 | S6: =VLOOKUP(A6,[1]allpride!$C$2:$V$215,17,FALSE) -> 1 | T6: =VLOOKUP(A6,[1]allpride!$C$2:$V$215,18,FALSE) -> 2013 | U6: =VLOOKUP(A6,[1]allpride!$C$2:$V$215,19,FALSE) -> 7 | V6: =VLOOKUP(A6,[1]allpride!$C$2:$V$215,20,FALSE) -> 0 | W6: =VLOOKUP(B6,'[2]pride covariates'!$A$2:$B$33,2,FALSE) -> 1 | X6: 1 | Y6: 0 | Z6: =CONCATENATE("/* ",A6," */ ",G6,H6,I6,J6,K6,L6,M6,N6," 1"," ",P6," ",S6," ",R6," ",Y6," ",V6," ",X6,";") -> /* ELI-587 */ 11111111 1 1 1 0 0 0 1; | AA6: =CONCATENATE(G6,H6,I6,J6,K6,L6,M6,N6) -> 11111111 | AB6: =CONCATENATE("/*",A6,"*/ ",G6,H6,I6,J6,K6,L6,M6,N6," 1;") -> /*ELI-587*/ 11111111 1;
A7: ELI-590 | B7: Big Pride | C7: Big Pride 2013 Cub 6 | D7: 0 | E7: 0 | F7: 0 | G7: 1 | H7: 1 | I7: 1 | J7: 1 | K7: 1 | L7: 1 | M7: 1 | N7: 1 | O7: 0 | P7: =VLOOKUP(A7,[1]allpride!$C$2:$V$215,14,FALSE) -> 1 | Q7: =VLOOKUP(A7,[1]allpride!$C$2:$V$215,15,FALSE) -> 0 | R7: =VLOOKUP(A7,[1]allpride!$C$2:$V$215,16,FALSE) -> 0 | S7: =VLOOKUP(A7,[1]allpride!$C$2:$V$215,17,FALSE) -> 1 | T7: =VLOOKUP(A7,[1]allpride!$C$2:$V$215,18,FALSE) -> 2013 | U7: =VLOOKUP(A7,[1]allpride!$C$2:$V$215,19,FALSE) -> 4 | V7: =VLOOKUP(A7,[1]allpride!$C$2:$V$215,20,FALSE) -> 0 | W7: =VLOOKUP(B7,'[2]pride covariates'!$A$2:$B$33,2,FALSE) -> 1 | X7: 1 | Y7: 0 | Z7: =CONCATENATE("/* ",A7," */ ",G7,H7,I7,J7,K7,L7,M7,N7," 1"," ",P7," ",S7," ",R7," ",Y7," ",V7," ",X7,";") -> /* ELI-590 */ 11111111 1 1 1 0 0 0 1; | AA7: =CONCATENATE(G7,H7,I7,J7,K7,L7,M7,N7) -> 11111111 | AB7: =CONCATENATE("/*",A7,"*/ ",G7,H7,I7,J7,K7,L7,M7,N7," 1;") -> /*ELI-590*/ 11111111 1;
A8: ELI-592 | B8: Big Pride | C8: Big Pride 2013 Cub 8 | D8: 0 | E8: 0 | F8: 0 | G8: 1 | H8: 1 | I8: 1 | J8: 1 | K8: 1 | L8: 1 | M8: 1 | N8: 1 | O8: 0 | P8: =VLOOKUP(A8,[1]allpride!$C$2:$V$215,14,FALSE) -> 1 | Q8: =VLOOKUP(A8,[1]allpride!$C$2:$V$215,15,FALSE) -> 0 | R8: =VLOOKUP(A8,[1]allpride!$C$2:$V$215,16,FALSE) -> 0 | S8: =VLOOKUP(A8,[1]allpride!$C$2:$V$215,17,FALSE) -> 1 | T8: =VLOOKUP(A8,[1]allpride!$C$2:$V$215,18,FALSE) -> 2013 | U8: =VLOOKUP(A8,[1]allpride!$C$2:$V$215,19,FALSE) -> 4 | V8: =VLOOKUP(A8,[1]allpride!$C$2:$V$215,20,FALSE) -> 0 | W8: =VLOOKUP(B8,'[2]pride covariates'!$A$2:$B$33,2,FALSE) -> 1 | X8: 1 | Y8: 0 | Z8: =CONCATENATE("/* ",A8," */ ",G8,H8,I8,J8,K8,L8,M8,N8," 1"," ",P8," ",S8," ",R8," ",Y8," ",V8," ",X8,";") -> /* ELI-592 */ 11111111 1 1 1 0 0 0 1; | AA8: =CONCATENATE(G8,H8,I8,J8,K8,L8,M8,N8) -> 11111111 | AB8: =CONCATENATE("/*",A8,"*/ ",G8,H8,I8,J8,K8,L8,M8,N8," 1;") -> /*ELI-592*/ 11111111 1;
A9: ELI-593 | B9: Big Pride | C9: Big Pride 2013 Cub 9 | D9: 0 | E9: 0 | F9: 0 | G9: 1 | H9: 1 | I9: 1 | J9: 1 | K9: 1 | L9: 1 | M9: 1 | N9: 1 | O9: 0 | P9: =VLOOKUP(A9,[1]allpride!$C$2:$V$215,14,FALSE) -> 1 | Q9: =VLOOKUP(A9,[1]allpride!$C$2:$V$215,15,FALSE) -> 1 | R9: =VLOOKUP(A9,[1]allpride!$C$2:$V$215,16,FALSE) -> 0 | S9: =VLOOKUP(A9,[1]allpride!$C$2:$V$215,17,FALSE) -> 1 | T9: =VLOOKUP(A9,[1]allpride!$C$2:$V$215,18,FALSE) -> 2013 | U9: =VLOOKUP(A9,[1]allpride!$C$2:$V$215,19,FALSE) -> 7 | V9: =VLOOKUP(A9,[1]allpride!$C$2:$V$215,20,FALSE) -> 0 | W9: =VLOOKUP(B9,'[2]pride covariates'!$A$2:$B$33,2,FALSE) -> 1 | X9: 1 | Y9: 1 | Z9: =CONCATENATE("/* ",A9," */ ",G9,H9,I9,J9,K9,L9,M9,N9," 1"," ",P9," ",S9," ",R9," ",Y9," ",V9," ",X9,";") -> /* ELI-593 */ 11111111 1 1 1 0 1 0 1; | AA9: =CONCATENATE(G9,H9,I9,J9,K9,L9,M9,N9) -> 11111111 | AB9: =CONCATENATE("/*",A9,"*/ ",G9,H9,I9,J9,K9,L9,M9,N9," 1;") -> /*ELI-593*/ 11111111 1;
A10: ELI-594 | B10: Big Pride | C10: Big Pride 2013 Cub 10 | D10: 0 | E10: 0 | F10: 0 | G10: 1 | H10: 1 | I10: 1 | J10: 1 | K10: 1 | L10: 1 | M10: 1 | N10: 1 | O10: 0 | P10: =VLOOKUP(A10,[1]allpride!$C$2:$V$215,14,FALSE) -> 1 | Q10: =VLOOKUP(A10,[1]allpride!$C$2:$V$215,15,FALSE) -> 0 | R10: =VLOOKUP(A10,[1]allpride!$C$2:$V$215,16,FALSE) -> 0 | S10: =VLOOKUP(A10,[1]allpride!$C$2:$V$215,17,FALSE) -> 1 | T10: =VLOOKUP(A10,[1]allpride!$C$2:$V$215,18,FALSE) -> 2013 | U10: =VLOOKUP(A10,[1]allpride!$C$2:$V$215,19,FALSE) -> 7 | V10: =VLOOKUP(A10,[1]allpride!$C$2:$V$215,20,FALSE) -> 0 | W10: =VLOOKUP(B10,'[2]pride covariates'!$A$2:$B$33,2,FALSE) -> 1 | X10: 1 | Y10: 0 | Z10: =CONCATENATE("/* ",A10," */ ",G10,H10,I10,J10,K10,L10,M10,N10," 1"," ",P10," ",S10," ",R10," ",Y10," ",V10," ",X10,";") -> /* ELI-594 */ 11111111 1 1 1 0 0 0 1; | AA10: =CONCATENATE(G10,H10,I10,J10,K10,L10,M10,N10) -> 11111111 | AB10: =CONCATENATE("/*",A10,"*/ ",G10,H10,I10,J10,K10,L10,M10,N10," 1;") -> /*ELI-594*/ 11111111 1;
A11: ELI-595 | B11: Big Pride | C11: Big Pride 2013 Cub 11 | D11: 0 | E11: 0 | F11: 0 | G11: 1 | H11: 1 | I11: 1 | J11: 1 | K11: 1 | L11: 1 | M11: 1 | N11: 1 | O11: 1 | P11: =VLOOKUP(A11,[1]allpride!$C$2:$V$215,14,FALSE) -> 1 | Q11: =VLOOKUP(A11,[1]allpride!$C$2:$V$215,15,FALSE) -> 1 | R11: 1 | S11: =VLOOKUP(A11,[1]allpride!$C$2:$V$215,17,FALSE) -> 1 | T11: =VLOOKUP(A11,[1]allpride!$C$2:$V$215,18,FALSE) -> 2013 | U11: =VLOOKUP(A11,[1]allpride!$C$2:$V$215,19,FALSE) -> 7 | V11: =VLOOKUP(A11,[1]allpride!$C$2:$V$215,20,FALSE) -> 0 | W11: =VLOOKUP(B11,'[2]pride covariates'!$A$2:$B$33,2,FALSE) -> 1 | X11: 1 | Y11: 1 | Z11: =CONCATENATE("/* ",A11," */ ",G11,H11,I11,J11,K11,L11,M11,N11," 1"," ",P11," ",S11," ",R11," ",Y11," ",V11," ",X11,";") -> /* ELI-595 */ 11111111 1 1 1 1 1 0 1; | AA11: =CONCATENATE(G11,H11,I11,J11,K11,L11,M11,N11) -> 11111111 | AB11: =CONCATENATE("/*",A11,"*/ ",G11,H11,I11,J11,K11,L11,M11,N11," 1;") -> /*ELI-595*/ 11111111 1;
A12: ELI-243 | B12: Big Pride | C12: Big Pride F01 | D12: 1 | E12: 1 | F12: 1 | G12: 1 | H12: 1 | I12: 1 | J12: 1 | K12: 1 | L12: 1 | M12: 1 | N12: 1 | O12: 0 | P12: =VLOOKUP(A12,[1]allpride!$C$2:$V$215,14,FALSE) -> 1 | Q12: =VLOOKUP(A12,[1]allpride!$C$2:$V$215,15,FALSE) -> 0 | R12: =VLOOKUP(A12,[1]allpride!$C$2:$V$215,16,FALSE) -> 0 | S12: =VLOOKUP(A12,[1]allpride!$C$2:$V$215,17,FALSE) -> 1 | T12: =VLOOKUP(A12,[1]allpride!$C$2:$V$215,18,FALSE) -> 2008 | U12: =VLOOKUP(A12,[1]allpride!$C$2:$V$215,19,FALSE) -> 10 | V12: =VLOOKUP(A12,[1]allpride!$C$2:$V$215,20,FALSE) -> 3 | W12: =VLOOKUP(B12,'[2]pride covariates'!$A$2:$B$33,2,FALSE) -> 1 | X12: 1 | Y12: 0 | Z12: =CONCATENATE("/* ",A12," */ ",G12,H12,I12,J12,K12,L12,M12,N12," 1"," ",P12," ",S12," ",R12," ",Y12," ",V12," ",X12,";") -> /* ELI-243 */ 11111111 1 1 1 0 0 3 1; | AA12: =CONCATENATE(G12,H12,I12,J12,K12,L12,M12,N12) -> 11111111 | AB12: =CONCATENATE("/*",A12,"*/ ",G12,H12,I12,J12,K12,L12,M12,N12," 1;") -> /*ELI-243*/ 11111111 1;
A13: ELI-242 | B13: Big Pride | C13: Big Pride F02 | D13: 0 | E13: 1 | F13: 1 | G13: 1 | H13: 1 | I13: 1 | J13: 1 | K13: 1 | L13: 0 | M13: 1 | N13: 1 | O13: 0 | P13: =VLOOKUP(A13,[1]allpride!$C$2:$V$215,14,FALSE) -> 1 | Q13: =VLOOKUP(A13,[1]allpride!$C$2:$V$215,15,FALSE) -> 0 | R13: =VLOOKUP(A13,[1]allpride!$C$2:$V$215,16,FALSE) -> 0 | S13: =VLOOKUP(A13,[1]allpride!$C$2:$V$215,17,FALSE) -> 1 | T13: =VLOOKUP(A13,[1]allpride!$C$2:$V$215,18,FALSE) -> 2008 | U13: =VLOOKUP(A13,[1]allpride!$C$2:$V$215,19,FALSE) -> 10 | V13: =VLOOKUP(A13,[1]allpride!$C$2:$V$215,20,FALSE) -> 6 | W13: =VLOOKUP(B13,'[2]pride covariates'!$A$2:$B$33,2,FALSE) -> 1 | X13: 1 | Y13: 0 | Z13: =CONCATENATE("/* ",A13," */ ",G13,H13,I13,J13,K13,L13,M13,N13," 1"," ",P13," ",S13," ",R13," ",Y13," ",V13," ",X13,";") -> /* ELI-242 */ 11111011 1 1 1 0 0 6 1; | AA13: =CONCATENATE(G13,H13,I13,J13,K13,L13,M13,N13) -> 11111011 | AB13: =CONCATENATE("/*",A13,"*/ ",G13,H13,I13,J13,K13,L13,M13,N13," 1;") -> /*ELI-242*/ 11111011 1;
A14: ELI-224 | B14: Big Pride | C14: Big Pride F04 | D14: 0 | E14: 0 | F14: 0 | G14: 1 | H14: 1 | I14: 1 | J14: 1 | K14: 0 | L14: 1 | M14: 1 | N14: 1 | O14: 0 | P14: =VLOOKUP(A14,[1]allpride!$C$2:$V$215,14,FALSE) -> 1 | Q14: =VLOOKUP(A14,[1]allpride!$C$2:$V$215,15,FALSE) -> 0 | R14: =VLOOKUP(A14,[1]allpride!$C$2:$V$215,16,FALSE) -> 0 | S14: =VLOOKUP(A14,[1]allpride!$C$2:$V$215,17,FALSE) -> 1 | T14: =VLOOKUP(A14,[1]allpride!$C$2:$V$215,18,FALSE) -> 2009 | U14: =VLOOKUP(A14,[1]allpride!$C$2:$V$215,19,FALSE) -> 4 | V14: =VLOOKUP(A14,[1]allpride!$C$2:$V$215,20,FALSE) -> 4 | W14: =VLOOKUP(B14,'[2]pride covariates'!$A$2:$B$33,2,FALSE) -> 1 | X14: 1 | Y14: 0 | Z14: =CONCATENATE("/* ",A14," */ ",G14,H14,I14,J14,K14,L14,M14,N14," 1"," ",P14," ",S14," ",R14," ",Y14," ",V14," ",X14,";") -> /* ELI-224 */ 11110111 1 1 1 0 0 4 1; | AA14: =CONCATENATE(G14,H14,I14,J14,K14,L14,M14,N14) -> 11110111 | AB14: =CONCATENATE("/*",A14,"*/ ",G14,H14,I14,J14,K14,L14,M14,N14," 1;") -> /*ELI-224*/ 11110111 1;
A15: ELI-245 | B15: Big Pride | C15: Big Pride F05 | D15: 0 | E15: 0 | F15: 0 | G15: 1 | H15: 1 | I15: 1 | J15: 1 | K15: 0 | L15: 1 | M15: 1 | N15: 1 | O15: 0 | P15: =VLOOKUP(A15,[1]allpride!$C$2:$V$215,14,FALSE) -> 1 | Q15: =VLOOKUP(A15,[1]allpride!$C$2:$V$215,15,FALSE) -> 0 | R15: =VLOOKUP(A15,[1]allpride!$C$2:$V$215,16,FALSE) -> 0 | S15: =VLOOKUP(A15,[1]allpride!$C$2:$V$215,17,FALSE) -> 1 | T15: =VLOOKUP(A15,[1]allpride!$C$2:$V$215,18,FALSE) -> 2008 | U15: =VLOOKUP(A15,[1]allpride!$C$2:$V$215,19,FALSE) -> 10 | V15: =VLOOKUP(A15,[1]allpride!$C$2:$V$215,20,FALSE) -> 1 | W15: =VLOOKUP(B15,'[2]pride covariates'!$A$2:$B$33,2,FALSE) -> 1 | X15: 1 | Y15: 0 | Z15: =CONCATENATE("/* ",A15," */ ",G15,H15,I15,J15,K15,L15,M15,N15," 1"," ",P15," ",S15," ",R15," ",Y15," ",V15," ",X15,";") -> /* ELI-245 */ 11110111 1 1 1 0 0 1 1; | AA15: =CONCATENATE(G15,H15,I15,J15,K15,L15,M15,N15) -> 11110111 | AB15: =CONCATENATE("/*",A15,"*/ ",G15,H15,I15,J15,K15,L15,M15,N15," 1;") -> /*ELI-245*/ 11110111 1;
A16: ELI-223 | B16: Big Pride | C16: Big Pride F06 | D16: 0 | E16: 0 | F16: 0 | G16: 1 | H16: 1 | I16: 1 | J16: 1 | K16: 1 | L16: 1 | M16: 1 | N16: 1 | O16: 0 | P16: =VLOOKUP(A16,[1]allpride!$C$2:$V$215,14,FALSE) -> 1 | Q16: =VLOOKUP(A16,[1]allpride!$C$2:$V$215,15,FALSE) -> 0 | R16: =VLOOKUP(A16,[1]allpride!$C$2:$V$215,16,FALSE) -> 0 | S16: =VLOOKUP(A16,[1]allpride!$C$2:$V$215,17,FALSE) -> 1 | T16: =VLOOKUP(A16,[1]allpride!$C$2:$V$215,18,FALSE) -> 2008 | U16: =VLOOKUP(A16,[1]allpride!$C$2:$V$215,19,FALSE) -> 10 | V16: =VLOOKUP(A16,[1]allpride!$C$2:$V$215,20,FALSE) -> 1 | W16: =VLOOKUP(B16,'[2]pride covariates'!$A$2:$B$33,2,FALSE) -> 1 | X16: 1 | Y16: 0 | Z16: =CONCATENATE("/* ",A16," */ ",G16,H16,I16,J16,K16,L16,M16,N16," 1"," ",P16," ",S16," ",R16," ",Y16," ",V16," ",X16,";") -> /* ELI-223 */ 11111111 1 1 1 0 0 1 1; | AA16: =CONCATENATE(G16,H16,I16,J16,K16,L16,M16,N16) -> 11111111 | AB16: =CONCATENATE("/*",A16,"*/ ",G16,H16,I16,J16,K16,L16,M16,N16," 1;") -> /*ELI-223*/ 11111111 1;
A17: ELI-220 | B17: Big Pride | C17: Big Pride F07 | D17: 0 | E17: 0 | F17: 0 | G17: 1 | H17: 1 | I17: 1 | J17: 1 | K17: 1 | L17: 1 | M17: 1 | N17: 1 | O17: 0 | P17: =VLOOKUP(A17,[1]allpride!$C$2:$V$215,14,FALSE) -> 1 | Q17: =VLOOKUP(A17,[1]allpride!$C$2:$V$215,15,FALSE) -> 0 | R17: =VLOOKUP(A17,[1]allpride!$C$2:$V$215,16,FALSE) -> 0 | S17: =VLOOKUP(A17,[1]allpride!$C$2:$V$215,17,FALSE) -> 1 | T17: =VLOOKUP(A17,[1]allpride!$C$2:$V$215,18,FALSE) -> 2008 | U17: =VLOOKUP(A17,[1]allpride!$C$2:$V$215,19,FALSE) -> 10 | V17: =VLOOKUP(A17,[1]allpride!$C$2:$V$215,20,FALSE) -> 0 | W17: =VLOOKUP(B17,'[2]pride covariates'!$A$2:$B$33,2,FALSE) -> 1 | X17: 1 | Y17: 0 | Z17: =CONCATENATE("/* ",A17," */ ",G17,H17,I17,J17,K17,L17,M17,N17," 1"," ",P17," ",S17," ",R17," ",Y17," ",V17," ",X17,";") -> /* ELI-220 */ 11111111 1 1 1 0 0 0 1; | AA17: =CONCATENATE(G17,H17,I17,J17,K17,L17,M17,N17) -> 11111111 | AB17: =CONCATENATE("/*",A17,"*/ ",G17,H17,I17,J17,K17,L17,M17,N17," 1;") -> /*ELI-220*/ 11111111 1;
A18: ELI-218 | B18: Big Pride | C18: Big Pride F08 | D18: 0 | E18: 0 | F18: 0 | G18: 1 | H18: 1 | I18: 1 | J18: 1 | K18: 1 | L18: 1 | M18: 1 | N18: 1 | O18: 1 | P18: =VLOOKUP(A18,[1]allpride!$C$2:$V$215,14,FALSE) -> 1 | Q18: =VLOOKUP(A18,[1]allpride!$C$2:$V$215,15,FALSE) -> 0 | R18: =VLOOKUP(A18,[1]allpride!$C$2:$V$215,16,FALSE) -> 0 | S18: =VLOOKUP(A18,[1]allpride!$C$2:$V$215,17,FALSE) -> 1 | T18: =VLOOKUP(A18,[1]allpride!$C$2:$V$215,18,FALSE) -> 2009 | U18: =VLOOKUP(A18,[1]allpride!$C$2:$V$215,19,FALSE) -> 4 | V18: =VLOOKUP(A18,[1]allpride!$C$2:$V$215,20,FALSE) -> 1 | W18: =VLOOKUP(B18,'[2]pride covariates'!$A$2:$B$33,2,FALSE) -> 1 | X18: 1 | Y18: 0 | Z18: =CONCATENATE("/* ",A18," */ ",G18,H18,I18,J18,K18,L18,M18,N18," 1"," ",P18," ",S18," ",R18," ",Y18," ",V18," ",X18,";") -> /* ELI-218 */ 11111111 1 1 1 0 0 1 1; | AA18: =CONCATENATE(G18,H18,I18,J18,K18,L18,M18,N18) -> 11111111 | AB18: =CONCATENATE("/*",A18,"*/ ",G18,H18,I18,J18,K18,L18,M18,N18," 1;") -> /*ELI-218*/ 11111111 1;
A19: ELI-219 | B19: Big Pride | C19: Big Pride F10 | D19: 0 | E19: 0 | F19: 0 | G19: 1 | H19: 1 | I19: 1 | J19: 1 | K19: 1 | L19: 1 | M19: 1 | N19: 1 | O19: 0 | P19: =VLOOKUP(A19,[1]allpride!$C$2:$V$215,14,FALSE) -> 1 | Q19: =VLOOKUP(A19,[1]allpride!$C$2:$V$215,15,FALSE) -> 0 | R19: =VLOOKUP(A19,[1]allpride!$C$2:$V$215,16,FALSE) -> 0 | S19: =VLOOKUP(A19,[1]allpride!$C$2:$V$215,17,FALSE) -> 1 | T19: =VLOOKUP(A19,[1]allpride!$C$2:$V$215,18,FALSE) -> 2008 | U19: =VLOOKUP(A19,[1]allpride!$C$2:$V$215,19,FALSE) -> 10 | V19: =VLOOKUP(A19,[1]allpride!$C$2:$V$215,20,FALSE) -> 0 | W19: =VLOOKUP(B19,'[2]pride covariates'!$A$2:$B$33,2,FALSE) -> 1 | X19: 1 | Y19: 0 | Z19: =CONCATENATE("/* ",A19," */ ",G19,H19,I19,J19,K19,L19,M19,N19," 1"," ",P19," ",S19," ",R19," ",Y19," ",V19," ",X19,";") -> /* ELI-219 */ 11111111 1 1 1 0 0 0 1; | AA19: =CONCATENATE(G19,H19,I19,J19,K19,L19,M19,N19) -> 11111111 | AB19: =CONCATENATE("/*",A19,"*/ ",G19,H19,I19,J19,K19,L19,M19,N19," 1;") -> /*ELI-219*/ 11111111 1;
A20: ELI-765 | B20: Big Pride | C20: 2014 Cub 1 | D20: 0 | E20: 0 | F20: 0 | G20: 1 | H20: 0 | I20: 0 | J20: 1 | K20: 0 | L20: 1 | M20: 1 | N20: 1 | O20: 0 | P20: 1 | Q20: 1 | R20: 0 | S20: 1 | T20: 2014 | U20: 4 | V20: 0 | W20: =VLOOKUP(B20,'[2]pride covariates'!$A$2:$B$33,2,FALSE) -> 1 | X20: 1 | Y20: 1 | Z20: =CONCATENATE("/* ",A20," */ ",G20,H20,I20,J20,K20,L20,M20,N20," 1"," ",P20," ",S20," ",R20," ",Y20," ",V20," ",X20,";") -> /* ELI-765 */ 10010111 1 1 1 0 1 0 1; | AA20: =CONCATENATE(G20,H20,I20,J20,K20,L20,M20,N20) -> 10010111 | AB20: =CONCATENATE("/*",A20,"*/ ",G20,H20,I20,J20,K20,L20,M20,N20," 1;") -> /*ELI-765*/ 10010111 1;
A21: ELI-766 | B21: Big Pride | C21: 2014 Cub 2 | D21: 0 | E21: 0 | F21: 0 | G21: 1 | H21: 0 | I21: 0 | J21: 1 | K21: 0 | L21: 1 | M21: 1 | N21: 1 | O21: 0 | P21: 1 | Q21: 1 | R21: 0 | S21: 1 | T21: 2014 | U21: 4 | V21: 0 | W21: =VLOOKUP(B21,'[2]pride covariates'!$A$2:$B$33,2,FALSE) -> 1 | X21: 1 | Y21: 1 | Z21: =CONCATENATE("/* ",A21," */ ",G21,H21,I21,J21,K21,L21,M21,N21," 1"," ",P21," ",S21," ",R21," ",Y21," ",V21," ",X21,";") -> /* ELI-766 */ 10010111 1 1 1 0 1 0 1; | AA21: =CONCATENATE(G21,H21,I21,J21,K21,L21,M21,N21) -> 10010111 | AB21: =CONCATENATE("/*",A21,"*/ ",G21,H21,I21,J21,K21,L21,M21,N21," 1;") -> /*ELI-766*/ 10010111 1;
A22: ELI-767 | B22: Big Pride | C22: 2014 Cub 3 | D22: 0 | E22: 0 | F22: 0 | G22: 1 | H22: 0 | I22: 0 | J22: 1 | K22: 0 | L22: 1 | M22: 1 | N22: 1 | O22: 0 | P22: 1 | Q22: 1 | R22: 1 | S22: 1 | T22: 2014 | U22: 4 | V22: 0 | W22: =VLOOKUP(B22,'[2]pride covariates'!$A$2:$B$33,2,FALSE) -> 1 | X22: 1 | Y22: 1 | Z22: =CONCATENATE("/* ",A22," */ ",G22,H22,I22,J22,K22,L22,M22,N22," 1"," ",P22," ",S22," ",R22," ",Y22," ",V22," ",X22,";") -> /* ELI-767 */ 10010111 1 1 1 1 1 0 1; | AA22: =CONCATENATE(G22,H22,I22,J22,K22,L22,M22,N22) -> 10010111 | AB22: =CONCATENATE("/*",A22,"*/ ",G22,H22,I22,J22,K22,L22,M22,N22," 1;") -> /*ELI-767*/ 10010111 1;
A23: ELI-768 | B23: Big Pride | C23: 2014 Cub 4 | D23: 0 | E23: 0 | F23: 0 | G23: 1 | H23: 0 | I23: 0 | J23: 1 | K23: 0 | L23: 1 | M23: 1 | N23: 1 | O23: 0 | P23: 1 | Q23: 1 | R23: 0 | S23: 1 | T23: 2014 | U23: 4 | V23: 0 | W23: =VLOOKUP(B23,'[2]pride covariates'!$A$2:$B$33,2,FALSE) -> 1 | X23: 1 | Y23: 1 | Z23: =CONCATENATE("/* ",A23," */ ",G23,H23,I23,J23,K23,L23,M23,N23," 1"," ",P23," ",S23," ",R23," ",Y23," ",V23," ",X23,";") -> /* ELI-768 */ 10010111 1 1 1 0 1 0 1; | AA23: =CONCATENATE(G23,H23,I23,J23,K23,L23,M23,N23) -> 10010111 | AB23: =CONCATENATE("/*",A23,"*/ ",G23,H23,I23,J23,K23,L23,M23,N23," 1;") -> /*ELI-768*/ 10010111 1;
A24: ELI-769 | B24: Big Pride | C24: 2014 Cub 5 | D24: 0 | E24: 0 | F24: 0 | G24: 1 | H24: 0 | I24: 0 | J24: 1 | K24: 0 | L24: 1 | M24: 1 | N24: 1 | O24: 0 | P24: 1 | Q24: 1 | R24: 0 | S24: 1 | T24: 2014 | U24: 4 | V24: 0 | W24: =VLOOKUP(B24,'[2]pride covariates'!$A$2:$B$33,2,FALSE) -> 1 | X24: 1 | Y24: 1 | Z24: =CONCATENATE("/* ",A24," */ ",G24,H24,I24,J24,K24,L24,M24,N24," 1"," ",P24," ",S24," ",R24," ",Y24," ",V24," ",X24,";") -> /* ELI-769 */ 10010111 1 1 1 0 1 0 1; | AA24: =CONCATENATE(G24,H24,I24,J24,K24,L24,M24,N24) -> 10010111 | AB24: =CONCATENATE("/*",A24,"*/ ",G24,H24,I24,J24,K24,L24,M24,N24," 1;") -> /*ELI-769*/ 10010111 1;
A25: ELI-414 | B25: Chowo | C25: Chowo F01 | D25: 1 | E25: 0 | F25: 1 | G25: 0 | H25: 1 | I25: 1 | J25: 1 | K25: 1 | L25: 1 | M25: 1 | N25: 1 | O25: 0 | P25: =VLOOKUP(A25,[1]allpride!$C$2:$V$215,14,FALSE) -> 1 | Q25: =VLOOKUP(A25,[1]allpride!$C$2:$V$215,15,FALSE) -> 0 | R25: =VLOOKUP(A25,[1]allpride!$C$2:$V$215,16,FALSE) -> 0 | S25: =VLOOKUP(A25,[1]allpride!$C$2:$V$215,17,FALSE) -> 1 | T25: =VLOOKUP(A25,[1]allpride!$C$2:$V$215,18,FALSE) -> 2011 | U25: =VLOOKUP(A25,[1]allpride!$C$2:$V$215,19,FALSE) -> 7 | V25: =VLOOKUP(A25,[1]allpride!$C$2:$V$215,20,FALSE) -> 3 | W25: =VLOOKUP(B25,'[2]pride covariates'!$A$2:$B$33,2,FALSE) -> 1 | X25: 1 | Y25: 0 | Z25: =CONCATENATE("/* ",A25," */ ",G25,H25,I25,J25,K25,L25,M25,N25," 1"," ",P25," ",S25," ",R25," ",Y25," ",V25," ",X25,";") -> /* ELI-414 */ 01111111 1 1 1 0 0 3 1; | AA25: =CONCATENATE(G25,H25,I25,J25,K25,L25,M25,N25) -> 01111111 | AB25: =CONCATENATE("/*",A25,"*/ ",G25,H25,I25,J25,K25,L25,M25,N25," 1;") -> /*ELI-414*/ 01111111 1;
A26: ELI-493 | B26: Chowo | C26: Chowo F05 | D26: 0 | E26: 0 | F26: 1 | G26: 0 | H26: 0 | I26: 0 | J26: 1 | K26: 1 | L26: 1 | M26: 1 | N26: 1 | O26: 0 | P26: =VLOOKUP(A26,[1]allpride!$C$2:$V$215,14,FALSE) -> 1 | Q26: =VLOOKUP(A26,[1]allpride!$C$2:$V$215,15,FALSE) -> 0 | R26: =VLOOKUP(A26,[1]allpride!$C$2:$V$215,16,FALSE) -> 0 | S26: =VLOOKUP(A26,[1]allpride!$C$2:$V$215,17,FALSE) -> 1 | T26: =VLOOKUP(A26,[1]allpride!$C$2:$V$215,18,FALSE) -> 2012 | U26: =VLOOKUP(A26,[1]allpride!$C$2:$V$215,19,FALSE) -> 6 | V26: =VLOOKUP(A26,[1]allpride!$C$2:$V$215,20,FALSE) -> 4 | W26: =VLOOKUP(B26,'[2]pride covariates'!$A$2:$B$33,2,FALSE) -> 1 | X26: 1 | Y26: 0 | Z26: =CONCATENATE("/* ",A26," */ ",G26,H26,I26,J26,K26,L26,M26,N26," 1"," ",P26," ",S26," ",R26," ",Y26," ",V26," ",X26,";") -> /* ELI-493 */ 00011111 1 1 1 0 0 4 1; | AA26: =CONCATENATE(G26,H26,I26,J26,K26,L26,M26,N26) -> 00011111 | AB26: =CONCATENATE("/*",A26,"*/ ",G26,H26,I26,J26,K26,L26,M26,N26," 1;") -> /*ELI-493*/ 00011111 1;
A27: ELI-494 | B27: Chowo | C27: Chowo F06 | D27: 0 | E27: 0 | F27: 1 | G27: 0 | H27: 1 | I27: 0 | J27: 1 | K27: 1 | L27: 1 | M27: 1 | N27: 1 | O27: 0 | P27: =VLOOKUP(A27,[1]allpride!$C$2:$V$215,14,FALSE) -> 1 | Q27: =VLOOKUP(A27,[1]allpride!$C$2:$V$215,15,FALSE) -> 0 | R27: =VLOOKUP(A27,[1]allpride!$C$2:$V$215,16,FALSE) -> 0 | S27: =VLOOKUP(A27,[1]allpride!$C$2:$V$215,17,FALSE) -> 1 | T27: =VLOOKUP(A27,[1]allpride!$C$2:$V$215,18,FALSE) -> 2012 | U27: =VLOOKUP(A27,[1]allpride!$C$2:$V$215,19,FALSE) -> 6 | V27: =VLOOKUP(A27,[1]allpride!$C$2:$V$215,20,FALSE) -> 1 | W27: =VLOOKUP(B27,'[2]pride covariates'!$A$2:$B$33,2,FALSE) -> 1 | X27: 1 | Y27: 0 | Z27: =CONCATENATE("/* ",A27," */ ",G27,H27,I27,J27,K27,L27,M27,N27," 1"," ",P27," ",S27," ",R27," ",Y27," ",V27," ",X27,";") -> /* ELI-494 */ 01011111 1 1 1 0 0 1 1; | AA27: =CONCATENATE(G27,H27,I27,J27,K27,L27,M27,N27) -> 01011111 | AB27: =CONCATENATE("/*",A27,"*/ ",G27,H27,I27,J27,K27,L27,M27,N27," 1;") -> /*ELI-494*/ 01011111 1;
A28: ELI-524 | B28: Chowo | C28: Chowo U02 | D28: 0 | E28: 0 | F28: 1 | G28: 0 | H28: 1 | I28: 0 | J28: 1 | K28: 1 | L28: 1 | M28: 1 | N28: 1 | O28: 0 | P28: =VLOOKUP(A28,[1]allpride!$C$2:$V$215,14,FALSE) -> 1 | Q28: =VLOOKUP(A28,[1]allpride!$C$2:$V$215,15,FALSE) -> 0 | R28: =VLOOKUP(A28,[1]allpride!$C$2:$V$215,16,FALSE) -> 0 | S28: =VLOOKUP(A28,[1]allpride!$C$2:$V$215,17,FALSE) -> 1 | T28: =VLOOKUP(A28,[1]allpride!$C$2:$V$215,18,FALSE) -> 2012 | U28: =VLOOKUP(A28,[1]allpride!$C$2:$V$215,19,FALSE) -> 10 | V28: =VLOOKUP(A28,[1]allpride!$C$2:$V$215,20,FALSE) -> 0 | W28: =VLOOKUP(B28,'[2]pride covariates'!$A$2:$B$33,2,FALSE) -> 1 | X28: 1 | Y28: 0 | Z28: =CONCATENATE("/* ",A28," */ ",G28,H28,I28,J28,K28,L28,M28,N28," 1"," ",P28," ",S28," ",R28," ",Y28," ",V28," ",X28,";") -> /* ELI-524 */ 01011111 1 1 1 0 0 0 1; | AA28: =CONCATENATE(G28,H28,I28,J28,K28,L28,M28,N28) -> 01011111 | AB28: =CONCATENATE("/*",A28,"*/ ",G28,H28,I28,J28,K28,L28,M28,N28," 1;") -> /*ELI-524*/ 01011111 1;
A29: ELI-598 | B29: Chowo | C29: Chowo U04 | D29: 0 | E29: 0 | F29: 1 | G29: 0 | H29: 1 | I29: 0 | J29: 1 | K29: 1 | L29: 1 | M29: 1 | N29: 1 | O29: 0 | P29: =VLOOKUP(A29,[1]allpride!$C$2:$V$215,14,FALSE) -> 1 | Q29: =VLOOKUP(A29,[1]allpride!$C$2:$V$215,15,FALSE) -> 0 | R29: =VLOOKUP(A29,[1]allpride!$C$2:$V$215,16,FALSE) -> 0 | S29: =VLOOKUP(A29,[1]allpride!$C$2:$V$215,17,FALSE) -> 1 | T29: =VLOOKUP(A29,[1]allpride!$C$2:$V$215,18,FALSE) -> 2013 | U29: =VLOOKUP(A29,[1]allpride!$C$2:$V$215,19,FALSE) -> 4 | V29: =VLOOKUP(A29,[1]allpride!$C$2:$V$215,20,FALSE) -> 0 | W29: =VLOOKUP(B29,'[2]pride covariates'!$A$2:$B$33,2,FALSE) -> 1 | X29: 1 | Y29: 0 | Z29: =CONCATENATE("/* ",A29," */ ",G29,H29,I29,J29,K29,L29,M29,N29," 1"," ",P29," ",S29," ",R29," ",Y29," ",V29," ",X29,";") -> /* ELI-598 */ 01011111 1 1 1 0 0 0 1; | AA29: =CONCATENATE(G29,H29,I29,J29,K29,L29,M29,N29) -> 01011111 | AB29: =CONCATENATE("/*",A29,"*/ ",G29,H29,I29,J29,K29,L29,M29,N29," 1;") -> /*ELI-598*/ 01011111 1;
A30: ELI-599 | B30: Chowo | C30: Chowo U05 | D30: 0 | E30: 0 | F30: 1 | G30: 0 | H30: 1 | I30: 0 | J30: 1 | K30: 1 | L30: 1 | M30: 1 | N30: 1 | O30: 0 | P30: =VLOOKUP(A30,[1]allpride!$C$2:$V$215,14,FALSE) -> 1 | Q30: =VLOOKUP(A30,[1]allpride!$C$2:$V$215,15,FALSE) -> 0 | R30: =VLOOKUP(A30,[1]allpride!$C$2:$V$215,16,FALSE) -> 0 | S30: =VLOOKUP(A30,[1]allpride!$C$2:$V$215,17,FALSE) -> 1 | T30: =VLOOKUP(A30,[1]allpride!$C$2:$V$215,18,FALSE) -> 2013 | U30: =VLOOKUP(A30,[1]allpride!$C$2:$V$215,19,FALSE) -> 4 | V30: =VLOOKUP(A30,[1]allpride!$C$2:$V$215,20,FALSE) -> 0 | W30: =VLOOKUP(B30,'[2]pride covariates'!$A$2:$B$33,2,FALSE) -> 1 | X30: 1 | Y30: 0 | Z30: =CONCATENATE("/* ",A30," */ ",G30,H30,I30,J30,K30,L30,M30,N30," 1"," ",P30," ",S30," ",R30," ",Y30," ",V30," ",X30,";") -> /* ELI-599 */ 01011111 1 1 1 0 0 0 1; | AA30: =CONCATENATE(G30,H30,I30,J30,K30,L30,M30,N30) -> 01011111 | AB30: =CONCATENATE("/*",A30,"*/ ",G30,H30,I30,J30,K30,L30,M30,N30," 1;") -> /*ELI-599*/ 01011111 1;
A31: ELI-236 | B31: Chichele | C31: Chichele F02 | D31: 0 | E31: 0 | F31: 1 | G31: 1 | H31: 1 | I31: 1 | J31: 1 | K31: 1 | L31: 1 | M31: 1 | N31: 1 | O31: 0 | P31: =VLOOKUP(A31,[1]allpride!$C$2:$V$215,14,FALSE) -> 1 | Q31: =VLOOKUP(A31,[1]allpride!$C$2:$V$215,15,FALSE) -> 0 | R31: =VLOOKUP(A31,[1]allpride!$C$2:$V$215,16,FALSE) -> 0 | S31: =VLOOKUP(A31,[1]allpride!$C$2:$V$215,17,FALSE) -> 1 | T31: =VLOOKUP(A31,[1]allpride!$C$2:$V$215,18,FALSE) -> 2008 | U31: =VLOOKUP(A31,[1]allpride!$C$2:$V$215,19,FALSE) -> 9 | V31: =VLOOKUP(A31,[1]allpride!$C$2:$V$215,20,FALSE) -> 5 | W31: =VLOOKUP(B31,'[2]pride covariates'!$A$2:$B$33,2,FALSE) -> 1 | X31: 1 | Y31: 0 | Z31: =CONCATENATE("/* ",A31," */ ",G31,H31,I31,J31,K31,L31,M31,N31," 1"," ",P31," ",S31," ",R31," ",Y31," ",V31," ",X31,";") -> /* ELI-236 */ 11111111 1 1 1 0 0 5 1; | AA31: =CONCATENATE(G31,H31,I31,J31,K31,L31,M31,N31) -> 11111111 | AB31: =CONCATENATE("/*",A31,"*/ ",G31,H31,I31,J31,K31,L31,M31,N31," 1;") -> /*ELI-236*/ 11111111 1;
A32: ELI-235 | B32: Chichele | C32: Chichele F03 | D32: 1 | E32: 1 | F32: 1 | G32: 1 | H32: 1 | I32: 1 | J32: 1 | K32: 1 | L32: 1 | M32: 1 | N32: 1 | O32: 0 | P32: =VLOOKUP(A32,[1]allpride!$C$2:$V$215,14,FALSE) -> 1 | Q32: =VLOOKUP(A32,[1]allpride!$C$2:$V$215,15,FALSE) -> 0 | R32: 0 | S32: =VLOOKUP(A32,[1]allpride!$C$2:$V$215,17,FALSE) -> 1 | T32: =VLOOKUP(A32,[1]allpride!$C$2:$V$215,18,FALSE) -> 2008 | U32: =VLOOKUP(A32,[1]allpride!$C$2:$V$215,19,FALSE) -> 9 | V32: =VLOOKUP(A32,[1]allpride!$C$2:$V$215,20,FALSE) -> 2 | W32: =VLOOKUP(B32,'[2]pride covariates'!$A$2:$B$33,2,FALSE) -> 1 | X32: 1 | Y32: 0 | Z32: =CONCATENATE("/* ",A32," */ ",G32,H32,I32,J32,K32,L32,M32,N32," 1"," ",P32," ",S32," ",R32," ",Y32," ",V32," ",X32,";") -> /* ELI-235 */ 11111111 1 1 1 0 0 2 1; | AA32: =CONCATENATE(G32,H32,I32,J32,K32,L32,M32,N32) -> 11111111 | AB32: =CONCATENATE("/*",A32,"*/ ",G32,H32,I32,J32,K32,L32,M32,N32," 1;") -> /*ELI-235*/ 11111111 1;
A33: ELI-604 | B33: Chichele | C33: Chichele Cub1 | D33: 0 | E33: 0 | F33: 1 | G33: 1 | H33: 1 | I33: 1 | J33: 1 | K33: 1 | L33: 1 | M33: 1 | N33: 1 | O33: 0 | P33: 1 | Q33: 1 | R33: 0 | S33: 1 | T33: 2014 | U33: 4 | V33: 0 | W33: =VLOOKUP(B33,'[2]pride covariates'!$A$2:$B$33,2,FALSE) -> 1 | X33: 1 | Y33: 1 | Z33: =CONCATENATE("/* ",A33," */ ",G33,H33,I33,J33,K33,L33,M33,N33," 1"," ",P33," ",S33," ",R33," ",Y33," ",V33," ",X33,";") -> /* ELI-604 */ 11111111 1 1 1 0 1 0 1; | AA33: =CONCATENATE(G33,H33,I33,J33,K33,L33,M33,N33) -> 11111111 | AB33: =CONCATENATE("/*",A33,"*/ ",G33,H33,I33,J33,K33,L33,M33,N33," 1;") -> /*ELI-604*/ 11111111 1;
A34: ELI-606 | B34: Chichele | C34: Chichele Cub2 | D34: 0 | E34: 0 | F34: 1 | G34: 1 | H34: 1 | I34: 1 | J34: 1 | K34: 1 | L34: 1 | M34: 1 | N34: 1 | O34: 0 | P34: 1 | Q34: 0 | R34: 1 | S34: 1 | T34: 2014 | U34: 4 | V34: 0 | W34: =VLOOKUP(B34,'[2]pride covariates'!$A$2:$B$33,2,FALSE) -> 1 | X34: 1 | Y34: 0 | Z34: =CONCATENATE("/* ",A34," */ ",G34,H34,I34,J34,K34,L34,M34,N34," 1"," ",P34," ",S34," ",R34," ",Y34," ",V34," ",X34,";") -> /* ELI-606 */ 11111111 1 1 1 1 0 0 1; | AA34: =CONCATENATE(G34,H34,I34,J34,K34,L34,M34,N34) -> 11111111 | AB34: =CONCATENATE("/*",A34,"*/ ",G34,H34,I34,J34,K34,L34,M34,N34," 1;") -> /*ELI-606*/ 11111111 1;
A35: ELI-607 | B35: Chichele | C35: Chichele Cub3 | D35: 0 | E35: 0 | F35: 1 | G35: 1 | H35: 1 | I35: 1 | J35: 1 | K35: 1 | L35: 1 | M35: 1 | N35: 1 | O35: 0 | P35: 1 | Q35: 0 | R35: 0 | S35: 1 | T35: 2014 | U35: 4 | V35: 0 | W35: =VLOOKUP(B35,'[2]pride covariates'!$A$2:$B$33,2,FALSE) -> 1 | X35: 1 | Y35: 0 | Z35: =CONCATENATE("/* ",A35," */ ",G35,H35,I35,J35,K35,L35,M35,N35," 1"," ",P35," ",S35," ",R35," ",Y35," ",V35," ",X35,";") -> /* ELI-607 */ 11111111 1 1 1 0 0 0 1; | AA35: =CONCATENATE(G35,H35,I35,J35,K35,L35,M35,N35) -> 11111111 | AB35: =CONCATENATE("/*",A35,"*/ ",G35,H35,I35,J35,K35,L35,M35,N35," 1;") -> /*ELI-607*/ 11111111 1;
A36: ELI-143 | B36: Chinzombo | C36: Chinzombo F01 | D36: 0 | E36: 0 | F36: 0 | G36: 0 | H36: 1 | I36: 1 | J36: 1 | K36: 1 | L36: 1 | M36: 1 | N36: 1 | O36: 1 | P36: =VLOOKUP(A36,[1]allpride!$C$2:$V$215,14,FALSE) -> 1 | Q36: =VLOOKUP(A36,[1]allpride!$C$2:$V$215,15,FALSE) -> 0 | R36: =VLOOKUP(A36,[1]allpride!$C$2:$V$215,16,FALSE) -> 0 | S36: =VLOOKUP(A36,[1]allpride!$C$2:$V$215,17,FALSE) -> 1 | T36: =VLOOKUP(A36,[1]allpride!$C$2:$V$215,18,FALSE) -> 2012 | U36: =VLOOKUP(A36,[1]allpride!$C$2:$V$215,19,FALSE) -> 4 | V36: =VLOOKUP(A36,[1]allpride!$C$2:$V$215,20,FALSE) -> 4 | W36: 1 | X36: 0 | Y36: 0 | Z36: =CONCATENATE("/* ",A36," */ ",G36,H36,I36,J36,K36,L36,M36,N36," 1"," ",P36," ",S36," ",R36," ",Y36," ",V36," ",X36,";") -> /* ELI-143 */ 01111111 1 1 1 0 0 4 0; | AA36: =CONCATENATE(G36,H36,I36,J36,K36,L36,M36,N36) -> 01111111 | AB36: =CONCATENATE("/*",A36,"*/ ",G36,H36,I36,J36,K36,L36,M36,N36," 1;") -> /*ELI-143*/ 01111111 1;
A37: ELI-496 | B37: Chinzombo | C37: Chinzombo F02 | D37: 0 | E37: 0 | F37: 0 | G37: 0 | H37: 1 | I37: 0 | J37: 1 | K37: 1 | L37: 1 | M37: 1 | N37: 1 | O37: 1 | P37: 1 | Q37: 0 | R37: 0 | S37: 1 | T37: 2014 | U37: 5 | V37: 2 | W37: 1 | X37: 0 | Y37: 0 | Z37: =CONCATENATE("/* ",A37," */ ",G37,H37,I37,J37,K37,L37,M37,N37," 1"," ",P37," ",S37," ",R37," ",Y37," ",V37," ",X37,";") -> /* ELI-496 */ 01011111 1 1 1 0 0 2 0; | AA37: =CONCATENATE(G37,H37,I37,J37,K37,L37,M37,N37) -> 01011111 | AB37: =CONCATENATE("/*",A37,"*/ ",G37,H37,I37,J37,K37,L37,M37,N37," 1;") -> /*ELI-496*/ 01011111 1;
A38: ELI-703 | B38: Chinzombo | C38: Chinzombo F03 | D38: 0 | E38: 0 | F38: 0 | G38: 0 | H38: 1 | I38: 0 | J38: 1 | K38: 1 | L38: 1 | M38: 1 | N38: 1 | O38: 1 | P38: 1 | Q38: 0 | R38: 0 | S38: 1 | T38: 2014 | U38: 5 | V38: 0 | W38: 1 | X38: 0 | Y38: 0 | Z38: =CONCATENATE("/* ",A38," */ ",G38,H38,I38,J38,K38,L38,M38,N38," 1"," ",P38," ",S38," ",R38," ",Y38," ",V38," ",X38,";") -> /* ELI-703 */ 01011111 1 1 1 0 0 0 0; | AA38: =CONCATENATE(G38,H38,I38,J38,K38,L38,M38,N38) -> 01011111 | AB38: =CONCATENATE("/*",A38,"*/ ",G38,H38,I38,J38,K38,L38,M38,N38," 1;") -> /*ELI-703*/ 01011111 1;
A39: ELI-173 | B39: Nsefu | C39: Nsefu F01 | D39: 0 | E39: 0 | F39: 0 | G39: 0 | H39: 0 | I39: 0 | J39: 1 | K39: 0 | L39: 1 | M39: 1 | N39: 1 | O39: 1 | P39: =VLOOKUP(A39,[1]allpride!$C$2:$V$215,14,FALSE) -> 1 | Q39: =VLOOKUP(A39,[1]allpride!$C$2:$V$215,15,FALSE) -> 0 | R39: =VLOOKUP(A39,[1]allpride!$C$2:$V$215,16,FALSE) -> 0 | S39: =VLOOKUP(A39,[1]allpride!$C$2:$V$215,17,FALSE) -> 1 | T39: =VLOOKUP(A39,[1]allpride!$C$2:$V$215,18,FALSE) -> 2008 | U39: =VLOOKUP(A39,[1]allpride!$C$2:$V$215,19,FALSE) -> 8 | V39: =VLOOKUP(A39,[1]allpride!$C$2:$V$215,20,FALSE) -> 2 | W39: =VLOOKUP(B39,'[2]pride covariates'!$A$2:$B$33,2,FALSE) -> 1 | X39: 1 | Y39: 0 | Z39: =CONCATENATE("/* ",A39," */ ",G39,H39,I39,J39,K39,L39,M39,N39," 1"," ",P39," ",S39," ",R39," ",Y39," ",V39," ",X39,";") -> /* ELI-173 */ 00010111 1 1 1 0 0 2 1; | AA39: =CONCATENATE(G39,H39,I39,J39,K39,L39,M39,N39) -> 00010111 | AB39: =CONCATENATE("/*",A39,"*/ ",G39,H39,I39,J39,K39,L39,M39,N39," 1;") -> /*ELI-173*/ 00010111 1;
A40: ELI-174 | B40: Nsefu | C40: Nsefu F02 | D40: 0 | E40: 0 | F40: 0 | G40: 0 | H40: 1 | I40: 0 | J40: 1 | K40: 0 | L40: 1 | M40: 0 | N40: 1 | O40: 0 | P40: =VLOOKUP(A40,[1]allpride!$C$2:$V$215,14,FALSE) -> 1 | Q40: =VLOOKUP(A40,[1]allpride!$C$2:$V$215,15,FALSE) -> 0 | R40: =VLOOKUP(A40,[1]allpride!$C$2:$V$215,16,FALSE) -> 0 | S40: =VLOOKUP(A40,[1]allpride!$C$2:$V$215,17,FALSE) -> 1 | T40: =VLOOKUP(A40,[1]allpride!$C$2:$V$215,18,FALSE) -> 2008 | U40: =VLOOKUP(A40,[1]allpride!$C$2:$V$215,19,FALSE) -> 8 | V40: =VLOOKUP(A40,[1]allpride!$C$2:$V$215,20,FALSE) -> 6 | W40: =VLOOKUP(B40,'[2]pride covariates'!$A$2:$B$33,2,FALSE) -> 1 | X40: 1 | Y40: 0 | Z40: =CONCATENATE("/* ",A40," */ ",G40,H40,I40,J40,K40,L40,M40,N40," 1"," ",P40," ",S40," ",R40," ",Y40," ",V40," ",X40,";") -> /* ELI-174 */ 01010101 1 1 1 0 0 6 1; | AA40: =CONCATENATE(G40,H40,I40,J40,K40,L40,M40,N40) -> 01010101 | AB40: =CONCATENATE("/*",A40,"*/ ",G40,H40,I40,J40,K40,L40,M40,N40," 1;") -> /*ELI-174*/ 01010101 1;
...

Sheet input_format
A1: =CONCATENATE("/*",allprides!A2,"*/ ",allprides!G2,allprides!H2,allprides!I2,allprides!J2,allprides!K2,allprides!L2,allprides!M2,allprides!N2," 1;") -> /*ELI-583*/ 11100000 1;
A2: =CONCATENATE("/*",allprides!A3,"*/ ",allprides!G3,allprides!H3,allprides!I3,allprides!J3,allprides!K3,allprides!L3,allprides!M3,allprides!N3," 1;") -> /*ELI-584*/ 11111111 1;
A3: =CONCATENATE("/*",allprides!A4,"*/ ",allprides!G4,allprides!H4,allprides!I4,allprides!J4,allprides!K4,allprides!L4,allprides!M4,allprides!N4," 1;") -> /*ELI-585*/ 11111111 1;
A4: =CONCATENATE("/*",allprides!A5,"*/ ",allprides!G5,allprides!H5,allprides!I5,allprides!J5,allprides!K5,allprides!L5,allprides!M5,allprides!N5," 1;") -> /*ELI-586*/ 11111111 1;
A5: =CONCATENATE("/*",allprides!A6,"*/ ",allprides!G6,allprides!H6,allprides!I6,allprides!J6,allprides!K6,allprides!L6,allprides!M6,allprides!N6," 1;") -> /*ELI-587*/ 11111111 1;
A6: =CONCATENATE("/*",allprides!A7,"*/ ",allprides!G7,allprides!H7,allprides!I7,allprides!J7,allprides!K7,allprides!L7,allprides!M7,allprides!N7," 1;") -> /*ELI-590*/ 11111111 1;
A7: =CONCATENATE("/*",allprides!A8,"*/ ",allprides!G8,allprides!H8,allprides!I8,allprides!J8,allprides!K8,allprides!L8,allprides!M8,allprides!N8," 1;") -> /*ELI-592*/ 11111111 1;
A8: =CONCATENATE("/*",allprides!A9,"*/ ",allprides!G9,allprides!H9,allprides!I9,allprides!J9,allprides!K9,allprides!L9,allprides!M9,allprides!N9," 1;") -> /*ELI-593*/ 11111111 1;
A9: =CONCATENATE("/*",allprides!A10,"*/ ",allprides!G10,allprides!H10,allprides!I10,allprides!J10,allprides!K10,allprides!L10,allprides!M10,allprides!N10," 1;") -> /*ELI-594*/ 11111111 1;
A10: =CONCATENATE("/*",allprides!A11,"*/ ",allprides!G11,allprides!H11,allprides!I11,allprides!J11,allprides!K11,allprides!L11,allprides!M11,allprides!N11," 1;") -> /*ELI-595*/ 11111111 1;
A11: =CONCATENATE("/*",allprides!A12,"*/ ",allprides!G12,allprides!H12,allprides!I12,allprides!J12,allprides!K12,allprides!L12,allprides!M12,allprides!N12," 1;") -> /*ELI-243*/ 11111111 1;
A12: =CONCATENATE("/*",allprides!A13,"*/ ",allprides!G13,allprides!H13,allprides!I13,allprides!J13,allprides!K13,allprides!L13,allprides!M13,allprides!N13," 1;") -> /*ELI-242*/ 11111011 1;
... A171: =CONCATENATE("/*",allprides!A172,"*/ ",allprides!G172,allprides!H172,allprides!I172,allprides!J172,allprides!K172,allprides!L172,allprides!M172,allprides!N172," 1;") -> /*ELI-972*/ 00000100 1;

Sheet 2014_slnp_lion_ch
A1: /*ELI-583*/ 11100000 1;
A2: /*ELI-584*/ 11111111 1;
A3: /*ELI-585*/ 11111111 1;
A4: /*ELI-586*/ 11111111 1;
A5: /*ELI-587*/ 11111111 1;
A6: /*ELI-590*/ 11111111 1;
A7: /*ELI-592*/ 11111111 1;
A8: /*ELI-593*/ 11111111 1;
A9: /*ELI-594*/ 11111111 1;
A10: /*ELI-595*/ 11111111 1;
A11: /*ELI-243*/ 11111111 1;
A12: /*ELI-242*/ 11111011 1;
... A171: /*ELI-972*/ 00000100 1;

Sheet 2014_slnp_lion_3monRD
A1: =CONCATENATE("/*",allprides!A2,"*/ ",allprides!F2,allprides!G2,allprides!H2,allprides!L2,allprides!M2,allprides!N2," 1;") -> /*ELI-583*/ 011000 1;
A2: =CONCATENATE("/*",allprides!A3,"*/ ",allprides!F3,allprides!G3,allprides!H3,allprides!L3,allprides!M3,allprides!N3," 1;") -> /*ELI-584*/ 011111 1;
A3: =CONCATENATE("/*",allprides!A4,"*/ ",allprides!F4,allprides!G4,allprides!H4,allprides!L4,allprides!M4,allprides!N4," 1;") -> /*ELI-585*/ 011111 1;
A4: =CONCATENATE("/*",allprides!A5,"*/ ",allprides!F5,allprides!G5,allprides!H5,allprides!L5,allprides!M5,allprides!N5," 1;") -> /*ELI-586*/ 011111 1;
A5: =CONCATENATE("/*",allprides!A6,"*/ ",allprides!F6,allprides!G6,allprides!H6,allprides!L6,allprides!M6,allprides!N6," 1;") -> /*ELI-587*/ 011111 1;
A6: =CONCATENATE("/*",allprides!A7,"*/ ",allprides!F7,allprides!G7,allprides!H7,allprides!L7,allprides!M7,allprides!N7," 1;") -> /*ELI-590*/ 011111 1;
A7: =CONCATENATE("/*",allprides!A8,"*/ ",allprides!F8,allprides!G8,allprides!H8,allprides!L8,allprides!M8,allprides!N8," 1;") -> /*ELI-592*/ 011111 1;
A8: =CONCATENATE("/*",allprides!A9,"*/ ",allprides!F9,allprides!G9,allprides!H9,allprides!L9,allprides!M9,allprides!N9," 1;") -> /*ELI-593*/ 011111 1;
A9: =CONCATENATE("/*",allprides!A10,"*/ ",allprides!F10,allprides!G10,allprides!H10,allprides!L10,allprides!M10,allprides!N10," 1;") -> /*ELI-594*/ 011111 1;
A10: =CONCATENATE("/*",allprides!A11,"*/ ",allprides!F11,allprides!G11,allprides!H11,allprides!L11,allprides!M11,allprides!N11," 1;") -> /*ELI-595*/ 011111 1;
A11: =CONCATENATE("/*",allprides!A12,"*/ ",allprides!F12,allprides!G12,allprides!H12,allprides!L12,allprides!M12,allprides!N12," 1;") -> /*ELI-243*/ 111111 1;
A12: =CONCATENATE("/*",allprides!A13,"*/ ",allprides!F13,allprides!G13,allprides!H13,allprides!L13,allprides!M13,allprides!N13," 1;") -> /*ELI-242*/ 111011 1;
... A171: =CONCATENATE("/*",allprides!A172,"*/ ",allprides!F172,allprides!G172,allprides!H172,allprides!L172,allprides!M172,allprides!N172," 1;") -> /*ELI-972*/ 000100 1;
