Workbook

Sheet BCC
A1: pride | B1: altname | C1: lionid | D1: jan | E1: feb | F1: mar | G1: apr | H1: may | I1: jun | J1: jul | K1: aug | L1: sep | M1: oct | N1: nov | O1: dec | P1: sexknown | Q1: sexmale | R1: knowndead | S1: dobknown | T1: yearatfirst | U1: monthatfirst | V1: ageatfirst
B2: Big Pride 2013 Cub 2 | C2: ELI-584 | D2: 0 | E2: 0 | G2: 1 | H2: 1 | I2: 1 | J2: 1 | K2: 1 | L2: 1 | M2: 1 | N2: 1 | O2: 0
B3: Big Pride 2013 Cub 3 | C3: ELI-585 | D3: 0 | E3: 0 | F3: 1 | G3: 1 | H3: 1 | I3: 1 | J3: 1 | K3: 1 | L3: 1 | M3: 0 | N3: 1 | O3: 0
B4: Big Pride 2013 Cub 4 | C4: ELI-586 | D4: 0 | E4: 0 | F4: 1 | G4: 1 | H4: 1 | I4: 1 | J4: 1 | K4: 1 | L4: 1 | M4: 1 | N4: 1 | O4: 0
B5: Big Pride 2013 Cub 5 | C5: ELI-587 | D5: 0 | E5: 0 | F5: 1 | G5: 1 | H5: 1 | I5: 1 | J5: 1 | K5: 1 | L5: 1 | M5: 1 | N5: 1 | O5: 0
B6: Big Pride 2013 Cub 6 | C6: ELI-590 | D6: 0 | E6: 0 | F6: 1 | G6: 1 | H6: 1 | I6: 1 | J6: 1 | K6: 1 | L6: 1 | M6: 1 | N6: 1 | O6: 0
B7: Big Pride 2013 Cub 8 | C7: ELI-592 | D7: 0 | E7: 0 | F7: 1 | G7: 1 | H7: 1 | I7: 1 | J7: 1 | K7: 1 | L7: 1 | M7: 0 | N7: 1 | O7: 0
B8: Big Pride 2013 Cub 9 | C8: ELI-593 | D8: 0 | E8: 0 | F8: 1 | G8: 1 | H8: 1 | I8: 1 | J8: 1 | K8: 1 | L8: 1 | M8: 0 | N8: 1 | O8: 0
B9: Big Pride 2013 Cub 10 | C9: ELI-594 | D9: 0 | E9: 0 | F9: 1 | G9: 1 | H9: 1 | I9: 1 | J9: 1 | K9: 1 | L9: 1 | M9: 1 | N9: 1 | O9: 0
B10: Big Pride F01 | C10: ELI-243 | D10: 0 | E10: 0 | F10: 1 | G10: 1 | H10: 1 | I10: 1 | J10: 1 | K10: 1 | L10: 1 | M10: 0 | N10: 1 | O10: 0
B11: Big Pride F02 | C11: ELI-242 | D11: 0 | E11: 0 | F11: 0 | G11: 0 | H11: 0 | I11: 0 | J11: 0 | K11: 0 | L11: 0 | M11: 0 | N11: 0 | O11: 0
B12: Big Pride F03 | C12: ELI-225 | D12: 0 | E12: 0 | F12: 0 | G12: 0 | H12: 0 | I12: 0 | J12: 0 | K12: 0 | L12: 0 | M12: 0 | N12: 0 | O12: 0
B13: Big Pride F04 | C13: ELI-224 | D13: 0 | E13: 0 | F13: 0 | G13: 0 | H13: 0 | I13: 0 | J13: 1 | K13: 0 | L13: 0 | M13: 1 | N13: 0 | O13: 0
B14: Big Pride F05 | C14: ELI-245 | D14: 0 | E14: 0 | F14: 0 | G14: 1 | H14: 0 | I14: 0 | J14: 1 | K14: 1 | L14: 0 | M14: 1 | N14: 0 | O14: 0
... B21: Big Pride M03 | C21: ELI-222 | D21: 0 | E21: 0 | F21: 0 | G21: 0 | H21: 0 | I21: 0 | J21: 0 | K21: 0 | L21: 0 | M21: 0 | N21: 0 | O21: 0
C22: ELI-769 | D22: 0 | E22: 0 | F22: 0 | G22: 1 | H22: 0 | I22: 0 | J22: 0 | K22: 1 | L22: 0 | M22: 1 | N22: 0 | O22: 0
C23: ELI-768 | D23: 0 | E23: 0 | F23: 0 | G23: 0 | H23: 0 | I23: 0 | J23: 0 | K23: 1 | L23: 0 | M23: 1 | N23: 0 | O23: 0
C24: ELI-767 | D24: 0 | E24: 0 | F24: 0 | G24: 0 | H24: 0 | I24: 0 | J24: 0 | K24: 0 | L24: 0 | M24: 0 | N24: 0 | O24: 0
C25: ELI-766 | D25: 0 | E25: 0 | F25: 0 | G25: 1 | H25: 0 | I25: 0 | J25: 0 | K25: 1 | L25: 0 | M25: 1 | N25: 0 | O25: 0
C26: ELI-765 | D26: 0 | E26: 0 | F26: 0 | G26: 1 | H26: 0 | I26: 0 | J26: 0 | K26: 0 | L26: 0 | M26: 1 | N26: 0 | O26: 0
B27: Cub 1 | D27: 0 | E27: 0 | F27: 0 | G27: 0 | H27: 0 | I27: 0 | J27: 0 | K27: 1 | L27: 0 | M27: 1 | N27: 0 | O27: 0
B28: Cub 2 | D28: 0 | E28: 0 | F28: 0 | G28: 0 | H28: 0 | I28: 0 | J28: 0 | K28: 1 | L28: 0 | M28: 1 | N28: 0 | O28: 0
B29: Cub 3 | D29: 0 | E29: 0 | F29: 0 | G29: 0 | H29: 0 | I29: 0 | J29: 0 | K29: 1 | L29: 0 | M29: 1 | N29: 0 | O29: 0
B30: Cub 4 | D30: 0 | E30: 0 | F30: 0 | G30: 0 | H30: 0 | I30: 0 | J30: 0 | K30: 1 | L30: 0 | M30: 1 | N30: 0 | O30: 0
B31: Cub 5 | D31: 0 | E31: 0 | F31: 0 | G31: 0 | H31: 0 | I31: 0 | J31: 0 | K31: 1 | L31: 0 | M31: 1 | N31: 0 | O31: 0
B32: Cub 6 | D32: 0 | E32: 0 | F32: 0 | G32: 0 | H32: 0 | I32: 0 | J32: 0 | K32: 1 | L32: 0 | M32: 1 | N32: 0 | O32: 0
D34: Jan | E34: Feb | F34: Mar | G34: Apr | H34: May | I34: Jun | J34: Jul | K34: Aug | L34: Sept | M34: Oct | N34: Nov | O34: Dec
B35: Group | C35: ID
B36: Chowo F01 | C36: ELI-414 | D36: 0 | E36: 0 | F36: 0 | G36: 0 | H36: 0 | I36: 0 | J36: 0 | K36: 0 | L36: 1 | M36: 1 | N36: 1 | O36: 0
B37: Chowo F02 | C37: ELI-415 | D37: 0 | E37: 0 | F37: 0 | G37: 0 | H37: 0 | I37: 0 | J37: 0 | K37: 0 | L37: 0 | M37: 0 | N37: 0 | O37: 0
B38: Chowo F03 | C38: ELI-436 | D38: 0 | E38: 0 | F38: 0 | G38: 0 | H38: 0 | I38: 0 | J38: 0 | K38: 0 | L38: 0 | M38: 0 | N38: 0 | O38: 0
B39: Chowo F04 | C39: ELI-413 | D39: 0 | E39: 0 | F39: 0 | G39: 0 | H39: 0 | I39: 0 | J39: 0 | K39: 0 | L39: 0 | M39: 0 | N39: 0 | O39: 0
B40: Chowo F05 | C40: ELI-493 | D40: 0 | E40: 0 | F40: 0 | G40: 0 | H40: 0 | I40: 0 | J40: 0 | K40: 0 | L40: 0 | M40: 0 | N40: 0 | O40: 0
B41: Chowo F06 | C41: ELI-494 | D41: 0 | E41: 0 | F41: 0 | G41: 0 | H41: 0 | I41: 0 | J41: 0 | K41: 0 | L41: 0 | M41: 0 | N41: 0 | O41: 0
B42: Chowo U01 | C42: ELI-523 | D42: 0 | E42: 0 | F42: 0 | G42: 0 | H42: 0 | I42: 0 | J42: 0 | K42: 0 | L42: 0 | M42: 0 | N42: 0 | O42: 0
B43: Chowo U02 | C43: ELI-524 | D43: 0 | E43: 0 | F43: 0 | G43: 0 | H43: 0 | I43: 0 | J43: 0 | K43: 0 | L43: 0 | M43: 0 | N43: 0 | O43: 0
B44: Chowo U03 | C44: ELI-525 | D44: 0 | E44: 0 | F44: 0 | G44: 0 | H44: 0 | I44: 0 | J44: 0 | K44: 0 | L44: 0 | M44: 0 | N44: 0 | O44: 0
D47: Jan | E47: Feb | F47: Mar | G47: Apr | H47: May | I47: Jun | J47: Jul | K47: Aug | L47: Sept | M47: Oct | N47: Nov | O47: Dec
B48: Group | C48: ID
B49: Chichele F02 | C49: ELI-236 | D49: 0 | E49: 0 | F49: 0 | G49: 1 | H49: 0 | I49: 0 | J49: 0 | K49: 0 | L49: 0 | M49: 0 | N49: 0 | O49: 0
...

Sheet Allprides 
A1: pride | B1: altname | C1: lionid | D1: jan | E1: feb | F1: mar | G1: apr | H1: may | I1: jun | J1: jul | K1: aug | L1: sep | M1: oct | N1: nov | O1: dec | P1: sexknown | Q1: sexmale | R1: knowndead | S1: dobknown | T1: yearatfirst | U1: monthatfirst | V1: ageatfirst | W1: collaredgroup
A2: Big Pride | B2: Big Pride 2013 Cub 2 | C2: ELI-584 | D2: 0 | E2: 0 | F2: 0 | G2: 1 | H2: 1 | I2: 1 | J2: 1 | K2: 1 | L2: 1 | M2: 1 | N2: 1 | O2: 0 | P2: =VLOOKUP(C2,[1]allprides!$C$2:$X$170,14,FALSE) -> 1 | Q2: =VLOOKUP(C2,[1]allprides!$C$2:$X$170,15,FALSE) -> 0 | R2: =VLOOKUP(C2,[1]allprides!$C$2:$X$170,16,FALSE) -> 0 | S2: =VLOOKUP(C2,[1]allprides!$C$2:$X$170,17,FALSE) -> 1 | T2: =VLOOKUP(C2,[1]allprides!$C$2:$X$170,18,FALSE) -> 2013 | U2: =VLOOKUP(C2,[1]allprides!$C$2:$X$170,19,FALSE) -> 7 | V2: =VLOOKUP(C2,[1]allprides!$C$2:$X$170,20,FALSE) -> 0 | W2: 1
A3: Big Pride | B3: Big Pride 2013 Cub 3 | C3: ELI-585 | D3: 0 | E3: 0 | F3: 1 | G3: 1 | H3: 1 | I3: 1 | J3: 1 | K3: 1 | L3: 1 | M3: 0 | N3: 1 | O3: 0 | P3: =VLOOKUP(C3,[1]allprides!$C$2:$X$170,14,FALSE) -> 1 | Q3: =VLOOKUP(C3,[1]allprides!$C$2:$X$170,15,FALSE) -> 0 | R3: =VLOOKUP(C3,[1]allprides!$C$2:$X$170,16,FALSE) -> 0 | S3: =VLOOKUP(C3,[1]allprides!$C$2:$X$170,17,FALSE) -> 1 | T3: =VLOOKUP(C3,[1]allprides!$C$2:$X$170,18,FALSE) -> 2013 | U3: =VLOOKUP(C3,[1]allprides!$C$2:$X$170,19,FALSE) -> 7 | V3: =VLOOKUP(C3,[1]allprides!$C$2:$X$170,20,FALSE) -> 0 | W3: 1 | X3: =CONCATENATE("/*",C3,"*/ ",G3,H3,I3,J3,K3,L3,M3,N3," 1;") -> /*ELI-585*/ 11111101 1;
A4: Big Pride | B4: Big Pride 2013 Cub 4 | C4: ELI-586 | D4: 0 | E4: 0 | F4: 1 | G4: 1 | H4: 1 | I4: 1 | J4: 1 | K4: 1 | L4: 1 | M4: 1 | N4: 1 | O4: 0 | P4: =VLOOKUP(C4,[1]allprides!$C$2:$X$170,14,FALSE) -> 1 | Q4: =VLOOKUP(C4,[1]allprides!$C$2:$X$170,15,FALSE) -> 1 | R4: =VLOOKUP(C4,[1]allprides!$C$2:$X$170,16,FALSE) -> 0 | S4: =VLOOKUP(C4,[1]allprides!$C$2:$X$170,17,FALSE) -> 1 | T4: =VLOOKUP(C4,[1]allprides!$C$2:$X$170,18,FALSE) -> 2013 | U4: =VLOOKUP(C4,[1]allprides!$C$2:$X$170,19,FALSE) -> 7 | V4: =VLOOKUP(C4,[1]allprides!$C$2:$X$170,20,FALSE) -> 0 | W4: 1 | X4: =CONCATENATE("/*",C4,"*/ ",G4,H4,I4,J4,K4,L4,M4,N4," 1;") -> /*ELI-586*/ 11111111 1;
A5: Big Pride | B5: Big Pride 2013 Cub 5 | C5: ELI-587 | D5: 0 | E5: 0 | F5: 1 | G5: 1 | H5: 1 | I5: 1 | J5: 1 | K5: 1 | L5: 1 | M5: 1 | N5: 1 | O5: 0 | P5: =VLOOKUP(C5,[1]allprides!$C$2:$X$170,14,FALSE) -> 1 | Q5: =VLOOKUP(C5,[1]allprides!$C$2:$X$170,15,FALSE) -> 0 | R5: =VLOOKUP(C5,[1]allprides!$C$2:$X$170,16,FALSE) -> 0 | S5: =VLOOKUP(C5,[1]allprides!$C$2:$X$170,17,FALSE) -> 1 | T5: =VLOOKUP(C5,[1]allprides!$C$2:$X$170,18,FALSE) -> 2013 | U5: =VLOOKUP(C5,[1]allprides!$C$2:$X$170,19,FALSE) -> 7 | V5: =VLOOKUP(C5,[1]allprides!$C$2:$X$170,20,FALSE) -> 0 | W5: 1 | X5: =CONCATENATE("/*",C5,"*/ ",G5,H5,I5,J5,K5,L5,M5,N5," 1;") -> /*ELI-587*/ 11111111 1;
A6: Big Pride | B6: Big Pride 2013 Cub 6 | C6: ELI-590 | D6: 0 | E6: 0 | F6: 1 | G6: 1 | H6: 1 | I6: 1 | J6: 1 | K6: 1 | L6: 1 | M6: 1 | N6: 1 | O6: 0 | P6: =VLOOKUP(C6,[1]allprides!$C$2:$X$170,14,FALSE) -> 1 | Q6: =VLOOKUP(C6,[1]allprides!$C$2:$X$170,15,FALSE) -> 0 | R6: =VLOOKUP(C6,[1]allprides!$C$2:$X$170,16,FALSE) -> 0 | S6: =VLOOKUP(C6,[1]allprides!$C$2:$X$170,17,FALSE) -> 1 | T6: =VLOOKUP(C6,[1]allprides!$C$2:$X$170,18,FALSE) -> 2013 | U6: =VLOOKUP(C6,[1]allprides!$C$2:$X$170,19,FALSE) -> 4 | V6: =VLOOKUP(C6,[1]allprides!$C$2:$X$170,20,FALSE) -> 0 | W6: 1 | X6: =CONCATENATE("/*",C6,"*/ ",G6,H6,I6,J6,K6,L6,M6,N6," 1;") -> /*ELI-590*/ 11111111 1;
A7: Big Pride | B7: Big Pride 2013 Cub 8 | C7: ELI-592 | D7: 0 | E7: 0 | F7: 1 | G7: 1 | H7: 1 | I7: 1 | J7: 1 | K7: 1 | L7: 1 | M7: 0 | N7: 1 | O7: 0 | P7: =VLOOKUP(C7,[1]allprides!$C$2:$X$170,14,FALSE) -> 1 | Q7: =VLOOKUP(C7,[1]allprides!$C$2:$X$170,15,FALSE) -> 0 | R7: =VLOOKUP(C7,[1]allprides!$C$2:$X$170,16,FALSE) -> 0 | S7: =VLOOKUP(C7,[1]allprides!$C$2:$X$170,17,FALSE) -> 1 | T7: =VLOOKUP(C7,[1]allprides!$C$2:$X$170,18,FALSE) -> 2013 | U7: =VLOOKUP(C7,[1]allprides!$C$2:$X$170,19,FALSE) -> 4 | V7: =VLOOKUP(C7,[1]allprides!$C$2:$X$170,20,FALSE) -> 0 | W7: 1 | X7: =CONCATENATE("/*",C7,"*/ ",G7,H7,I7,J7,K7,L7,M7,N7," 1;") -> /*ELI-592*/ 11111101 1;
A8: Big Pride | B8: Big Pride 2013 Cub 9 | C8: ELI-593 | D8: 0 | E8: 0 | F8: 1 | G8: 1 | H8: 1 | I8: 1 | J8: 1 | K8: 1 | L8: 1 | M8: 0 | N8: 1 | O8: 0 | P8: =VLOOKUP(C8,[1]allprides!$C$2:$X$170,14,FALSE) -> 1 | Q8: =VLOOKUP(C8,[1]allprides!$C$2:$X$170,15,FALSE) -> 1 | R8: =VLOOKUP(C8,[1]allprides!$C$2:$X$170,16,FALSE) -> 0 | S8: =VLOOKUP(C8,[1]allprides!$C$2:$X$170,17,FALSE) -> 1 | T8: =VLOOKUP(C8,[1]allprides!$C$2:$X$170,18,FALSE) -> 2013 | U8: =VLOOKUP(C8,[1]allprides!$C$2:$X$170,19,FALSE) -> 7 | V8: =VLOOKUP(C8,[1]allprides!$C$2:$X$170,20,FALSE) -> 0 | W8: 1 | X8: =CONCATENATE("/*",C8,"*/ ",G8,H8,I8,J8,K8,L8,M8,N8," 1;") -> /*ELI-593*/ 11111101 1;
A9: Big Pride | B9: Big Pride 2013 Cub 10 | C9: ELI-594 | D9: 0 | E9: 0 | F9: 1 | G9: 1 | H9: 1 | I9: 1 | J9: 1 | K9: 1 | L9: 1 | M9: 1 | N9: 1 | O9: 0 | P9: =VLOOKUP(C9,[1]allprides!$C$2:$X$170,14,FALSE) -> 1 | Q9: =VLOOKUP(C9,[1]allprides!$C$2:$X$170,15,FALSE) -> 0 | R9: =VLOOKUP(C9,[1]allprides!$C$2:$X$170,16,FALSE) -> 0 | S9: =VLOOKUP(C9,[1]allprides!$C$2:$X$170,17,FALSE) -> 1 | T9: =VLOOKUP(C9,[1]allprides!$C$2:$X$170,18,FALSE) -> 2013 | U9: =VLOOKUP(C9,[1]allprides!$C$2:$X$170,19,FALSE) -> 7 | V9: =VLOOKUP(C9,[1]allprides!$C$2:$X$170,20,FALSE) -> 0 | W9: 1 | X9: =CONCATENATE("/*",C9,"*/ ",G9,H9,I9,J9,K9,L9,M9,N9," 1;") -> /*ELI-594*/ 11111111 1;
A10: Big Pride | B10: Big Pride F01 | C10: ELI-243 | D10: 0 | E10: 0 | F10: 1 | G10: 1 | H10: 1 | I10: 1 | J10: 1 | K10: 1 | L10: 1 | M10: 0 | N10: 1 | O10: 0 | P10: =VLOOKUP(C10,[1]allprides!$C$2:$X$170,14,FALSE) -> 1 | Q10: =VLOOKUP(C10,[1]allprides!$C$2:$X$170,15,FALSE) -> 0 | R10: =VLOOKUP(C10,[1]allprides!$C$2:$X$170,16,FALSE) -> 0 | S10: =VLOOKUP(C10,[1]allprides!$C$2:$X$170,17,FALSE) -> 1 | T10: =VLOOKUP(C10,[1]allprides!$C$2:$X$170,18,FALSE) -> 2008 | U10: =VLOOKUP(C10,[1]allprides!$C$2:$X$170,19,FALSE) -> 10 | V10: =VLOOKUP(C10,[1]allprides!$C$2:$X$170,20,FALSE) -> 3 | W10: 1 | X10: =CONCATENATE("/*",C10,"*/ ",G10,H10,I10,J10,K10,L10,M10,N10," 1;") -> /*ELI-243*/ 11111101 1;
A11: Big Pride | B11: Big Pride F04 | C11: ELI-224 | D11: 0 | E11: 0 | F11: 0 | G11: 0 | H11: 0 | I11: 1 | J11: 1 | K11: 0 | L11: 1 | M11: 1 | N11: 0 | O11: 0 | P11: =VLOOKUP(C11,[1]allprides!$C$2:$X$170,14,FALSE) -> 1 | Q11: =VLOOKUP(C11,[1]allprides!$C$2:$X$170,15,FALSE) -> 0 | R11: =VLOOKUP(C11,[1]allprides!$C$2:$X$170,16,FALSE) -> 0 | S11: =VLOOKUP(C11,[1]allprides!$C$2:$X$170,17,FALSE) -> 1 | T11: =VLOOKUP(C11,[1]allprides!$C$2:$X$170,18,FALSE) -> 2009 | U11: =VLOOKUP(C11,[1]allprides!$C$2:$X$170,19,FALSE) -> 4 | V11: =VLOOKUP(C11,[1]allprides!$C$2:$X$170,20,FALSE) -> 4 | W11: 1 | X11: =CONCATENATE("/*",C11,"*/ ",G11,H11,I11,J11,K11,L11,M11,N11," 1;") -> /*ELI-224*/ 00110110 1;
A12: Big Pride | B12: Big Pride F05 | C12: ELI-245 | D12: 0 | E12: 0 | F12: 0 | G12: 1 | H12: 0 | I12: 1 | J12: 1 | K12: 1 | L12: 1 | M12: 1 | N12: 0 | O12: 0 | P12: =VLOOKUP(C12,[1]allprides!$C$2:$X$170,14,FALSE) -> 1 | Q12: =VLOOKUP(C12,[1]allprides!$C$2:$X$170,15,FALSE) -> 0 | R12: =VLOOKUP(C12,[1]allprides!$C$2:$X$170,16,FALSE) -> 0 | S12: =VLOOKUP(C12,[1]allprides!$C$2:$X$170,17,FALSE) -> 1 | T12: =VLOOKUP(C12,[1]allprides!$C$2:$X$170,18,FALSE) -> 2008 | U12: =VLOOKUP(C12,[1]allprides!$C$2:$X$170,19,FALSE) -> 10 | V12: =VLOOKUP(C12,[1]allprides!$C$2:$X$170,20,FALSE) -> 1 | W12: 1 | X12: =CONCATENATE("/*",C12,"*/ ",G12,H12,I12,J12,K12,L12,M12,N12," 1;") -> /*ELI-245*/ 10111110 1;
A13: Big Pride | B13: Big Pride F06 | C13: ELI-223 | D13: 0 | E13: 0 | F13: 0 | G13: 0 | H13: 0 | I13: 0 | J13: 0 | K13: 1 | L13: 1 | M13: 1 | N13: 0 | O13: 0 | P13: =VLOOKUP(C13,[1]allprides!$C$2:$X$170,14,FALSE) -> 1 | Q13: =VLOOKUP(C13,[1]allprides!$C$2:$X$170,15,FALSE) -> 0 | R13: =VLOOKUP(C13,[1]allprides!$C$2:$X$170,16,FALSE) -> 0 | S13: =VLOOKUP(C13,[1]allprides!$C$2:$X$170,17,FALSE) -> 1 | T13: =VLOOKUP(C13,[1]allprides!$C$2:$X$170,18,FALSE) -> 2008 | U13: =VLOOKUP(C13,[1]allprides!$C$2:$X$170,19,FALSE) -> 10 | V13: =VLOOKUP(C13,[1]allprides!$C$2:$X$170,20,FALSE) -> 1 | W13: 1 | X13: =CONCATENATE("/*",C13,"*/ ",G13,H13,I13,J13,K13,L13,M13,N13," 1;") -> /*ELI-223*/ 00001110 1;
A14: Big Pride | B14: Big Pride F07 | C14: ELI-220 | D14: 0 | E14: 0 | F14: 0 | G14: 0 | H14: 0 | I14: 0 | J14: 0 | K14: 1 | L14: 1 | M14: 1 | N14: 0 | O14: 0 | P14: =VLOOKUP(C14,[1]allprides!$C$2:$X$170,14,FALSE) -> 1 | Q14: =VLOOKUP(C14,[1]allprides!$C$2:$X$170,15,FALSE) -> 0 | R14: =VLOOKUP(C14,[1]allprides!$C$2:$X$170,16,FALSE) -> 0 | S14: =VLOOKUP(C14,[1]allprides!$C$2:$X$170,17,FALSE) -> 1 | T14: =VLOOKUP(C14,[1]allprides!$C$2:$X$170,18,FALSE) -> 2008 | U14: =VLOOKUP(C14,[1]allprides!$C$2:$X$170,19,FALSE) -> 10 | V14: =VLOOKUP(C14,[1]allprides!$C$2:$X$170,20,FALSE) -> 0 | W14: 1 | X14: =CONCATENATE("/*",C14,"*/ ",G14,H14,I14,J14,K14,L14,M14,N14," 1;") -> /*ELI-220*/ 00001110 1;
... A21: Big Pride | B21: 2014 Cub 5 | C21: ELI-765 | D21: 0 | E21: 0 | F21: 0 | G21: 1 | H21: 0 | I21: 1 | J21: 0 | K21: 1 | L21: 1 | M21: 1 | N21: 0 | O21: 0 | P21: =VLOOKUP(C21,[1]allprides!$C$2:$X$170,14,FALSE) -> 1 | Q21: =VLOOKUP(C21,[1]allprides!$C$2:$X$170,15,FALSE) -> 1 | R21: =VLOOKUP(C21,[1]allprides!$C$2:$X$170,16,FALSE) -> 0 | S21: =VLOOKUP(C21,[1]allprides!$C$2:$X$170,17,FALSE) -> 1 | T21: =VLOOKUP(C21,[1]allprides!$C$2:$X$170,18,FALSE) -> 2014 | U21: =VLOOKUP(C21,[1]allprides!$C$2:$X$170,19,FALSE) -> 4 | V21: =VLOOKUP(C21,[1]allprides!$C$2:$X$170,20,FALSE) -> 0 | W21: 1 | X21: =CONCATENATE("/*",C21,"*/ ",G21,H21,I21,J21,K21,L21,M21,N21," 1;") -> /*ELI-765*/ 10101110 1;
A22: Big Pride | B22: 2015 Cub1 | C22: ELI-815 | D22: 0 | E22: 0 | F22: 0 | G22: 0 | H22: 0 | I22: 0 | J22: 0 | K22: 1 | L22: 1 | M22: 1 | N22: 0 | O22: 0 | P22: 1 | Q22: 0 | R22: 0 | S22: 1 | T22: 2015 | U22: 8 | V22: 0 | W22: 1 | X22: =CONCATENATE("/*",C22,"*/ ",G22,H22,I22,J22,K22,L22,M22,N22," 1;") -> /*ELI-815*/ 00001110 1;
A23: Big Pride | B23: 2015 Cub2 | C23: ELI-816 | D23: 0 | E23: 0 | F23: 0 | G23: 0 | H23: 0 | I23: 0 | J23: 0 | K23: 1 | L23: 1 | M23: 1 | N23: 0 | O23: 0 | P23: 1 | Q23: 0 | R23: 0 | S23: 1 | T23: 2015 | U23: 8 | V23: 0 | W23: 1 | X23: =CONCATENATE("/*",C23,"*/ ",G23,H23,I23,J23,K23,L23,M23,N23," 1;") -> /*ELI-816*/ 00001110 1;
A24: Big Pride | B24: 2015 Cub3 | C24: ELI-817 | D24: 0 | E24: 0 | F24: 0 | G24: 0 | H24: 0 | I24: 0 | J24: 0 | K24: 1 | L24: 1 | M24: 1 | N24: 0 | O24: 0 | P24: 1 | Q24: 1 | R24: 0 | S24: 1 | T24: 2015 | U24: 8 | V24: 0 | W24: 1 | X24: =CONCATENATE("/*",C24,"*/ ",G24,H24,I24,J24,K24,L24,M24,N24," 1;") -> /*ELI-817*/ 00001110 1;
A25: Big Pride | B25: 2015 Cub4 | C25: ELI-818 | D25: 0 | E25: 0 | F25: 0 | G25: 0 | H25: 0 | I25: 0 | J25: 0 | K25: 1 | L25: 1 | M25: 1 | N25: 0 | O25: 0 | P25: 1 | Q25: 1 | R25: 0 | S25: 1 | T25: 2015 | U25: 8 | V25: 0 | W25: 1 | X25: =CONCATENATE("/*",C25,"*/ ",G25,H25,I25,J25,K25,L25,M25,N25," 1;") -> /*ELI-818*/ 00001110 1;
A26: Big Pride | B26: 2015 Cub5 | C26: ELI-819 | D26: 0 | E26: 0 | F26: 0 | G26: 0 | H26: 0 | I26: 0 | J26: 0 | K26: 1 | L26: 1 | M26: 1 | N26: 0 | O26: 0 | P26: 1 | Q26: 1 | R26: 0 | S26: 1 | T26: 2015 | U26: 8 | V26: 0 | W26: 1 | X26: =CONCATENATE("/*",C26,"*/ ",G26,H26,I26,J26,K26,L26,M26,N26," 1;") -> /*ELI-819*/ 00001110 1;
A27: Big Pride | B27: 2015 Cub6 | C27: ELI-820 | D27: 0 | E27: 0 | F27: 0 | G27: 0 | H27: 0 | I27: 0 | J27: 0 | K27: 1 | L27: 1 | M27: 1 | N27: 0 | O27: 0 | P27: 1 | Q27: 1 | R27: 0 | S27: 1 | T27: 2015 | U27: 8 | V27: 0 | W27: 1 | X27: =CONCATENATE("/*",C27,"*/ ",G27,H27,I27,J27,K27,L27,M27,N27," 1;") -> /*ELI-820*/ 00001110 1;
A28: Big Pride | B28: 2015 Cub7 | C28: ELI-821 | D28: 0 | E28: 0 | F28: 0 | G28: 0 | H28: 0 | I28: 0 | J28: 1 | K28: 1 | L28: 1 | M28: 1 | N28: 0 | O28: 0 | P28: 1 | Q28: 0 | R28: 0 | S28: 1 | T28: 2015 | U28: 7 | V28: 0 | W28: 1 | X28: =CONCATENATE("/*",C28,"*/ ",G28,H28,I28,J28,K28,L28,M28,N28," 1;") -> /*ELI-821*/ 00011110 1;
A29: Big Pride | B29: 2015 Cub8 | C29: ELI-822 | D29: 0 | E29: 0 | F29: 0 | G29: 0 | H29: 0 | I29: 0 | J29: 1 | K29: 1 | L29: 1 | M29: 1 | N29: 0 | O29: 0 | P29: 1 | Q29: 0 | R29: 0 | S29: 1 | T29: 2015 | U29: 7 | V29: 0 | W29: 1 | X29: =CONCATENATE("/*",C29,"*/ ",G29,H29,I29,J29,K29,L29,M29,N29," 1;") -> /*ELI-822*/ 00011110 1;
A30: Chowo | B30: Chowo F01 | C30: ELI-414 | D30: 0 | E30: 1 | F30: 0 | G30: 1 | H30: 0 | I30: 1 | J30: 1 | K30: 1 | L30: 1 | M30: 1 | N30: 1 | O30: 0 | P30: =VLOOKUP(C30,[1]allprides!$C$2:$X$170,14,FALSE) -> 1 | Q30: =VLOOKUP(C30,[1]allprides!$C$2:$X$170,15,FALSE) -> 0 | R30: =VLOOKUP(C30,[1]allprides!$C$2:$X$170,16,FALSE) -> 0 | S30: =VLOOKUP(C30,[1]allprides!$C$2:$X$170,17,FALSE) -> 1 | T30: =VLOOKUP(C30,[1]allprides!$C$2:$X$170,18,FALSE) -> 2011 | U30: =VLOOKUP(C30,[1]allprides!$C$2:$X$170,19,FALSE) -> 7 | V30: =VLOOKUP(C30,[1]allprides!$C$2:$X$170,20,FALSE) -> 3 | W30: 1 | X30: =CONCATENATE("/*",C30,"*/ ",G30,H30,I30,J30,K30,L30,M30,N30," 1;") -> /*ELI-414*/ 10111111 1;
A31: Chowo | B31: Chowo F05 | C31: ELI-493 | D31: 0 | E31: 1 | F31: 0 | G31: 1 | H31: 0 | I31: 1 | J31: 1 | K31: 1 | L31: 0 | M31: 0 | N31: 0 | O31: 0 | P31: =VLOOKUP(C31,[1]allprides!$C$2:$X$170,14,FALSE) -> 1 | Q31: =VLOOKUP(C31,[1]allprides!$C$2:$X$170,15,FALSE) -> 0 | R31: 1 | S31: =VLOOKUP(C31,[1]allprides!$C$2:$X$170,17,FALSE) -> 1 | T31: =VLOOKUP(C31,[1]allprides!$C$2:$X$170,18,FALSE) -> 2012 | U31: =VLOOKUP(C31,[1]allprides!$C$2:$X$170,19,FALSE) -> 6 | V31: =VLOOKUP(C31,[1]allprides!$C$2:$X$170,20,FALSE) -> 4 | W31: 1 | X31: =CONCATENATE("/*",C31,"*/ ",G31,H31,I31,J31,K31,L31,M31,N31," 1;") -> /*ELI-493*/ 10111000 1;
A32: Chowo | B32: Chowo F06 | C32: ELI-494 | D32: 0 | E32: 0 | F32: 0 | G32: 0 | H32: 0 | I32: 1 | J32: 0 | K32: 1 | L32: 0 | M32: 0 | N32: 0 | O32: 0 | P32: =VLOOKUP(C32,[1]allprides!$C$2:$X$170,14,FALSE) -> 1 | Q32: =VLOOKUP(C32,[1]allprides!$C$2:$X$170,15,FALSE) -> 0 | R32: 0 | S32: =VLOOKUP(C32,[1]allprides!$C$2:$X$170,17,FALSE) -> 1 | T32: =VLOOKUP(C32,[1]allprides!$C$2:$X$170,18,FALSE) -> 2012 | U32: 6 | V32: 1 | W32: 1 | X32: =CONCATENATE("/*",C32,"*/ ",G32,H32,I32,J32,K32,L32,M32,N32," 1;") -> /*ELI-494*/ 00101000 1;
A33: Chowo | B33: Chowo U02 | C33: ELI-598 | D33: 0 | E33: 0 | F33: 0 | G33: 0 | H33: 0 | I33: 0 | J33: 0 | K33: 1 | L33: 0 | M33: 0 | N33: 0 | O33: 0 | P33: =VLOOKUP(C33,[1]allprides!$C$2:$X$170,14,FALSE) -> 1 | Q33: =VLOOKUP(C33,[1]allprides!$C$2:$X$170,15,FALSE) -> 0 | R33: 0 | S33: =VLOOKUP(C33,[1]allprides!$C$2:$X$170,17,FALSE) -> 1 | T33: 2013 | U33: 4 | V33: 0 | W33: 1 | X33: =CONCATENATE("/*",C33,"*/ ",G33,H33,I33,J33,K33,L33,M33,N33," 1;") -> /*ELI-598*/ 00001000 1;
A34: Chowo | B34: Chowo U03 | C34: ELI-599 | D34: 0 | E34: 0 | F34: 0 | G34: 0 | H34: 0 | I34: 0 | J34: 0 | K34: 1 | L34: 0 | M34: 0 | N34: 0 | O34: 0 | P34: =VLOOKUP(C34,[1]allprides!$C$2:$X$170,14,FALSE) -> 1 | Q34: =VLOOKUP(C34,[1]allprides!$C$2:$X$170,15,FALSE) -> 0 | R34: 0 | S34: =VLOOKUP(C34,[1]allprides!$C$2:$X$170,17,FALSE) -> 1 | T34: 2013 | U34: 4 | V34: 0 | W34: 1 | X34: =CONCATENATE("/*",C34,"*/ ",G34,H34,I34,J34,K34,L34,M34,N34," 1;") -> /*ELI-599*/ 00001000 1;
A35: Chichele | B35: Chichele F03 | C35: ELI-235 | D35: 0 | E35: 0 | F35: 0 | G35: 1 | H35: 0 | I35: 1 | J35: 1 | K35: 1 | L35: 1 | M35: 1 | N35: 1 | O35: 1 | P35: =VLOOKUP(C35,[1]allprides!$C$2:$X$170,14,FALSE) -> 1 | Q35: =VLOOKUP(C35,[1]allprides!$C$2:$X$170,15,FALSE) -> 0 | R35: =VLOOKUP(C35,[1]allprides!$C$2:$X$170,16,FALSE) -> 0 | S35: =VLOOKUP(C35,[1]allprides!$C$2:$X$170,17,FALSE) -> 1 | T35: =VLOOKUP(C35,[1]allprides!$C$2:$X$170,18,FALSE) -> 2008 | U35: =VLOOKUP(C35,[1]allprides!$C$2:$X$170,19,FALSE) -> 9 | V35: =VLOOKUP(C35,[1]allprides!$C$2:$X$170,20,FALSE) -> 2 | W35: 1 | X35: =CONCATENATE("/*",C35,"*/ ",G35,H35,I35,J35,K35,L35,M35,N35," 1;") -> /*ELI-235*/ 10111111 1;
A36: Chichele | B36: Chichele Cub1 | C36: ELI-604 | D36: 0 | E36: 0 | F36: 0 | G36: 1 | H36: 0 | I36: 1 | J36: 1 | K36: 1 | L36: 1 | M36: 0 | N36: 1 | O36: 1 | P36: =VLOOKUP(C36,[1]allprides!$C$2:$X$170,14,FALSE) -> 1 | Q36: =VLOOKUP(C36,[1]allprides!$C$2:$X$170,15,FALSE) -> 1 | R36: =VLOOKUP(C36,[1]allprides!$C$2:$X$170,16,FALSE) -> 0 | S36: =VLOOKUP(C36,[1]allprides!$C$2:$X$170,17,FALSE) -> 1 | T36: =VLOOKUP(C36,[1]allprides!$C$2:$X$170,18,FALSE) -> 2014 | U36: =VLOOKUP(C36,[1]allprides!$C$2:$X$170,19,FALSE) -> 4 | V36: =VLOOKUP(C36,[1]allprides!$C$2:$X$170,20,FALSE) -> 0 | W36: 1 | X36: =CONCATENATE("/*",C36,"*/ ",G36,H36,I36,J36,K36,L36,M36,N36," 1;") -> /*ELI-604*/ 10111101 1;
A37: Chichele | B37: Chichele Cub3 | C37: ELI-606 | D37: 0 | E37: 0 | F37: 0 | G37: 1 | H37: 0 | I37: 1 | J37: 1 | K37: 1 | L37: 1 | M37: 0 | N37: 1 | O37: 1 | P37: =VLOOKUP(C37,[1]allprides!$C$2:$X$170,14,FALSE) -> 1 | Q37: =VLOOKUP(C37,[1]allprides!$C$2:$X$170,15,FALSE) -> 0 | R37: =VLOOKUP(C37,[1]allprides!$C$2:$X$170,16,FALSE) -> 1 | S37: =VLOOKUP(C37,[1]allprides!$C$2:$X$170,17,FALSE) -> 1 | T37: =VLOOKUP(C37,[1]allprides!$C$2:$X$170,18,FALSE) -> 2014 | U37: =VLOOKUP(C37,[1]allprides!$C$2:$X$170,19,FALSE) -> 4 | V37: =VLOOKUP(C37,[1]allprides!$C$2:$X$170,20,FALSE) -> 0 | W37: 1 | X37: =CONCATENATE("/*",C37,"*/ ",G37,H37,I37,J37,K37,L37,M37,N37," 1;") -> /*ELI-606*/ 10111101 1;
A38: Chinzombo | B38: Chinzombo F01 | C38: ELI-143 | D38: 1 | E38: 0 | F38: 0 | G38: 0 | H38: 1 | I38: 1 | J38: 1 | K38: 1 | L38: 1 | M38: 1 | N38: 0 | O38: 0 | P38: =VLOOKUP(C38,[1]allprides!$C$2:$X$170,14,FALSE) -> 1 | Q38: =VLOOKUP(C38,[1]allprides!$C$2:$X$170,15,FALSE) -> 0 | R38: =VLOOKUP(C38,[1]allprides!$C$2:$X$170,16,FALSE) -> 0 | S38: =VLOOKUP(C38,[1]allprides!$C$2:$X$170,17,FALSE) -> 1 | T38: =VLOOKUP(C38,[1]allprides!$C$2:$X$170,18,FALSE) -> 2012 | U38: =VLOOKUP(C38,[1]allprides!$C$2:$X$170,19,FALSE) -> 4 | V38: =VLOOKUP(C38,[1]allprides!$C$2:$X$170,20,FALSE) -> 4 | W38: 1 | X38: =CONCATENATE("/*",C38,"*/ ",G38,H38,I38,J38,K38,L38,M38,N38," 1;") -> /*ELI-143*/ 01111110 1;
A39: Chinzombo | B39: Chinzombo F02 | C39: ELI-496 | D39: 0 | E39: 0 | F39: 0 | G39: 0 | H39: 1 | I39: 0 | J39: 1 | K39: 1 | L39: 0 | M39: 1 | N39: 0 | O39: 0 | P39: =VLOOKUP(C39,[1]allprides!$C$2:$X$170,14,FALSE) -> 1 | Q39: =VLOOKUP(C39,[1]allprides!$C$2:$X$170,15,FALSE) -> 0 | R39: =VLOOKUP(C39,[1]allprides!$C$2:$X$170,16,FALSE) -> 0 | S39: =VLOOKUP(C39,[1]allprides!$C$2:$X$170,17,FALSE) -> 1 | T39: =VLOOKUP(C39,[1]allprides!$C$2:$X$170,18,FALSE) -> 2014 | U39: =VLOOKUP(C39,[1]allprides!$C$2:$X$170,19,FALSE) -> 5 | V39: =VLOOKUP(C39,[1]allprides!$C$2:$X$170,20,FALSE) -> 2 | W39: 1 | X39: =CONCATENATE("/*",C39,"*/ ",G39,H39,I39,J39,K39,L39,M39,N39," 1;") -> /*ELI-496*/ 01011010 1;
A40: Chinzombo | B40: Chinzombo F03 | C40: ELI-703 | D40: 0 | E40: 0 | F40: 0 | G40: 0 | H40: 1 | I40: 0 | J40: 1 | K40: 1 | L40: 0 | M40: 1 | N40: 0 | O40: 0 | P40: =VLOOKUP(C40,[1]allprides!$C$2:$X$170,14,FALSE) -> 1 | Q40: =VLOOKUP(C40,[1]allprides!$C$2:$X$170,15,FALSE) -> 0 | R40: =VLOOKUP(C40,[1]allprides!$C$2:$X$170,16,FALSE) -> 0 | S40: =VLOOKUP(C40,[1]allprides!$C$2:$X$170,17,FALSE) -> 1 | T40: =VLOOKUP(C40,[1]allprides!$C$2:$X$170,18,FALSE) -> 2014 | U40: =VLOOKUP(C40,[1]allprides!$C$2:$X$170,19,FALSE) -> 5 | V40: =VLOOKUP(C40,[1]allprides!$C$2:$X$170,20,FALSE) -> 0 | W40: 1 | X40: =CONCATENATE("/*",C40,"*/ ",G40,H40,I40,J40,K40,L40,M40,N40," 1;") -> /*ELI-703*/ 01011010 1;
A41: Tena Tena | B41: Tena Tena F02 | C41: ELI-262 | D41: 0 | E41: 0 | F41: 0 | G41: 0 | H41: 0 | I41: 0 | J41: 1 | K41: 1 | L41: 0 | M41: 0 | N41: 0 | O41: 0 | P41: =VLOOKUP(C41,[1]allprides!$C$2:$X$170,14,FALSE) -> 1 | Q41: =VLOOKUP(C41,[1]allprides!$C$2:$X$170,15,FALSE) -> 0 | R41: =VLOOKUP(C41,[1]allprides!$C$2:$X$170,16,FALSE) -> 0 | S41: =VLOOKUP(C41,[1]allprides!$C$2:$X$170,17,FALSE) -> 1 | T41: =VLOOKUP(C41,[1]allprides!$C$2:$X$170,18,FALSE) -> 2008 | U41: =VLOOKUP(C41,[1]allprides!$C$2:$X$170,19,FALSE) -> 6 | V41: =VLOOKUP(C41,[1]allprides!$C$2:$X$170,20,FALSE) -> 2 | W41: 0 | X41: =CONCATENATE("/*",C41,"*/ ",G41,H41,I41,J41,K41,L41,M41,N41," 1;") -> /*ELI-262*/ 00011000 1;
A42: Tena Tena | B42: Tena Tena Cub 1 | C42: ELI-752 | D42: 0 | E42: 0 | F42: 0 | G42: 0 | H42: 0 | I42: 0 | J42: 1 | K42: 1 | L42: 0 | M42: 0 | N42: 0 | O42: 0 | P42: =VLOOKUP(C42,[1]allprides!$C$2:$X$170,14,FALSE) -> 1 | Q42: =VLOOKUP(C42,[1]allprides!$C$2:$X$170,15,FALSE) -> 1 | R42: =VLOOKUP(C42,[1]allprides!$C$2:$X$170,16,FALSE) -> 0 | S42: =VLOOKUP(C42,[1]allprides!$C$2:$X$170,17,FALSE) -> 1 | T42: =VLOOKUP(C42,[1]allprides!$C$2:$X$170,18,FALSE) -> 2014 | U42: =VLOOKUP(C42,[1]allprides!$C$2:$X$170,19,FALSE) -> 6 | V42: =VLOOKUP(C42,[1]allprides!$C$2:$X$170,20,FALSE) -> 0 | W42: 0 | X42: =CONCATENATE("/*",C42,"*/ ",G42,H42,I42,J42,K42,L42,M42,N42," 1;") -> /*ELI-752*/ 00011000 1;
A43: Tena Tena | B43: Tena Tena Cub 2 | C43: ELI-753 | D43: 0 | E43: 0 | F43: 0 | G43: 0 | H43: 0 | I43: 0 | J43: 1 | K43: 1 | L43: 0 | M43: 0 | N43: 0 | O43: 0 | P43: =VLOOKUP(C43,[1]allprides!$C$2:$X$170,14,FALSE) -> 1 | Q43: =VLOOKUP(C43,[1]allprides!$C$2:$X$170,15,FALSE) -> 0 | R43: =VLOOKUP(C43,[1]allprides!$C$2:$X$170,16,FALSE) -> 0 | S43: =VLOOKUP(C43,[1]allprides!$C$2:$X$170,17,FALSE) -> 1 | T43: =VLOOKUP(C43,[1]allprides!$C$2:$X$170,18,FALSE) -> 2014 | U43: =VLOOKUP(C43,[1]allprides!$C$2:$X$170,19,FALSE) -> 6 | V43: =VLOOKUP(C43,[1]allprides!$C$2:$X$170,20,FALSE) -> 0 | W43: 0 | X43: =CONCATENATE("/*",C43,"*/ ",G43,H43,I43,J43,K43,L43,M43,N43," 1;") -> /*ELI-753*/ 00011000 1;
A44: Tena Tena | C44: ELI-757 | D44: 0 | E44: 0 | F44: 0 | G44: 0 | H44: 0 | I44: 0 | J44: 0 | K44: 1 | L44: 0 | M44: 0 | N44: 0 | O44: 0 | P44: 0 | Q44: 0 | R44: 0 | S44: 1 | T44: =VLOOKUP(C44,[1]allprides!$C$2:$X$170,18,FALSE) -> 2014 | U44: 6 | V44: 0 | W44: 0
A45: Tena Tena | C45: ELI-260 | D45: 0 | E45: 0 | F45: 0 | G45: 0 | H45: 0 | I45: 0 | J45: 0 | K45: 1 | L45: 0 | M45: 0 | N45: 0 | O45: 0 | P45: 1 | Q45: 0 | R45: 0 | S45: 1 | T45: 2008 | U45: 6 | V45: 1 | W45: 0
A46: Nsefu | B46: Nsefu F01 | C46: ELI-173 | D46: 0 | E46: 0 | F46: 0 | G46: 0 | H46: 0 | I46: 0 | J46: 1 | K46: 0 | L46: 1 | M46: 0 | N46: 1 | O46: 0 | P46: =VLOOKUP(C46,[1]allprides!$C$2:$X$170,14,FALSE) -> 1 | Q46: =VLOOKUP(C46,[1]allprides!$C$2:$X$170,15,FALSE) -> 0 | R46: =VLOOKUP(C46,[1]allprides!$C$2:$X$170,16,FALSE) -> 0 | S46: =VLOOKUP(C46,[1]allprides!$C$2:$X$170,17,FALSE) -> 1 | T46: =VLOOKUP(C46,[1]allprides!$C$2:$X$170,18,FALSE) -> 2008 | U46: =VLOOKUP(C46,[1]allprides!$C$2:$X$170,19,FALSE) -> 8 | V46: =VLOOKUP(C46,[1]allprides!$C$2:$X$170,20,FALSE) -> 2 | W46: 1 | X46: =CONCATENATE("/*",C46,"*/ ",G46,H46,I46,J46,K46,L46,M46,N46," 1;") -> /*ELI-173*/ 00010101 1;
...

Sheet NHK
D1: Jan | E1: Feb | F1: Mar | G1: Apr | H1: May | I1: Jun | J1: Jul | K1: Aug | L1: Sept | M1: Oct | N1: Nov | O1: Dec
B2: Group | C2: ID
B3: Nsefu F01 | C3: ELI-173 | D3: 0 | E3: 0 | F3: 0 | G3: 0 | H3: 0 | I3: 0 | J3: 1 | K3: 0 | L3: 1 | M3: 0 | N3: 1 | O3: 0
B4: Nsefu F02 | C4: ELI-174 | D4: 0 | E4: 0 | F4: 0 | G4: 0 | H4: 0 | I4: 0 | J4: 0 | K4: 0 | L4: 0 | M4: 0 | N4: 0 | O4: 0
B5: Nsefu F03 | C5: ELI-247 | D5: 0 | E5: 0 | F5: 0 | G5: 0 | H5: 0 | I5: 0 | J5: 1 | K5: 0 | L5: 1 | M5: 0 | N5: 1 | O5: 0
B6: Nsefu F04 | C6: ELI-248 | D6: 0 | E6: 0 | F6: 0 | G6: 0 | H6: 0 | I6: 1 | J6: 1 | K6: 0 | L6: 1 | M6: 1 | N6: 1 | O6: 0
B7: Nsefu F05 | C7: ELI-249 | D7: 0 | E7: 0 | F7: 0 | G7: 0 | H7: 0 | I7: 0 | J7: 0 | K7: 0 | L7: 0 | M7: 0 | N7: 0 | O7: 0
B8: Nsefu F06 | C8: ELI-250 | D8: 0 | E8: 0 | F8: 0 | G8: 0 | H8: 0 | I8: 0 | J8: 0 | K8: 1 | L8: 1 | M8: 1 | N8: 1 | O8: 0
B9: Nsefu F07 | C9: ELI-462 | D9: 0 | E9: 0 | F9: 0 | G9: 0 | H9: 0 | I9: 1 | J9: 1 | K9: 0 | L9: 1 | M9: 1 | N9: 1 | O9: 0
B10: Nsefu F11 | C10: ELI-378 | D10: 0 | E10: 0 | F10: 0 | G10: 0 | H10: 0 | I10: 0 | J10: 1 | K10: 0 | L10: 1 | M10: 0 | N10: 0 | O10: 0
B11: Nsefu F12 | C11: ELI-463 | D11: 0 | E11: 0 | F11: 0 | G11: 0 | H11: 0 | I11: 1 | J11: 1 | K11: 0 | L11: 1 | M11: 1 | N11: 1 | O11: 0
B12: Nsefu M06 | C12: ELI-464 | D12: 0 | E12: 0 | F12: 0 | G12: 0 | H12: 0 | I12: 0 | J12: 0 | K12: 0 | L12: 0 | M12: 0 | N12: 0 | O12: 0
B13: Nsefu M07 | C13: ELI-553 | D13: 0 | E13: 0 | F13: 0 | G13: 0 | H13: 0 | I13: 0 | J13: 0 | K13: 0 | L13: 0 | M13: 0 | N13: 0 | O13: 0
B14: Nsefu F09 | C14: ELI-254 | D14: 0 | E14: 0 | F14: 0 | G14: 0 | H14: 0 | I14: 0 | J14: 0 | K14: 0 | L14: 0 | M14: 0 | N14: 0 | O14: 0
C15: ELI-589 | D15: 0 | E15: 0 | F15: 0 | G15: 0 | H15: 0 | I15: 0 | J15: 1 | K15: 0 | L15: 1 | M15: 0 | N15: 1 | O15: 0
C16: ELI-713 | D16: 0 | E16: 0 | F16: 0 | G16: 0 | H16: 0 | I16: 0 | J16: 1 | K16: 0 | L16: 1 | M16: 0 | N16: 1 | O16: 0
C17: ELI-714 | D17: 0 | E17: 0 | F17: 0 | G17: 0 | H17: 0 | I17: 0 | J17: 1 | K17: 0 | L17: 1 | M17: 0 | N17: 1 | O17: 0
C18: ELI-716 | D18: 0 | E18: 0 | F18: 0 | G18: 0 | H18: 0 | I18: 0 | J18: 1 | K18: 0 | L18: 1 | M18: 0 | N18: 1 | O18: 0
C19: ELI-717 | D19: 0 | E19: 0 | F19: 0 | G19: 0 | H19: 0 | I19: 0 | J19: 1 | K19: 1 | L19: 1 | M19: 0 | N19: 0 | O19: 0
C20: ELI-718 | D20: 0 | E20: 0 | F20: 0 | G20: 0 | H20: 0 | I20: 0 | J20: 1 | K20: 0 | L20: 1 | M20: 0 | N20: 1 | O20: 0
C21: ELI-719 | D21: 0 | E21: 0 | F21: 0 | G21: 0 | H21: 0 | I21: 0 | J21: 1 | K21: 1 | L21: 1 | M21: 0 | N21: 1 | O21: 0
B22: Cub 1 | C22: ELI-NSE1 | D22: 0 | E22: 0 | F22: 0 | G22: 0 | H22: 0 | I22: 0 | J22: 0 | K22: 0 | L22: 1 | M22: 1 | N22: 1 | O22: 0 | U22: 8
B23: Cub 2 | C23: ELI-NSE2 | D23: 0 | E23: 0 | F23: 0 | G23: 0 | H23: 0 | I23: 0 | J23: 0 | K23: 0 | L23: 1 | M23: 1 | N23: 1 | O23: 0 | U23: 8
B24: Cub 3 | C24: ELI-NSE3 | D24: 0 | E24: 0 | F24: 0 | G24: 0 | H24: 0 | I24: 0 | J24: 0 | K24: 0 | L24: 1 | M24: 1 | N24: 1 | O24: 0
B25: Cub 4 | C25: ELI-NSE4 | D25: 0 | E25: 0 | F25: 0 | G25: 0 | H25: 0 | I25: 0 | J25: 0 | K25: 0 | L25: 1 | M25: 1 | N25: 1 | O25: 0
B26: Cub 5 | C26: ELI-NSE5 | D26: 0 | E26: 0 | F26: 0 | G26: 0 | H26: 0 | I26: 0 | J26: 0 | K26: 0 | L26: 1 | M26: 1 | N26: 1 | O26: 0
B27: Cub 6 | C27: ELI-NSE6 | D27: 0 | E27: 0 | F27: 0 | G27: 0 | H27: 0 | I27: 0 | J27: 0 | K27: 0 | L27: 1 | M27: 0 | N27: 0 | O27: 0
J28: 1 | M28: 1 | U28: 7
B29: Group | C29: ID | J29: 1 | M29: 1 | U29: 7
B30: Hot Springs F01 | C30: ELI-258 | D30: 0 | E30: 1 | F30: 0 | G30: 0 | H30: 0 | I30: 0 | J30: 0 | K30: 0 | L30: 1 | M30: 0 | N30: 0 | O30: 0
B31: Hot Springs F02 | C31: ELI-256 | D31: 0 | E31: 1 | F31: 0 | G31: 0 | H31: 0 | I31: 0 | J31: 0 | K31: 0 | L31: 1 | M31: 0 | N31: 0 | O31: 0
B32: Hot Springs F03 | C32: ELI-466 | D32: 0 | E32: 0 | F32: 0 | G32: 0 | H32: 0 | I32: 0 | J32: 0 | K32: 0 | L32: 0 | M32: 0 | N32: 0 | O32: 0
B33: Hot Springs M01 | C33: ELI-379 | D33: 0 | E33: 0 | F33: 0 | G33: 0 | H33: 0 | I33: 0 | J33: 0 | K33: 0 | L33: 0 | M33: 0 | N33: 0 | O33: 0
D35: Jan | E35: Feb | F35: Mar | G35: Apr | H35: May | I35: Jun | J35: Jul | K35: Aug | L35: Sept | M35: 1 | N35: Nov | O35: Dec
B36: Group | C36: ID
B37: Kapamba F01 | C37: ELI-203 | D37: 0 | E37: 0 | F37: 0 | G37: 0 | H37: 0 | I37: 0 | J37: 0 | K37: 0 | L37: 0 | M37: 0 | N37: 0 | O37: 0
B38: Kapamba F02 | C38: ELI-204 | D38: 0 | E38: 0 | F38: 0 | G38: 0 | H38: 0 | I38: 1 | J38: 0 | K38: 0 | L38: 1 | M38: 0 | N38: 0 | O38: 0
B39: Kapamba F09 | C39: ELI-532 | D39: 0 | E39: 0 | F39: 0 | G39: 0 | H39: 0 | I39: 0 | J39: 0 | K39: 0 | L39: 0 | M39: 0 | N39: 0 | O39: 0
B40: Kapamba M03 | C40: ELI-534 | D40: 0 | E40: 0 | F40: 0 | G40: 0 | H40: 0 | I40: 0 | J40: 0 | K40: 0 | L40: 0 | M40: 0 | N40: 0 | O40: 0
B41: Kapamba M04 | C41: ELI-533 | D41: 0 | E41: 0 | F41: 0 | G41: 0 | H41: 0 | I41: 0 | J41: 0 | K41: 0 | L41: 0 | M41: 0 | N41: 0 | O41: 0
...

Sheet CHM
C1: Jan | D1: Feb | E1: Mar | F1: Apr | G1: May | H1: Jun | I1: Jul | J1: Aug | K1: Sept | L1: Oct | M1: Nov | N1: Dec
A2: Group | B2: ID
A3: 2011 Cub U01 | B3: ELI-438 | C3: 0 | D3: 0 | E3: 0 | F3: 0 | G3: 0 | H3: 0 | I3: 0 | J3: 0 | K3: 0 | L3: 0 | M3: 0 | N3: 0
A4: 2011 Cub U02 | B4: ELI-441 | C4: 0 | D4: 0 | E4: 0 | F4: 0 | G4: 0 | H4: 0 | I4: 0 | J4: 0 | K4: 0 | L4: 0 | M4: 0 | N4: 0
A5: 2011 Cub U03 | B5: ELI-442 | C5: 0 | D5: 0 | E5: 0 | F5: 0 | G5: 0 | H5: 0 | I5: 0 | J5: 0 | K5: 0 | L5: 0 | M5: 0 | N5: 0
A6: 2011 Cub U04 | B6: ELI-443 | C6: 0 | D6: 0 | E6: 0 | F6: 0 | G6: 0 | H6: 0 | I6: 0 | J6: 0 | K6: 0 | L6: 0 | M6: 0 | N6: 0
A7: Chamilandu F01 | B7: ELI-192 | C7: 0 | D7: 0 | E7: 0 | F7: 0 | G7: 0 | H7: 0 | I7: 0 | J7: 0 | K7: 0 | L7: 0 | M7: 0 | N7: 0
A8: Chamilandu F02 | B8: ELI-193 | C8: 0 | D8: 0 | E8: 0 | F8: 0 | G8: 0 | H8: 0 | I8: 0 | J8: 0 | K8: 0 | L8: 0 | M8: 0 | N8: 0
A9: Chamilandu F03 | B9: ELI-194 | C9: 0 | D9: 0 | E9: 0 | F9: 0 | G9: 0 | H9: 0 | I9: 0 | J9: 0 | K9: 0 | L9: 0 | M9: 0 | N9: 0
A10: Chamilandu F05 | B10: ELI-228 | C10: 0 | D10: 0 | E10: 0 | F10: 0 | G10: 0 | H10: 0 | I10: 0 | J10: 0 | K10: 0 | L10: 0 | M10: 0 | N10: 0
A11: Chamilandu F06 | B11: ELI-398 | C11: 0 | D11: 0 | E11: 0 | F11: 0 | G11: 0 | H11: 0 | I11: 0 | J11: 0 | K11: 0 | L11: 0 | M11: 0 | N11: 0
A12: Chamilandu F07 | B12: ELI-405 | C12: 0 | D12: 0 | E12: 0 | F12: 0 | G12: 0 | H12: 0 | I12: 1 | J12: 0 | K12: 0 | L12: 0 | M12: 1 | N12: 0
A13: Chamilandu F08 | B13: ELI-444 | C13: 0 | D13: 0 | E13: 0 | F13: 0 | G13: 0 | H13: 0 | I13: 0 | J13: 0 | K13: 0 | L13: 0 | M13: 0 | N13: 0
A14: Chamilandu F09 | B14: ELI-439 | C14: 0 | D14: 0 | E14: 0 | F14: 0 | G14: 0 | H14: 0 | I14: 0 | J14: 0 | K14: 0 | L14: 0 | M14: 0 | N14: 0
... A18: Chamilandu Male Cub 01 | B18: ELI-196 | C18: 0 | D18: 0 | E18: 0 | F18: 0 | G18: 0 | H18: 0 | I18: 0 | J18: 0 | K18: 0 | L18: 0 | M18: 0 | N18: 0
C19: 0 | D19: 0 | E19: 0 | F19: 0 | G19: 0 | H19: 0 | I19: 0 | J19: 0 | K19: 1 | L19: 0 | M19: 0 | N19: 0
K21: 1
C22: Jan | D22: Feb | E22: Mar | F22: April | G22: May | H22: Jun | I22: Jul | J22: 0 | K22: Sept | L22: Oct | M22: Nov | N22: Dec | U22: 8
A23: Group | B23: ID | J23: 0 | U23: 8
A24: Hollywood M01 | B24: ELI-233 | C24: 0 | D24: 0 | E24: 0 | F24: 0 | G24: 0 | H24: 0 | I24: 0 | J24: 0 | K24: 0 | L24: 0 | M24: 0 | N24: 0
A25: Hollywood Cub 01 '10 | B25: ELI-400 | C25: 0 | D25: 0 | E25: 0 | F25: 0 | G25: 0 | H25: 0 | I25: 0 | J25: 0 | K25: 0 | L25: 0 | M25: 0 | N25: 0
A26: Hollywood Cub 02 '10 | B26: ELI-401 | C26: 0 | D26: 0 | E26: 0 | F26: 0 | G26: 0 | H26: 0 | I26: 0 | J26: 0 | K26: 0 | L26: 0 | M26: 0 | N26: 0
A27: Hollywood F01 | B27: ELI-197 | C27: 0 | D27: 0 | E27: 0 | F27: 0 | G27: 1 | H27: 1 | I27: 1 | J27: 1 | K27: 1 | L27: 0 | M27: 0 | N27: 0
A28: Hollywood F02 | B28: ELI-198 | C28: 0 | D28: 0 | E28: 0 | F28: 0 | G28: 1 | H28: 1 | I28: 1 | J28: 1 | K28: 1 | L28: 0 | M28: 1 | N28: 0 | U28: 7
A29: Hollywood F03 | B29: ELI-230 | C29: 0 | D29: 0 | E29: 0 | F29: 0 | G29: 1 | H29: 1 | I29: 1 | J29: 1 | K29: 1 | L29: 0 | M29: 1 | N29: 0 | U29: 7
A30: Hollywood F04 | B30: ELI-231 | C30: 0 | D30: 0 | E30: 1 | F30: 0 | G30: 1 | I30: 1 | J30: 1 | K30: 0 | L30: 0 | M30: 0 | N30: 0
A31: Hollywood F05 | B31: ELI-232 | C31: 0 | D31: 0 | E31: 1 | F31: 0 | G31: 0 | H31: 0 | I31: 0 | J31: 0 | K31: 0 | L31: 0 | M31: 0 | N31: 0
A32: Hollywood F06 | B32: ELI-424 | C32: 0 | D32: 0 | E32: 0 | F32: 0 | G32: 0 | H32: 0 | I32: 1 | J32: 0 | K32: 0 | L32: 0 | M32: 0 | N32: 0
B33: ELI-425 | I33: 1 | K33: 1
B34: ELI-613 | C34: 0 | D34: 0 | E34: 0 | F34: 0 | G34: 1 | H34: 1 | I34: 1 | J34: 1 | K34: 1 | L34: 0 | M34: 0 | N34: 0
B35: ELI-615 | C35: 0 | D35: 0 | E35: 0 | F35: 0 | G35: 0 | H35: 1 | I35: 1 | K35: 1 | L35: 0 | M35: 1 | N35: 0
B36: ELI-616 | C36: 0 | D36: 0 | E36: 0 | F36: 0 | G36: 1 | H36: 1 | I36: 1 | J36: 1 | K36: 1 | L36: 0 | M36: 0 | N36: 0
B37: ELI-617 | C37: 0 | D37: 0 | E37: 0 | F37: 0 | G37: 0 | H37: 1 | I37: 1 | J37: 0 | K37: 1 | L37: 0 | M37: 0 | N37: 0
B38: ELI-618 | C38: 0 | D38: 0 | E38: 0 | F38: 0 | G38: 1 | I38: 1 | J38: 1 | K38: 1 | L38: 1 | M38: 0 | N38: 0
B39: ELI-738 | C39: 0 | D39: 0 | E39: 0 | F39: 0 | G39: 0 | H39: 1 | I39: 1 | J39: 0 | K39: 1 | L39: 0 | M39: 0 | N39: 0
B40: ELI-737 | C40: 0 | D40: 0 | E40: 0 | F40: 0 | G40: 1 | H40: 1 | I40: 1 | J40: 0 | K40: 1 | L40: 0 | M40: 0 | N40: 0
B41: ELI-736 | C41: 0 | D41: 0 | E41: 0 | F41: 0 | G41: 1 | H41: 1 | I41: 1 | J41: 1 | K41: 1 | L41: 0 | M41: 0 | N41: 0
B42: ELI-735 | C42: 0 | D42: 0 | E42: 0 | F42: 0 | G42: 0 | H42: 1 | I42: 1 | J42: 0 | K42: 1 | L42: 0 | M42: 0 | N42: 0
C44: Jan | D44: Feb | E44: Mar | F44: Apr | G44: May | H44: Jun | I44: Jul | J44: Aug | K44: Sept | L44: Oct | M44: Nov | N44: Dec
A45: Group | B45: ID
...

Sheet LM
C1: Jan | D1: Feb | E1: Mar | F1: Apr | G1: May | H1: Jun | I1: Jul | J1: Aug | K1: Sept | L1: Oct | M1: Nov | N1: Dec
A2: Group | B2: ID
A3: Luwi F01 | B3: ELI-152 | C3: 0 | D3: 0 | E3: 0 | F3: 0 | G3: 0 | H3: 0 | I3: 0 | J3: 0 | K3: 0 | L3: 0 | M3: 0 | N3: 0
A4: Luwi F03 | B4: ELI-154 | C4: 0 | D4: 0 | E4: 0 | F4: 0 | G4: 0 | H4: 0 | I4: 0 | J4: 0 | K4: 0 | L4: 0 | M4: 0 | N4: 0
A5: Luwi F04 | B5: ELI-155 | C5: 0 | D5: 0 | E5: 0 | F5: 0 | G5: 0 | H5: 1 | I5: 1 | J5: 1 | K5: 1 | L5: 1 | M5: 1 | N5: 0
A6: Luwi F08 | B6: ELI-160 | C6: 0 | D6: 0 | E6: 0 | F6: 0 | G6: 0 | H6: 0 | I6: 0 | J6: 0 | K6: 0 | L6: 0 | M6: 0 | N6: 0
A7: Luwi F09 | B7: ELI-241 | C7: 0 | D7: 0 | E7: 0 | F7: 0 | G7: 0 | H7: 0 | I7: 0 | J7: 0 | K7: 0 | L7: 0 | M7: 0 | N7: 0
A8: Luwi F10 | B8: ELI-369 | C8: 0 | D8: 0 | E8: 0 | F8: 0 | G8: 0 | H8: 1 | I8: 1 | J8: 1 | K8: 1 | L8: 1 | M8: 1 | N8: 0
A9: Luwi M05 | B9: ELI-370 | C9: 0 | D9: 0 | E9: 0 | F9: 0 | G9: 0 | H9: 0 | I9: 0 | J9: 0 | K9: 0 | L9: 0 | M9: 0 | N9: 0
A10: Manky Ear | B10: ELI-159 | C10: 0 | D10: 0 | E10: 0 | F10: 0 | G10: 0 | H10: 1 | I10: 1 | J10: 1 | K10: 1 | L10: 1 | M10: 1 | N10: 0
A11: Luwi M01 | B11: ELI-158 | C11: 0 | D11: 0 | E11: 0 | F11: 0 | G11: 0 | H11: 0 | I11: 0 | J11: 0 | K11: 0 | L11: 0 | M11: 0 | N11: 0
A12: Luwi M02 | B12: ELI-161 | C12: 0 | D12: 0 | E12: 0 | F12: 0 | G12: 0 | H12: 0 | I12: 0 | J12: 0 | K12: 0 | L12: 0 | M12: 0 | N12: 0
A13: Ginger | B13: ELI-162 | C13: 0 | D13: 0 | E13: 0 | F13: 0 | G13: 0 | H13: 0 | I13: 0 | J13: 0 | K13: 0 | L13: 0 | M13: 0 | N13: 0
A14: Luwi M04 | B14: ELI-163 | C14: 0 | D14: 0 | E14: 0 | F14: 0 | G14: 0 | H14: 0 | I14: 0 | J14: 0 | K14: 0 | L14: 0 | M14: 0 | N14: 0
... A19: Cub 5 | B19: ELI-LP155 | C19: 0 | D19: 0 | E19: 0 | F19: 0 | G19: 0 | H19: 0 | I19: 1 | J19: 1 | K19: 1 | L19: 1 | M19: 1 | N19: 0
C21: Jan | D21: Feb | E21: Mar | F21: Apr | G21: May | H21: Jun | I21: Jul | J21: Aug | K21: 1 | L21: Oct | M21: Nov | N21: Dec
A22: Group | B22: ID | J22: 0
A23: Mwamba I F01 | B23: ELI-124 | C23: 0 | D23: 0 | E23: 0 | F23: 0 | G23: 0 | H23: 0 | I23: 0 | J23: 0 | K23: 1 | L23: 0 | M23: 0 | N23: 0
A24: Mwamba I F02 | B24: ELI-125 | C24: 0 | D24: 0 | E24: 0 | F24: 0 | G24: 0 | H24: 0 | I24: 0 | J24: 0 | K24: 0 | L24: 0 | M24: 0 | N24: 0
A25: Mwamba I F03 | B25: ELI-246 | C25: 0 | D25: 0 | E25: 0 | F25: 0 | G25: 0 | H25: 0 | I25: 0 | J25: 0 | K25: 0 | L25: 0 | M25: 0 | N25: 0
A26: Mwamba I F04 | B26: ELI-126 | C26: 0 | D26: 0 | E26: 0 | F26: 0 | G26: 0 | H26: 1 | I26: 0 | J26: 0 | K26: 1 | L26: 1 | M26: 0 | N26: 0
A27: Mwamba I F05 | B27: ELI-127 | C27: 0 | D27: 0 | E27: 0 | F27: 0 | G27: 0 | H27: 0 | I27: 1 | J27: 1 | K27: 1 | L27: 1 | M27: 0 | N27: 0
A28: Mwamba I M03 | B28: ELI-130 | C28: 0 | D28: 0 | E28: 0 | F28: 0 | G28: 0 | H28: 0 | I28: 0 | J28: 1 | K28: 0 | L28: 0 | M28: 1 | N28: 0
A29: Mwamba II F01 | B29: ELI-134 | C29: 0 | D29: 0 | E29: 0 | F29: 0 | G29: 0 | H29: 0 | I29: 0 | J29: 1 | K29: 0 | L29: 0 | M29: 1 | N29: 0
A30: Mwamba II F02 | B30: ELI-135 | C30: 0 | D30: 0 | E30: 1 | F30: 0 | G30: 0 | H30: 0 | I30: 0 | J30: 0 | K30: 0 | L30: 0 | M30: 0 | N30: 0
A31: Mwamba II F03 | B31: ELI-136 | C31: 0 | D31: 0 | E31: 1 | F31: 0 | G31: 0 | H31: 0 | I31: 0 | J31: 0 | K31: 0 | L31: 0 | M31: 0 | N31: 0
A32: Mwamba II F05 | B32: ELI-138 | C32: 0 | D32: 0 | E32: 0 | F32: 0 | G32: 0 | H32: 1 | I32: 0 | J32: 0 | K32: 1 | L32: 1 | M32: 0 | N32: 0
A33: Mwamba II F06 | B33: ELI-139 | C33: 0 | D33: 0 | E33: 0 | F33: 0 | G33: 0 | H33: 0 | I33: 0 | J33: 0 | K33: 0 | L33: 0 | M33: 0 | N33: 0
B34: ELI-657 | C34: 0 | D34: 0 | E34: 0 | F34: 0 | G34: 0 | H34: 0 | I34: 0 | J34: 1 | K34: 1 | L34: 1 | M34: 0 | N34: 0
B35: ELI-658 | C35: 0 | D35: 0 | E35: 0 | F35: 0 | G35: 0 | H35: 0 | I35: 0 | J35: 1 | K35: 1 | L35: 1 | M35: 1 | N35: 0
B36: ELI-659 | C36: 0 | D36: 0 | E36: 0 | F36: 0 | G36: 0 | H36: 0 | I36: 1 | J36: 1 | K36: 1 | L36: 0 | M36: 0 | N36: 0
B37: ELI-660 | C37: 0 | D37: 0 | E37: 0 | F37: 0 | G37: 0 | H37: 0 | I37: 0 | J37: 1 | K37: 1 | L37: 0 | M37: 0 | N37: 0
B38: ELI-661 | I38: 1 | K38: 1 | L38: 1
B39: ELI-662 | C39: 0 | D39: 0 | E39: 0 | F39: 0 | G39: 0 | H39: 0 | I39: 0 | J39: 1 | K39: 1 | L39: 0 | M39: 0 | N39: 0
B40: ELI-663 | C40: 0 | D40: 0 | E40: 0 | F40: 0 | G40: 0 | H40: 0 | I40: 0 | J40: 0 | K40: 1 | L40: 0 | M40: 0 | N40: 0
B41: ELI-664 | C41: 0 | D41: 0 | E41: 0 | F41: 0 | G41: 0 | H41: 1 | I41: 1 | J41: 0 | K41: 0 | L41: 0 | M41: 0 | N41: 0
B42: ELI-666 | C42: 0 | D42: 0 | E42: 0 | F42: 0 | G42: 0 | H42: 0 | I42: 1 | J42: 0 | K42: 1 | L42: 0 | M42: 0 | N42: 0
B43: ELI-469 | C43: 0 | D43: 0 | E43: 0 | F43: 0 | G43: 0 | H43: 1 | I43: 0 | J43: 0 | K43: 1 | L43: 1 | M43: 0 | N43: 0
B44: ELI-421 | C44: 0 | D44: 0 | E44: 0 | F44: 0 | G44: 0 | H44: 0 | I44: 0 | J44: 0 | K44: 1 | L44: 1 | M44: 0 | N44: 0
A45: Cub 1 | B45: ELI-MP1 | C45: 0 | D45: 0 | E45: 0 | F45: 0 | G45: 0 | H45: 1 | I45: 0 | J45: 0 | K45: 1 | L45: 1 | M45: 0 | N45: 0
...

Sheet NSN
D1: Jan | E1: Feb | F1: Mar | G1: Apr | H1: May | I1: Jun | J1: Jul | K1: Aug | L1: Sept | M1: Oct | N1: Nov | O1: Dec
B2: Group | C2: ID
B3: Nsolo F06 | C3: ELI-215 | D3: 0 | E3: 0 | F3: 0 | G3: 0 | H3: 0 | I3: 0 | J3: 0 | K3: 0 | L3: 0 | M3: 0 | N3: 0 | O3: 0
B4: Nsolo F07 | C4: ELI-454 | D4: 0 | E4: 0 | F4: 0 | G4: 0 | H4: 0 | I4: 0 | J4: 0 | K4: 0 | L4: 0 | M4: 0 | N4: 0 | O4: 0
B5: Nsolo F08 | C5: ELI-455 | D5: 0 | E5: 0 | F5: 0 | G5: 0 | H5: 0 | I5: 0 | J5: 0 | K5: 0 | L5: 0 | M5: 0 | N5: 0 | O5: 0
B6: Nsolo F09 | C6: ELI-458 | D6: 0 | E6: 0 | F6: 0 | G6: 0 | H6: 0 | I6: 0 | J6: 0 | K6: 0 | L6: 0 | M6: 0 | N6: 0 | O6: 0
B7: Nsolo F10 | C7: ELI-459 | D7: 0 | E7: 0 | F7: 0 | G7: 0 | H7: 0 | I7: 0 | J7: 0 | K7: 0 | L7: 0 | M7: 0 | N7: 0 | O7: 0
B8: Nsolo M04 | C8: ELI-461 | D8: 0 | E8: 0 | F8: 0 | G8: 0 | H8: 0 | I8: 0 | J8: 0 | K8: 0 | L8: 0 | M8: 0 | N8: 0 | O8: 0
B9: Nsolo M05 | C9: ELI-456 | D9: 0 | E9: 0 | F9: 0 | G9: 0 | H9: 0 | I9: 0 | J9: 0 | K9: 0 | L9: 0 | M9: 0 | N9: 0 | O9: 0
B10: Nsolo M06 | C10: ELI-457 | D10: 0 | E10: 0 | F10: 0 | G10: 0 | H10: 0 | I10: 0 | J10: 0 | K10: 0 | L10: 0 | M10: 0 | N10: 0 | O10: 0
B11: Nsolo M07 | C11: ELI-460 | D11: 0 | E11: 0 | F11: 0 | G11: 0 | H11: 0 | I11: 0 | J11: 0 | K11: 0 | L11: 0 | M11: 0 | N11: 0 | O11: 0
B12: Nsolo Pride F02 | C12: ELI-209 | D12: 0 | E12: 0 | F12: 0 | G12: 0 | H12: 0 | I12: 0 | J12: 0 | K12: 0 | L12: 0 | M12: 0 | N12: 0 | O12: 0
B13: Nsolo Pride F03 | C13: ELI-210 | D13: 0 | E13: 0 | F13: 0 | G13: 0 | H13: 0 | I13: 0 | J13: 0 | K13: 0 | L13: 0 | M13: 0 | N13: 0 | O13: 0
B14: Nsolo Pride F05 | C14: ELI-212 | D14: 0 | E14: 0 | F14: 0 | G14: 0 | H14: 0 | I14: 0 | J14: 0 | K14: 0 | L14: 0 | M14: 0 | N14: 0 | O14: 0
A15: Nsolo 2 | B15: Nsolo 2 F01 | C15: ELI-700 | D15: 0 | E15: 0 | F15: 0 | G15: 1 | H15: 1 | I15: 0 | J15: 0 | K15: 1 | L15: 1 | M15: 1 | N15: 0 | O15: 0
B16: Nsolo 2 F02 | C16: ELI-701 | D16: 0 | E16: 0 | F16: 0 | G16: 1 | H16: 1 | I16: 0 | J16: 1 | K16: 1 | L16: 1 | M16: 1 | N16: 0 | O16: 0
B17: Nsolo 2 F03 | C17: ELI-702 | D17: 0 | E17: 0 | F17: 0 | G17: 1 | H17: 1 | I17: 0 | J17: 0 | K17: 1 | L17: 1 | M17: 1 | N17: 0 | O17: 0
B18: Nsolo 2 Cub'14 01 | C18: ELI-708 | D18: 0 | E18: 0 | F18: 0 | G18: 0 | H18: 1 | I18: 0 | J18: 0 | K18: 1 | L18: 1 | M18: 1 | N18: 0 | O18: 0
B19: Nsolo 2 Cub'14 02 | C19: ELI-709 | D19: 0 | E19: 0 | F19: 0 | G19: 0 | H19: 1 | I19: 0 | J19: 0 | K19: 1 | L19: 1 | M19: 1 | N19: 0 | O19: 0
B20: Nsolo 2 Cub'14 03 | C20: ELI-710 | D20: 0 | E20: 0 | F20: 0 | G20: 0 | H20: 1 | I20: 0 | J20: 0 | K20: 1 | L20: 1 | M20: 1 | N20: 0 | O20: 0
B21: Nsolo 2 Cub'14 04 | C21: ELI-711 | D21: 0 | E21: 0 | F21: 0 | G21: 0 | H21: 1 | I21: 0 | J21: 0 | K21: 1 | L21: 1 | M21: 1 | N21: 0 | O21: 0
B22: Nsolo 2 Cub'15 01 | C22: ELI-NS1 | D22: 0 | E22: 0 | F22: 0 | G22: 0 | H22: 0 | I22: 0 | J22: 0 | K22: 1 | L22: 1 | M22: 1 | N22: 0 | O22: 0 | U22: 8
B23: Nsolo 2 Cub'15 02 | C23: ELI-NS2 | D23: 0 | E23: 0 | F23: 0 | G23: 0 | H23: 0 | I23: 0 | J23: 0 | K23: 1 | L23: 1 | M23: 1 | N23: 0 | O23: 0 | U23: 8
D26: Jan | E26: Feb | F26: Mar | G26: Apr | H26: May | I26: Jun | J26: Jul | K26: Aug | L26: Sept | M26: Oct | N26: Nov | O26: Dec
B27: Group | C27: ID
B28: Saltpan 2011 Cub U01 | C28: ELI-468 | J28: 1 | M28: 1 | U28: 7
B29: Saltpan F01 | C29: ELI-182 | J29: 1 | M29: 1 | U29: 7
B30: Saltpan F03 | C30: ELI-261 | E30: 1
B31: Saltpan F04 | C31: ELI-185 | E31: 1
B32: Saltpan F06 | C32: ELI-257
B33: Saltpan F07 | C33: ELI-183
B34: Saltpan F08 | C34: ELI-189
B35: Saltpan F09 | C35: ELI-465 | M35: 1
B36: Saltpan F10 | C36: ELI-467
B37: Saltpan M02 | C37: ELI-259
B38: Saltpan M04 | C38: ELI-187 | I38: 1 | L38: 1
D42: Jan | E42: Feb | F42: Mar | G42: Apr | H42: May | I42: Jun | J42: Jul | K42: Aug | L42: Sept | M42: Oct | N42: Nov | O42: Dec
B43: Group | C43: ID
B44: Nchindeni | C44: ELI-775 | D44: 0 | E44: 0 | F44: 0 | G44: 0 | H44: 1 | I44: 0 | J44: 0 | K44: 1 | L44: 0 | M44: 0 | N44: 1 | O44: 0
C45: ELI-776 | D45: 0 | E45: 0 | F45: 0 | G45: 0 | H45: 1 | I45: 0 | J45: 0 | K45: 1 | L45: 0 | M45: 0 | N45: 1 | O45: 0
...

Sheet Coa
D1: Jan | E1: Feb | F1: Mar | G1: Apr | H1: May | I1: Jun | J1: Jul | K1: Aug | L1: Sept | M1: Oct | N1: Nov | O1: Dec
B2: Group | C2: ID
B3: Saltpan Coa M02 | C3: ELI-179 | D3: 0 | E3: 0 | F3: 0 | G3: 0 | H3: 0 | I3: 0 | J3: 0 | K3: 0 | L3: 0 | M3: 0 | N3: 0 | O3: 0
B4: Big Pride M04 | C4: ELI-167 | D4: 0 | E4: 0 | F4: 0 | G4: 0 | H4: 0 | I4: 0 | J4: 0 | K4: 0 | L4: 0 | M4: 0 | N4: 0 | O4: 0
B5: Big Pride M05 | C5: ELI-168 | D5: 0 | E5: 0 | F5: 0 | G5: 0 | H5: 0 | I5: 0 | J5: 0 | K5: 0 | L5: 0 | M5: 0 | N5: 0 | O5: 0
B6: Big Pride M06 | C6: ELI-169 | D6: 0 | E6: 0 | F6: 0 | G6: 0 | H6: 0 | I6: 0 | J6: 0 | K6: 0 | L6: 0 | M6: 0 | N6: 0 | O6: 0
B7: Tafika F01 | C7: ELI-475 | D7: 0 | E7: 0 | F7: 0 | G7: 0 | H7: 0 | I7: 0 | J7: 0 | K7: 0 | L7: 0 | M7: 0 | N7: 0 | O7: 0
B8: Tafika M01 | C8: ELI-476 | D8: 0 | E8: 0 | F8: 0 | G8: 0 | H8: 0 | I8: 0 | J8: 0 | K8: 0 | L8: 0 | M8: 0 | N8: 0 | O8: 0
B9: Tafika M02 | C9: ELI-477 | D9: 0 | E9: 0 | F9: 0 | G9: 0 | H9: 0 | I9: 0 | J9: 0 | K9: 0 | L9: 0 | M9: 0 | N9: 0 | O9: 0
B10: Tafika M03 | C10: ELI-478 | D10: 0 | E10: 0 | F10: 0 | G10: 0 | H10: 0 | I10: 0 | J10: 0 | K10: 0 | L10: 0 | M10: 0 | N10: 0 | O10: 0
B11: Tsetse Coa M01 | C11: ELI-564 | D11: 0 | E11: 0 | F11: 0 | G11: 0 | H11: 0 | I11: 0 | J11: 0 | K11: 0 | L11: 0 | M11: 1 | N11: 0 | O11: 0
B12: Tsetse Coa M02 | C12: ELI-565 | D12: 0 | E12: 0 | F12: 0 | G12: 0 | H12: 0 | I12: 0 | J12: 0 | K12: 0 | L12: 0 | M12: 1 | N12: 1 | O12: 0
B13: Nsolo I Coa M02 | C13: ELI-207 | D13: 0 | E13: 0 | F13: 0 | G13: 0 | H13: 0 | I13: 0 | J13: 0 | K13: 0 | L13: 0 | M13: 0 | N13: 0 | O13: 0
B14: Nsolo II Coa M01 | C14: ELI-213 | D14: 0 | E14: 0 | F14: 0 | G14: 0 | H14: 0 | I14: 0 | J14: 1 | K14: 0 | L14: 0 | M14: 1 | N14: 0 | O14: 0
... B20: Mwamba Coa M01 | C20: ELI-420 | D20: 0 | E20: 0 | F20: 0 | G20: 0 | H20: 0 | I20: 0 | J20: 0 | K20: 0 | L20: 0 | M20: 0 | N20: 0 | O20: 0
A21: Mwamba Coa | B21: Mwamba Coa M02 | C21: ELI-421 | K21: 1 | L21: 1
B22: Scarface | C22: ELI-202 | D22: 0 | E22: 0 | F22: 0 | G22: 0 | H22: 0 | I22: 0 | J22: 0 | K22: 0 | L22: 0 | M22: 0 | N22: 0 | O22: 0
B23: Kakonje M02 | C23: ELI-407 | D23: 0 | E23: 0 | F23: 0 | G23: 0 | H23: 0 | I23: 0 | J23: 0 | K23: 0 | L23: 0 | M23: 0 | N23: 0 | O23: 0
B24: Lion Plain M01 | C24: ELI-175 | D24: 0 | E24: 0 | F24: 0 | G24: 0 | H24: 0 | I24: 0 | J24: 0 | K24: 0 | L24: 0 | M24: 0 | N24: 0 | O24: 0
B25: Luamfwa F01 | C25: ELI-562 | D25: 0 | E25: 0 | F25: 0 | G25: 0 | H25: 0 | I25: 0 | J25: 0 | K25: 0 | L25: 0 | M25: 0 | N25: 0 | O25: 0
B26: Luamfwa M01 | C26: ELI-402 | D26: 0 | E26: 0 | F26: 0 | G26: 0 | H26: 0 | I26: 0 | J26: 0 | K26: 0 | L26: 0 | M26: 0 | N26: 0 | O26: 0
B27: Limpy | C27: ELI-474 | D27: 0 | E27: 0 | F27: 0 | G27: 0 | H27: 0 | I27: 0 | J27: 1 | K27: 0 | L27: 0 | M27: 0 | N27: 0 | O27: 0
B28: Shaka | C28: ELI-234 | D28: 0 | E28: 0 | F28: 0 | G28: 0 | H28: 0 | I28: 0 | J28: 1 | K28: 0 | L28: 0 | M28: 1 | N28: 0 | O28: 0
B29: Mwamba II F05 | C29: ELI-138 | D29: 0 | E29: 0 | F29: 0 | G29: 0 | H29: 0 | I29: 0 | J29: 1 | K29: 0 | L29: 0 | M29: 1 | N29: 0 | O29: 0
B30: Mwamba II F06 | C30: ELI-139 | D30: 0 | E30: 1 | F30: 0 | G30: 0 | H30: 0 | I30: 0 | J30: 0 | K30: 0 | L30: 0 | M30: 0 | N30: 0 | O30: 0
A31: Tafika 2 COA | B31: Tafika 2 M1 | C31: ELI-628 | E31: 1 | J31: 1 | L31: 1 | M31: 1 | N31: 1
A32: Tafika 2 COA | B32: Tafika 2 M2 | C32: ELI-629 | J32: 1 | L32: 1 | M32: 1 | N32: 1
A33: Zikomo Coa | B33: Zikomo M1 | C33: ELI-130 | J33: 1
A34: Zikomo Coa | B34: Zikomo M2 | C34: ELI-699 | J34: 1
B35: Kakumbi | C35: ELI-373 | D35: 0 | E35: 0 | F35: 0 | G35: 0 | H35: 0 | I35: 0 | J35: 0 | K35: 1 | L35: 0 | M35: 1 | N35: 1 | O35: 0
B36: Kakumbi | C36: ELI-375 | D36: 0 | E36: 0 | F36: 0 | G36: 0 | H36: 0 | I36: 0 | J36: 0 | K36: 1 | L36: 0 | M36: 0 | N36: 0 | O36: 0
B37: Kakumbi | C37: ELI-377 | D37: 0 | E37: 0 | F37: 0 | G37: 0 | H37: 0 | I37: 0 | J37: 0 | K37: 1 | L37: 0 | M37: 0 | N37: 1 | O37: 0
I38: 1 | L38: 1

Sheet input_format
A1: =CONCATENATE("/*",'Allprides '!C2,"*/ ",'Allprides '!G2,'Allprides '!H2,'Allprides '!I2,'Allprides '!J2,'Allprides '!K2,'Allprides '!L2,'Allprides '!M2,'Allprides '!N2," 1;") -> /*ELI-584*/ 11111111 1;
A2: =CONCATENATE("/*",'Allprides '!C3,"*/ ",'Allprides '!G3,'Allprides '!H3,'Allprides '!I3,'Allprides '!J3,'Allprides '!K3,'Allprides '!L3,'Allprides '!M3,'Allprides '!N3," 1;") -> /*ELI-585*/ 11111101 1;
A3: =CONCATENATE("/*",'Allprides '!C4,"*/ ",'Allprides '!G4,'Allprides '!H4,'Allprides '!I4,'Allprides '!J4,'Allprides '!K4,'Allprides '!L4,'Allprides '!M4,'Allprides '!N4," 1;") -> /*ELI-586*/ 11111111 1;
A4: =CONCATENATE("/*",'Allprides '!C5,"*/ ",'Allprides '!G5,'Allprides '!H5,'Allprides '!I5,'Allprides '!J5,'Allprides '!K5,'Allprides '!L5,'Allprides '!M5,'Allprides '!N5," 1;") -> /*ELI-587*/ 11111111 1;
A5: =CONCATENATE("/*",'Allprides '!C6,"*/ ",'Allprides '!G6,'Allprides '!H6,'Allprides '!I6,'Allprides '!J6,'Allprides '!K6,'Allprides '!L6,'Allprides '!M6,'Allprides '!N6," 1;") -> /*ELI-590*/ 11111111 1;
A6: =CONCATENATE("/*",'Allprides '!C7,"*/ ",'Allprides '!G7,'Allprides '!H7,'Allprides '!I7,'Allprides '!J7,'Allprides '!K7,'Allprides '!L7,'Allprides '!M7,'Allprides '!N7," 1;") -> /*ELI-592*/ 11111101 1;
A7: =CONCATENATE("/*",'Allprides '!C8,"*/ ",'Allprides '!G8,'Allprides '!H8,'Allprides '!I8,'Allprides '!J8,'Allprides '!K8,'Allprides '!L8,'Allprides '!M8,'Allprides '!N8," 1;") -> /*ELI-593*/ 11111101 1;
A8: =CONCATENATE("/*",'Allprides '!C9,"*/ ",'Allprides '!G9,'Allprides '!H9,'Allprides '!I9,'Allprides '!J9,'Allprides '!K9,'Allprides '!L9,'Allprides '!M9,'Allprides '!N9," 1;") -> /*ELI-594*/ 11111111 1;
A9: =CONCATENATE("/*",'Allprides '!C10,"*/ ",'Allprides '!G10,'Allprides '!H10,'Allprides '!I10,'Allprides '!J10,'Allprides '!K10,'Allprides '!L10,'Allprides '!M10,'Allprides '!N10," 1;") -> /*ELI-243*/ 11111101 1;
A10: =CONCATENATE("/*",'Allprides '!C11,"*/ ",'Allprides '!G11,'Allprides '!H11,'Allprides '!I11,'Allprides '!J11,'Allprides '!K11,'Allprides '!L11,'Allprides '!M11,'Allprides '!N11," 1;") -> /*ELI-224*/ 00110110 1;
A11: =CONCATENATE("/*",'Allprides '!C12,"*/ ",'Allprides '!G12,'Allprides '!H12,'Allprides '!I12,'Allprides '!J12,'Allprides '!K12,'Allprides '!L12,'Allprides '!M12,'Allprides '!N12," 1;") -> /*ELI-245*/ 10111110 1;
A12: =CONCATENATE("/*",'Allprides '!C13,"*/ ",'Allprides '!G13,'Allprides '!H13,'Allprides '!I13,'Allprides '!J13,'Allprides '!K13,'Allprides '!L13,'Allprides '!M13,'Allprides '!N13," 1;") -> /*ELI-223*/ 00001110 1;
... A200: =CONCATENATE("/*",'Allprides '!C201,"*/ ",'Allprides '!G201,'Allprides '!H201,'Allprides '!I201,'Allprides '!J201,'Allprides '!K201,'Allprides '!L201,'Allprides '!M201,'Allprides '!N201," 1;") -> /*ELI-779*/ 00100000 1;

Sheet 2015_slnp_lion_ch

Sheet 2015_slnp_lion_3monRD
A1: =CONCATENATE("/*",'Allprides '!C2,"*/ ",'Allprides '!F2,'Allprides '!G2,'Allprides '!H2,'Allprides '!L2,'Allprides '!M2,'Allprides '!N2," 1;") -> /*ELI-584*/ 011111 1;
A2: =CONCATENATE("/*",'Allprides '!C3,"*/ ",'Allprides '!F3,'Allprides '!G3,'Allprides '!H3,'Allprides '!L3,'Allprides '!M3,'Allprides '!N3," 1;") -> /*ELI-585*/ 111101 1;
A3: =CONCATENATE("/*",'Allprides '!C4,"*/ ",'Allprides '!F4,'Allprides '!G4,'Allprides '!H4,'Allprides '!L4,'Allprides '!M4,'Allprides '!N4," 1;") -> /*ELI-586*/ 111111 1;
A4: =CONCATENATE("/*",'Allprides '!C5,"*/ ",'Allprides '!F5,'Allprides '!G5,'Allprides '!H5,'Allprides '!L5,'Allprides '!M5,'Allprides '!N5," 1;") -> /*ELI-587*/ 111111 1;
A5: =CONCATENATE("/*",'Allprides '!C6,"*/ ",'Allprides '!F6,'Allprides '!G6,'Allprides '!H6,'Allprides '!L6,'Allprides '!M6,'Allprides '!N6," 1;") -> /*ELI-590*/ 111111 1;
A6: =CONCATENATE("/*",'Allprides '!C7,"*/ ",'Allprides '!F7,'Allprides '!G7,'Allprides '!H7,'Allprides '!L7,'Allprides '!M7,'Allprides '!N7," 1;") -> /*ELI-592*/ 111101 1;
A7: =CONCATENATE("/*",'Allprides '!C8,"*/ ",'Allprides '!F8,'Allprides '!G8,'Allprides '!H8,'Allprides '!L8,'Allprides '!M8,'Allprides '!N8," 1;") -> /*ELI-593*/ 111101 1;
A8: =CONCATENATE("/*",'Allprides '!C9,"*/ ",'Allprides '!F9,'Allprides '!G9,'Allprides '!H9,'Allprides '!L9,'Allprides '!M9,'Allprides '!N9," 1;") -> /*ELI-594*/ 111111 1;
A9: =CONCATENATE("/*",'Allprides '!C10,"*/ ",'Allprides '!F10,'Allprides '!G10,'Allprides '!H10,'Allprides '!L10,'Allprides '!M10,'Allprides '!N10," 1;") -> /*ELI-243*/ 111101 1;
A10: =CONCATENATE("/*",'Allprides '!C11,"*/ ",'Allprides '!F11,'Allprides '!G11,'Allprides '!H11,'Allprides '!L11,'Allprides '!M11,'Allprides '!N11," 1;") -> /*ELI-224*/ 000110 1;
A11: =CONCATENATE("/*",'Allprides '!C12,"*/ ",'Allprides '!F12,'Allprides '!G12,'Allprides '!H12,'Allprides '!L12,'Allprides '!M12,'Allprides '!N12," 1;") -> /*ELI-245*/ 010110 1;
A12: =CONCATENATE("/*",'Allprides '!C13,"*/ ",'Allprides '!F13,'Allprides '!G13,'Allprides '!H13,'Allprides '!L13,'Allprides '!M13,'Allprides '!N13," 1;") -> /*ELI-223*/ 000110 1;
... A200: =CONCATENATE("/*",'Allprides '!C201,"*/ ",'Allprides '!F201,'Allprides '!G201,'Allprides '!H201,'Allprides '!L201,'Allprides '!M201,'Allprides '!N201," 1;") -> /*ELI-779*/ 000000 1;
